Workbook

Sheet 说明
A1: 制作者信息 | E1: 当前赛事 | K1: =E3&F3 -> 2024IJL夏季赛常规赛
A2: 名称 | B2: 第五人格赛事信息记录表 | C2: 比分记录 for BWIKI V2.0 | E2: 年份 | F2: 类型 | K2: 总结
A3: BWIKI欢迎各位加入w点击此表格了解BWIKI | E3: 2024 | F3: IJL夏季赛常规赛 | K3: 总场次 | M3: 总局数 | N3: 2局 | O3: 3局 | P3: BO3加赛
A4: 主分、客分列，哪怕是2：0带走，第三局和加赛那一行也必须填上数字，没比的局局分填0就行 | E4: 可上场监管者角色数 | F4: 29 | G4: 监管者indirect区域 | H4: ="'各类选项'!C3:C"&(F4+3) -> '各类选项'!C3:C32 | K4: =90-COUNTIF(赛果!K$2:K$91,"") -> 42 | M4: =720-COUNTIF(原始数据!L2:L721,"") -> 230 | N4: =COUNTIF(赛果!O2:O91,"2") -> 0 | O4: =COUNTIF(赛果!O2:O91,"3") -> 0 | P4: =COUNTIF(赛果!O2:O91,"4") -> 0
E5: 可上场求生者角色数 | F5: 43 | G5: 求生者indirect区域 | H5: ="'各类选项'!E3:E"&(F5+3) -> '各类选项'!E3:E46 | K5: 监管者BAN | M5: 求生者BAN | O5: 监管者 胜利 | P5: 胜率 | Q5: 求生者 胜利 | R5: 胜率 | S5: 平局 | T5: 平率
A6: 只有与本格子颜色相同的部分才开放编辑权限噢~记录赛事时，原始数据、牵制时长这两个表是都需要填的。若两队通过加时赛的时长比对才分出胜负，那么需要在大分&小分表格寻找和本格子颜色一样的区域，手动填写最终获胜者。除此以外，本表格其他区域所有内容均使用excel函数自动生成，无需进行任何操作~ | E6: 队伍数量 | F6: 7 | G6: indirect区域 | H6: ="'各类选项'!F2:F"&(F6+1) -> '各类选项'!F2:F8
E7: 监管者阵营人数 | F7: 13 | G7: ="'各类选项'!K2:K"&(F7+1) -> '各类选项'!K2:K14 | H7: ="'各类选项'!L2:L"&(F7+1) -> '各类选项'!L2:L14 | O7: =COUNTIFS(原始数据!U2:U721,"屠") -> 98 | P7: =O7/M4 -> 0.42608696 | Q7: =COUNTIFS(原始数据!U2:U721,"人") -> 57 | R7: =Q7/M4 -> 0.24782609 | S7: =COUNTIFS(原始数据!U2:U721,"平") -> 75 | T7: =S7/M4 -> 0.32608696
E8: 求生者阵营人数 | F8: 34 | G8: 求生者indirect区域 | H8: ="'各类选项'!J2:J"&(F8+1) -> '各类选项'!J2:J35 | K8: 第五人格BWIKI赛事组制作 | R8: 45347
A9: 填写原始数据时，如第一轮第一场上半场由DOU5队东玄先上屠夫，则在屠队列填写D5（全大写），在屠名列填写东玄id（全小写）dx。第一轮是ZQ打DOU5，因此如果东玄被三跑，则ZQ:DOU5比分为3:1，主分填3，客分填1即可。地图名字请填写全名，请勿做任何省略。地图方主客即选择地图的一方本轮处于主场或者客场。如第一轮第一场若由DOU5选图，则此处填客字即可，主/客一个字就行！！倒数第二列的剩余台数就是填写剩余密码机数量。最后一列名字是错误，这是一个简单的纠错，一旦有常见的名字输入错误的问题，这里便会计数，但只是能查到，并不是100%查得到！牵制时长表格和原始数据用类似方法填写，但求生者ID不需要带队名。 | E9: 地图数量 | F9: 8 | G9: 地图区域 | H9: ="'各类选项'!G2:G"&(F9+2) -> '各类选项'!G2:G10
E10: 辅助特质 | F10: 8 | G10: 辅助特质校验 | H10: ="'各类选项'!H2:H"&(F10+2) -> '各类选项'!H2:H10
E11: BO数 | F11: 3
A21: 当参赛的选手、角色有更新时，请更改右上黄色区域 并修改【各类选项】sheet

Sheet 重复内容检查
A1: =COUNTIF(A2:A721,"×") -> 0 | B1: =COUNTIF(B2:B721,"×") -> 0 | C1: =COUNTIF(C2:C721,"×") -> 0 | D1: =COUNTIF(D2:D721,"×") -> 0 | E1: =COUNTIF(E2:E721,"×") -> 0 | F1: =COUNTIF(F2:F721,"×") -> 0 | G1: =COUNTIF(G2:G721,"×") -> 0 | H1: =COUNTIF(H2:H721,"×") -> 0 | ... AN1: =COUNTIF(AN2:AN721,"×") -> 0
A2: =IF(IFERROR(原始数据!B2,"×")="×","×","") | B2: =IF(IFERROR(原始数据!C2,"×")="×","×","") | C2: =IF(IFERROR(原始数据!D2,"×")="×","×","") | D2: =IF(IFERROR(原始数据!E2,"×")="×","×","") | E2: =IF(IFERROR(原始数据!F2,"×")="×","×","") | F2: =IF(IFERROR(原始数据!G2,"×")="×","×","") | G2: =IF(IFERROR(原始数据!H2,"×")="×","×","") | H2: =IF(IFERROR(原始数据!I2,"×")="×","×","") | ... T2: =IF(IFERROR(原始数据!U2,"×")="×","×","") | U2: {=IF(原始数据!V2="-","",IF(原始数据!V2="","",IF(COUNT(FIND(原始数据!V2,原始数据!2:2))=2,"×","")))} | V2: {=IF(原始数据!W2="-","",IF(原始数据!W2="","",IF(COUNT(FIND(原始数据!W2,原始数据!2:2))=2,"×","")))} | W2: =IF(原始数据!X2="","",IF(COUNTIF(原始数据!2:2,原始数据!X2)>1,"×","")) | X2: =IF(原始数据!Y2="","",IF(COUNTIF(原始数据!2:2,原始数据!Y2)>1,"×","")) | Y2: =IF(原始数据!Z2="","",IF(COUNTIF(原始数据!2:2,原始数据!Z2)>1,"×","")) | Z2: =IF(原始数据!AA2="","",IF(COUNTIF(原始数据!2:2,原始数据!AA2)>1,"×","")) | AA2: =IF(原始数据!AB2="","",IF(COUNTIF(原始数据!2:2,原始数据!AB2)>1,"×","")) | AB2: =IF(原始数据!AC2="","",IF(COUNTIF(原始数据!2:2,原始数据!AC2)>1,"×","")) | AC2: =IF(原始数据!AD2="","",IF(COUNTIF(原始数据!2:2,原始数据!AD2)>1,"×","")) | AD2: =IF(原始数据!AE2="","",IF(COUNTIF(原始数据!2:2,原始数据!AE2)>1,"×","")) | ... AN2: =IF(原始数据!AO2="","",IF(COUNTIF(原始数据!2:2,原始数据!AO2)>1,"×",""))
A3: =IF(IFERROR(原始数据!B3,"×")="×","×","") | B3: =IF(IFERROR(原始数据!C3,"×")="×","×","") | C3: =IF(IFERROR(原始数据!D3,"×")="×","×","") | D3: =IF(IFERROR(原始数据!E3,"×")="×","×","") | E3: =IF(IFERROR(原始数据!F3,"×")="×","×","") | F3: =IF(IFERROR(原始数据!G3,"×")="×","×","") | G3: =IF(IFERROR(原始数据!H3,"×")="×","×","") | H3: =IF(IFERROR(原始数据!I3,"×")="×","×","") | ... T3: =IF(IFERROR(原始数据!U3,"×")="×","×","") | U3: {=IF(原始数据!V3="-","",IF(原始数据!V3="","",IF(COUNT(FIND(原始数据!V3,原始数据!3:3))=2,"×","")))} | V3: {=IF(原始数据!W3="-","",IF(原始数据!W3="","",IF(COUNT(FIND(原始数据!W3,原始数据!3:3))=2,"×","")))} | W3: =IF(原始数据!X3="","",IF(COUNTIF(原始数据!3:3,原始数据!X3)>1,"×","")) | X3: =IF(原始数据!Y3="","",IF(COUNTIF(原始数据!3:3,原始数据!Y3)>1,"×","")) | Y3: =IF(原始数据!Z3="","",IF(COUNTIF(原始数据!3:3,原始数据!Z3)>1,"×","")) | Z3: =IF(原始数据!AA3="","",IF(COUNTIF(原始数据!3:3,原始数据!AA3)>1,"×","")) | AA3: =IF(原始数据!AB3="","",IF(COUNTIF(原始数据!3:3,原始数据!AB3)>1,"×","")) | AB3: =IF(原始数据!AC3="","",IF(COUNTIF(原始数据!3:3,原始数据!AC3)>1,"×","")) | AC3: =IF(原始数据!AD3="","",IF(COUNTIF(原始数据!3:3,原始数据!AD3)>1,"×","")) | AD3: =IF(原始数据!AE3="","",IF(COUNTIF(原始数据!3:3,原始数据!AE3)>1,"×","")) | ... AN3: =IF(原始数据!AO3="","",IF(COUNTIF(原始数据!3:3,原始数据!AO3)>1,"×",""))
A4: =IF(IFERROR(原始数据!B4,"×")="×","×","") | B4: =IF(IFERROR(原始数据!C4,"×")="×","×","") | C4: =IF(IFERROR(原始数据!D4,"×")="×","×","") | D4: =IF(IFERROR(原始数据!E4,"×")="×","×","") | E4: =IF(IFERROR(原始数据!F4,"×")="×","×","") | F4: =IF(IFERROR(原始数据!G4,"×")="×","×","") | G4: =IF(IFERROR(原始数据!H4,"×")="×","×","") | H4: =IF(IFERROR(原始数据!I4,"×")="×","×","") | ... T4: =IF(IFERROR(原始数据!U4,"×")="×","×","") | U4: {=IF(原始数据!V4="-","",IF(原始数据!V4="","",IF(COUNT(FIND(原始数据!V4,原始数据!4:4))=2,"×","")))} | V4: {=IF(原始数据!W4="-","",IF(原始数据!W4="","",IF(COUNT(FIND(原始数据!W4,原始数据!4:4))=2,"×","")))} | W4: =IF(原始数据!X4="","",IF(COUNTIF(原始数据!4:4,原始数据!X4)>1,"×","")) | X4: =IF(原始数据!Y4="","",IF(COUNTIF(原始数据!4:4,原始数据!Y4)>1,"×","")) | Y4: =IF(原始数据!Z4="","",IF(COUNTIF(原始数据!4:4,原始数据!Z4)>1,"×","")) | Z4: =IF(原始数据!AA4="","",IF(COUNTIF(原始数据!4:4,原始数据!AA4)>1,"×","")) | AA4: =IF(原始数据!AB4="","",IF(COUNTIF(原始数据!4:4,原始数据!AB4)>1,"×","")) | AB4: =IF(原始数据!AC4="","",IF(COUNTIF(原始数据!4:4,原始数据!AC4)>1,"×","")) | AC4: =IF(原始数据!AD4="","",IF(COUNTIF(原始数据!4:4,原始数据!AD4)>1,"×","")) | AD4: =IF(原始数据!AE4="","",IF(COUNTIF(原始数据!4:4,原始数据!AE4)>1,"×","")) | ... AN4: =IF(原始数据!AO4="","",IF(COUNTIF(原始数据!4:4,原始数据!AO4)>1,"×",""))
A5: =IF(IFERROR(原始数据!B5,"×")="×","×","") | B5: =IF(IFERROR(原始数据!C5,"×")="×","×","") | C5: =IF(IFERROR(原始数据!D5,"×")="×","×","") | D5: =IF(IFERROR(原始数据!E5,"×")="×","×","") | E5: =IF(IFERROR(原始数据!F5,"×")="×","×","") | F5: =IF(IFERROR(原始数据!G5,"×")="×","×","") | G5: =IF(IFERROR(原始数据!H5,"×")="×","×","") | H5: =IF(IFERROR(原始数据!I5,"×")="×","×","") | ... T5: =IF(IFERROR(原始数据!U5,"×")="×","×","") | U5: {=IF(原始数据!V5="-","",IF(原始数据!V5="","",IF(COUNT(FIND(原始数据!V5,原始数据!5:5))=2,"×","")))} | V5: {=IF(原始数据!W5="-","",IF(原始数据!W5="","",IF(COUNT(FIND(原始数据!W5,原始数据!5:5))=2,"×","")))} | W5: =IF(原始数据!X5="","",IF(COUNTIF(原始数据!5:5,原始数据!X5)>1,"×","")) | X5: =IF(原始数据!Y5="","",IF(COUNTIF(原始数据!5:5,原始数据!Y5)>1,"×","")) | Y5: =IF(原始数据!Z5="","",IF(COUNTIF(原始数据!5:5,原始数据!Z5)>1,"×","")) | Z5: =IF(原始数据!AA5="","",IF(COUNTIF(原始数据!5:5,原始数据!AA5)>1,"×","")) | AA5: =IF(原始数据!AB5="","",IF(COUNTIF(原始数据!5:5,原始数据!AB5)>1,"×","")) | AB5: =IF(原始数据!AC5="","",IF(COUNTIF(原始数据!5:5,原始数据!AC5)>1,"×","")) | AC5: =IF(原始数据!AD5="","",IF(COUNTIF(原始数据!5:5,原始数据!AD5)>1,"×","")) | AD5: =IF(原始数据!AE5="","",IF(COUNTIF(原始数据!5:5,原始数据!AE5)>1,"×","")) | ... AN5: =IF(原始数据!AO5="","",IF(COUNTIF(原始数据!5:5,原始数据!AO5)>1,"×",""))
A6: =IF(IFERROR(原始数据!B6,"×")="×","×","") | B6: =IF(IFERROR(原始数据!C6,"×")="×","×","") | C6: =IF(IFERROR(原始数据!D6,"×")="×","×","") | D6: =IF(IFERROR(原始数据!E6,"×")="×","×","") | E6: =IF(IFERROR(原始数据!F6,"×")="×","×","") | F6: =IF(IFERROR(原始数据!G6,"×")="×","×","") | G6: =IF(IFERROR(原始数据!H6,"×")="×","×","") | H6: =IF(IFERROR(原始数据!I6,"×")="×","×","") | ... T6: =IF(IFERROR(原始数据!U6,"×")="×","×","") | U6: {=IF(原始数据!V6="-","",IF(原始数据!V6="","",IF(COUNT(FIND(原始数据!V6,原始数据!6:6))=2,"×","")))} | V6: {=IF(原始数据!W6="-","",IF(原始数据!W6="","",IF(COUNT(FIND(原始数据!W6,原始数据!6:6))=2,"×","")))} | W6: =IF(原始数据!X6="","",IF(COUNTIF(原始数据!6:6,原始数据!X6)>1,"×","")) | X6: =IF(原始数据!Y6="","",IF(COUNTIF(原始数据!6:6,原始数据!Y6)>1,"×","")) | Y6: =IF(原始数据!Z6="","",IF(COUNTIF(原始数据!6:6,原始数据!Z6)>1,"×","")) | Z6: =IF(原始数据!AA6="","",IF(COUNTIF(原始数据!6:6,原始数据!AA6)>1,"×","")) | AA6: =IF(原始数据!AB6="","",IF(COUNTIF(原始数据!6:6,原始数据!AB6)>1,"×","")) | AB6: =IF(原始数据!AC6="","",IF(COUNTIF(原始数据!6:6,原始数据!AC6)>1,"×","")) | AC6: =IF(原始数据!AD6="","",IF(COUNTIF(原始数据!6:6,原始数据!AD6)>1,"×","")) | AD6: =IF(原始数据!AE6="","",IF(COUNTIF(原始数据!6:6,原始数据!AE6)>1,"×","")) | ... AN6: =IF(原始数据!AO6="","",IF(COUNTIF(原始数据!6:6,原始数据!AO6)>1,"×",""))
A7: =IF(IFERROR(原始数据!B7,"×")="×","×","") | B7: =IF(IFERROR(原始数据!C7,"×")="×","×","") | C7: =IF(IFERROR(原始数据!D7,"×")="×","×","") | D7: =IF(IFERROR(原始数据!E7,"×")="×","×","") | E7: =IF(IFERROR(原始数据!F7,"×")="×","×","") | F7: =IF(IFERROR(原始数据!G7,"×")="×","×","") | G7: =IF(IFERROR(原始数据!H7,"×")="×","×","") | H7: =IF(IFERROR(原始数据!I7,"×")="×","×","") | ... T7: =IF(IFERROR(原始数据!U7,"×")="×","×","") | U7: {=IF(原始数据!V7="-","",IF(原始数据!V7="","",IF(COUNT(FIND(原始数据!V7,原始数据!7:7))=2,"×","")))} | V7: {=IF(原始数据!W7="-","",IF(原始数据!W7="","",IF(COUNT(FIND(原始数据!W7,原始数据!7:7))=2,"×","")))} | W7: =IF(原始数据!X7="","",IF(COUNTIF(原始数据!7:7,原始数据!X7)>1,"×","")) | X7: =IF(原始数据!Y7="","",IF(COUNTIF(原始数据!7:7,原始数据!Y7)>1,"×","")) | Y7: =IF(原始数据!Z7="","",IF(COUNTIF(原始数据!7:7,原始数据!Z7)>1,"×","")) | Z7: =IF(原始数据!AA7="","",IF(COUNTIF(原始数据!7:7,原始数据!AA7)>1,"×","")) | AA7: =IF(原始数据!AB7="","",IF(COUNTIF(原始数据!7:7,原始数据!AB7)>1,"×","")) | AB7: =IF(原始数据!AC7="","",IF(COUNTIF(原始数据!7:7,原始数据!AC7)>1,"×","")) | AC7: =IF(原始数据!AD7="","",IF(COUNTIF(原始数据!7:7,原始数据!AD7)>1,"×","")) | AD7: =IF(原始数据!AE7="","",IF(COUNTIF(原始数据!7:7,原始数据!AE7)>1,"×","")) | ... AN7: =IF(原始数据!AO7="","",IF(COUNTIF(原始数据!7:7,原始数据!AO7)>1,"×",""))
A8: =IF(IFERROR(原始数据!B8,"×")="×","×","") | B8: =IF(IFERROR(原始数据!C8,"×")="×","×","") | C8: =IF(IFERROR(原始数据!D8,"×")="×","×","") | D8: =IF(IFERROR(原始数据!E8,"×")="×","×","") | E8: =IF(IFERROR(原始数据!F8,"×")="×","×","") | F8: =IF(IFERROR(原始数据!G8,"×")="×","×","") | G8: =IF(IFERROR(原始数据!H8,"×")="×","×","") | H8: =IF(IFERROR(原始数据!I8,"×")="×","×","") | ... T8: =IF(IFERROR(原始数据!U8,"×")="×","×","") | U8: {=IF(原始数据!V8="-","",IF(原始数据!V8="","",IF(COUNT(FIND(原始数据!V8,原始数据!8:8))=2,"×","")))} | V8: {=IF(原始数据!W8="-","",IF(原始数据!W8="","",IF(COUNT(FIND(原始数据!W8,原始数据!8:8))=2,"×","")))} | W8: =IF(原始数据!X8="","",IF(COUNTIF(原始数据!8:8,原始数据!X8)>1,"×","")) | X8: =IF(原始数据!Y8="","",IF(COUNTIF(原始数据!8:8,原始数据!Y8)>1,"×","")) | Y8: =IF(原始数据!Z8="","",IF(COUNTIF(原始数据!8:8,原始数据!Z8)>1,"×","")) | Z8: =IF(原始数据!AA8="","",IF(COUNTIF(原始数据!8:8,原始数据!AA8)>1,"×","")) | AA8: =IF(原始数据!AB8="","",IF(COUNTIF(原始数据!8:8,原始数据!AB8)>1,"×","")) | AB8: =IF(原始数据!AC8="","",IF(COUNTIF(原始数据!8:8,原始数据!AC8)>1,"×","")) | AC8: =IF(原始数据!AD8="","",IF(COUNTIF(原始数据!8:8,原始数据!AD8)>1,"×","")) | AD8: =IF(原始数据!AE8="","",IF(COUNTIF(原始数据!8:8,原始数据!AE8)>1,"×","")) | ... AN8: =IF(原始数据!AO8="","",IF(COUNTIF(原始数据!8:8,原始数据!AO8)>1,"×",""))
A9: =IF(IFERROR(原始数据!B9,"×")="×","×","") | B9: =IF(IFERROR(原始数据!C9,"×")="×","×","") | C9: =IF(IFERROR(原始数据!D9,"×")="×","×","") | D9: =IF(IFERROR(原始数据!E9,"×")="×","×","") | E9: =IF(IFERROR(原始数据!F9,"×")="×","×","") | F9: =IF(IFERROR(原始数据!G9,"×")="×","×","") | G9: =IF(IFERROR(原始数据!H9,"×")="×","×","") | H9: =IF(IFERROR(原始数据!I9,"×")="×","×","") | ... T9: =IF(IFERROR(原始数据!U9,"×")="×","×","") | U9: {=IF(原始数据!V9="-","",IF(原始数据!V9="","",IF(COUNT(FIND(原始数据!V9,原始数据!9:9))=2,"×","")))} | V9: {=IF(原始数据!W9="-","",IF(原始数据!W9="","",IF(COUNT(FIND(原始数据!W9,原始数据!9:9))=2,"×","")))} | W9: =IF(原始数据!X9="","",IF(COUNTIF(原始数据!9:9,原始数据!X9)>1,"×","")) | X9: =IF(原始数据!Y9="","",IF(COUNTIF(原始数据!9:9,原始数据!Y9)>1,"×","")) | Y9: =IF(原始数据!Z9="","",IF(COUNTIF(原始数据!9:9,原始数据!Z9)>1,"×","")) | Z9: =IF(原始数据!AA9="","",IF(COUNTIF(原始数据!9:9,原始数据!AA9)>1,"×","")) | AA9: =IF(原始数据!AB9="","",IF(COUNTIF(原始数据!9:9,原始数据!AB9)>1,"×","")) | AB9: =IF(原始数据!AC9="","",IF(COUNTIF(原始数据!9:9,原始数据!AC9)>1,"×","")) | AC9: =IF(原始数据!AD9="","",IF(COUNTIF(原始数据!9:9,原始数据!AD9)>1,"×","")) | AD9: =IF(原始数据!AE9="","",IF(COUNTIF(原始数据!9:9,原始数据!AE9)>1,"×","")) | ... AN9: =IF(原始数据!AO9="","",IF(COUNTIF(原始数据!9:9,原始数据!AO9)>1,"×",""))
A10: =IF(IFERROR(原始数据!B10,"×")="×","×","") | B10: =IF(IFERROR(原始数据!C10,"×")="×","×","") | C10: =IF(IFERROR(原始数据!D10,"×")="×","×","") | D10: =IF(IFERROR(原始数据!E10,"×")="×","×","") | E10: =IF(IFERROR(原始数据!F10,"×")="×","×","") | F10: =IF(IFERROR(原始数据!G10,"×")="×","×","") | G10: =IF(IFERROR(原始数据!H10,"×")="×","×","") | H10: =IF(IFERROR(原始数据!I10,"×")="×","×","") | ... T10: =IF(IFERROR(原始数据!U10,"×")="×","×","") | U10: {=IF(原始数据!V10="-","",IF(原始数据!V10="","",IF(COUNT(FIND(原始数据!V10,原始数据!10:10))=2,"×","")))} | V10: {=IF(原始数据!W10="-","",IF(原始数据!W10="","",IF(COUNT(FIND(原始数据!W10,原始数据!10:10))=2,"×","")))} | W10: =IF(原始数据!X10="","",IF(COUNTIF(原始数据!10:10,原始数据!X10)>1,"×","")) | X10: =IF(原始数据!Y10="","",IF(COUNTIF(原始数据!10:10,原始数据!Y10)>1,"×","")) | Y10: =IF(原始数据!Z10="","",IF(COUNTIF(原始数据!10:10,原始数据!Z10)>1,"×","")) | Z10: =IF(原始数据!AA10="","",IF(COUNTIF(原始数据!10:10,原始数据!AA10)>1,"×","")) | AA10: =IF(原始数据!AB10="","",IF(COUNTIF(原始数据!10:10,原始数据!AB10)>1,"×","")) | AB10: =IF(原始数据!AC10="","",IF(COUNTIF(原始数据!10:10,原始数据!AC10)>1,"×","")) | AC10: =IF(原始数据!AD10="","",IF(COUNTIF(原始数据!10:10,原始数据!AD10)>1,"×","")) | AD10: =IF(原始数据!AE10="","",IF(COUNTIF(原始数据!10:10,原始数据!AE10)>1,"×","")) | ... AN10: =IF(原始数据!AO10="","",IF(COUNTIF(原始数据!10:10,原始数据!AO10)>1,"×",""))
A11: =IF(IFERROR(原始数据!B11,"×")="×","×","") | B11: =IF(IFERROR(原始数据!C11,"×")="×","×","") | C11: =IF(IFERROR(原始数据!D11,"×")="×","×","") | D11: =IF(IFERROR(原始数据!E11,"×")="×","×","") | E11: =IF(IFERROR(原始数据!F11,"×")="×","×","") | F11: =IF(IFERROR(原始数据!G11,"×")="×","×","") | G11: =IF(IFERROR(原始数据!H11,"×")="×","×","") | H11: =IF(IFERROR(原始数据!I11,"×")="×","×","") | ... T11: =IF(IFERROR(原始数据!U11,"×")="×","×","") | U11: {=IF(原始数据!V11="-","",IF(原始数据!V11="","",IF(COUNT(FIND(原始数据!V11,原始数据!11:11))=2,"×","")))} | V11: {=IF(原始数据!W11="-","",IF(原始数据!W11="","",IF(COUNT(FIND(原始数据!W11,原始数据!11:11))=2,"×","")))} | W11: =IF(原始数据!X11="","",IF(COUNTIF(原始数据!11:11,原始数据!X11)>1,"×","")) | X11: =IF(原始数据!Y11="","",IF(COUNTIF(原始数据!11:11,原始数据!Y11)>1,"×","")) | Y11: =IF(原始数据!Z11="","",IF(COUNTIF(原始数据!11:11,原始数据!Z11)>1,"×","")) | Z11: =IF(原始数据!AA11="","",IF(COUNTIF(原始数据!11:11,原始数据!AA11)>1,"×","")) | AA11: =IF(原始数据!AB11="","",IF(COUNTIF(原始数据!11:11,原始数据!AB11)>1,"×","")) | AB11: =IF(原始数据!AC11="","",IF(COUNTIF(原始数据!11:11,原始数据!AC11)>1,"×","")) | AC11: =IF(原始数据!AD11="","",IF(COUNTIF(原始数据!11:11,原始数据!AD11)>1,"×","")) | AD11: =IF(原始数据!AE11="","",IF(COUNTIF(原始数据!11:11,原始数据!AE11)>1,"×","")) | ... AN11: =IF(原始数据!AO11="","",IF(COUNTIF(原始数据!11:11,原始数据!AO11)>1,"×",""))
A12: =IF(IFERROR(原始数据!B12,"×")="×","×","") | B12: =IF(IFERROR(原始数据!C12,"×")="×","×","") | C12: =IF(IFERROR(原始数据!D12,"×")="×","×","") | D12: =IF(IFERROR(原始数据!E12,"×")="×","×","") | E12: =IF(IFERROR(原始数据!F12,"×")="×","×","") | F12: =IF(IFERROR(原始数据!G12,"×")="×","×","") | G12: =IF(IFERROR(原始数据!H12,"×")="×","×","") | H12: =IF(IFERROR(原始数据!I12,"×")="×","×","") | ... T12: =IF(IFERROR(原始数据!U12,"×")="×","×","") | U12: {=IF(原始数据!V12="-","",IF(原始数据!V12="","",IF(COUNT(FIND(原始数据!V12,原始数据!12:12))=2,"×","")))} | V12: {=IF(原始数据!W12="-","",IF(原始数据!W12="","",IF(COUNT(FIND(原始数据!W12,原始数据!12:12))=2,"×","")))} | W12: =IF(原始数据!X12="","",IF(COUNTIF(原始数据!12:12,原始数据!X12)>1,"×","")) | X12: =IF(原始数据!Y12="","",IF(COUNTIF(原始数据!12:12,原始数据!Y12)>1,"×","")) | Y12: =IF(原始数据!Z12="","",IF(COUNTIF(原始数据!12:12,原始数据!Z12)>1,"×","")) | Z12: =IF(原始数据!AA12="","",IF(COUNTIF(原始数据!12:12,原始数据!AA12)>1,"×","")) | AA12: =IF(原始数据!AB12="","",IF(COUNTIF(原始数据!12:12,原始数据!AB12)>1,"×","")) | AB12: =IF(原始数据!AC12="","",IF(COUNTIF(原始数据!12:12,原始数据!AC12)>1,"×","")) | AC12: =IF(原始数据!AD12="","",IF(COUNTIF(原始数据!12:12,原始数据!AD12)>1,"×","")) | AD12: =IF(原始数据!AE12="","",IF(COUNTIF(原始数据!12:12,原始数据!AE12)>1,"×","")) | ... AN12: =IF(原始数据!AO12="","",IF(COUNTIF(原始数据!12:12,原始数据!AO12)>1,"×",""))
A13: =IF(IFERROR(原始数据!B13,"×")="×","×","") | B13: =IF(IFERROR(原始数据!C13,"×")="×","×","") | C13: =IF(IFERROR(原始数据!D13,"×")="×","×","") | D13: =IF(IFERROR(原始数据!E13,"×")="×","×","") | E13: =IF(IFERROR(原始数据!F13,"×")="×","×","") | F13: =IF(IFERROR(原始数据!G13,"×")="×","×","") | G13: =IF(IFERROR(原始数据!H13,"×")="×","×","") | H13: =IF(IFERROR(原始数据!I13,"×")="×","×","") | ... T13: =IF(IFERROR(原始数据!U13,"×")="×","×","") | U13: {=IF(原始数据!V13="-","",IF(原始数据!V13="","",IF(COUNT(FIND(原始数据!V13,原始数据!13:13))=2,"×","")))} | V13: {=IF(原始数据!W13="-","",IF(原始数据!W13="","",IF(COUNT(FIND(原始数据!W13,原始数据!13:13))=2,"×","")))} | W13: =IF(原始数据!X13="","",IF(COUNTIF(原始数据!13:13,原始数据!X13)>1,"×","")) | X13: =IF(原始数据!Y13="","",IF(COUNTIF(原始数据!13:13,原始数据!Y13)>1,"×","")) | Y13: =IF(原始数据!Z13="","",IF(COUNTIF(原始数据!13:13,原始数据!Z13)>1,"×","")) | Z13: =IF(原始数据!AA13="","",IF(COUNTIF(原始数据!13:13,原始数据!AA13)>1,"×","")) | AA13: =IF(原始数据!AB13="","",IF(COUNTIF(原始数据!13:13,原始数据!AB13)>1,"×","")) | AB13: =IF(原始数据!AC13="","",IF(COUNTIF(原始数据!13:13,原始数据!AC13)>1,"×","")) | AC13: =IF(原始数据!AD13="","",IF(COUNTIF(原始数据!13:13,原始数据!AD13)>1,"×","")) | AD13: =IF(原始数据!AE13="","",IF(COUNTIF(原始数据!13:13,原始数据!AE13)>1,"×","")) | ... AN13: =IF(原始数据!AO13="","",IF(COUNTIF(原始数据!13:13,原始数据!AO13)>1,"×",""))
A14: =IF(IFERROR(原始数据!B14,"×")="×","×","") | B14: =IF(IFERROR(原始数据!C14,"×")="×","×","") | C14: =IF(IFERROR(原始数据!D14,"×")="×","×","") | D14: =IF(IFERROR(原始数据!E14,"×")="×","×","") | E14: =IF(IFERROR(原始数据!F14,"×")="×","×","") | F14: =IF(IFERROR(原始数据!G14,"×")="×","×","") | G14: =IF(IFERROR(原始数据!H14,"×")="×","×","") | H14: =IF(IFERROR(原始数据!I14,"×")="×","×","") | ... T14: =IF(IFERROR(原始数据!U14,"×")="×","×","") | U14: {=IF(原始数据!V14="-","",IF(原始数据!V14="","",IF(COUNT(FIND(原始数据!V14,原始数据!14:14))=2,"×","")))} | V14: {=IF(原始数据!W14="-","",IF(原始数据!W14="","",IF(COUNT(FIND(原始数据!W14,原始数据!14:14))=2,"×","")))} | W14: =IF(原始数据!X14="","",IF(COUNTIF(原始数据!14:14,原始数据!X14)>1,"×","")) | X14: =IF(原始数据!Y14="","",IF(COUNTIF(原始数据!14:14,原始数据!Y14)>1,"×","")) | Y14: =IF(原始数据!Z14="","",IF(COUNTIF(原始数据!14:14,原始数据!Z14)>1,"×","")) | Z14: =IF(原始数据!AA14="","",IF(COUNTIF(原始数据!14:14,原始数据!AA14)>1,"×","")) | AA14: =IF(原始数据!AB14="","",IF(COUNTIF(原始数据!14:14,原始数据!AB14)>1,"×","")) | AB14: =IF(原始数据!AC14="","",IF(COUNTIF(原始数据!14:14,原始数据!AC14)>1,"×","")) | AC14: =IF(原始数据!AD14="","",IF(COUNTIF(原始数据!14:14,原始数据!AD14)>1,"×","")) | AD14: =IF(原始数据!AE14="","",IF(COUNTIF(原始数据!14:14,原始数据!AE14)>1,"×","")) | ... AN14: =IF(原始数据!AO14="","",IF(COUNTIF(原始数据!14:14,原始数据!AO14)>1,"×",""))
A15: =IF(IFERROR(原始数据!B15,"×")="×","×","") | B15: =IF(IFERROR(原始数据!C15,"×")="×","×","") | C15: =IF(IFERROR(原始数据!D15,"×")="×","×","") | D15: =IF(IFERROR(原始数据!E15,"×")="×","×","") | E15: =IF(IFERROR(原始数据!F15,"×")="×","×","") | F15: =IF(IFERROR(原始数据!G15,"×")="×","×","") | G15: =IF(IFERROR(原始数据!H15,"×")="×","×","") | H15: =IF(IFERROR(原始数据!I15,"×")="×","×","") | ... T15: =IF(IFERROR(原始数据!U15,"×")="×","×","") | U15: {=IF(原始数据!V15="-","",IF(原始数据!V15="","",IF(COUNT(FIND(原始数据!V15,原始数据!15:15))=2,"×","")))} | V15: {=IF(原始数据!W15="-","",IF(原始数据!W15="","",IF(COUNT(FIND(原始数据!W15,原始数据!15:15))=2,"×","")))} | W15: =IF(原始数据!X15="","",IF(COUNTIF(原始数据!15:15,原始数据!X15)>1,"×","")) | X15: =IF(原始数据!Y15="","",IF(COUNTIF(原始数据!15:15,原始数据!Y15)>1,"×","")) | Y15: =IF(原始数据!Z15="","",IF(COUNTIF(原始数据!15:15,原始数据!Z15)>1,"×","")) | Z15: =IF(原始数据!AA15="","",IF(COUNTIF(原始数据!15:15,原始数据!AA15)>1,"×","")) | AA15: =IF(原始数据!AB15="","",IF(COUNTIF(原始数据!15:15,原始数据!AB15)>1,"×","")) | AB15: =IF(原始数据!AC15="","",IF(COUNTIF(原始数据!15:15,原始数据!AC15)>1,"×","")) | AC15: =IF(原始数据!AD15="","",IF(COUNTIF(原始数据!15:15,原始数据!AD15)>1,"×","")) | AD15: =IF(原始数据!AE15="","",IF(COUNTIF(原始数据!15:15,原始数据!AE15)>1,"×","")) | ... AN15: =IF(原始数据!AO15="","",IF(COUNTIF(原始数据!15:15,原始数据!AO15)>1,"×",""))
A16: =IF(IFERROR(原始数据!B16,"×")="×","×","") | B16: =IF(IFERROR(原始数据!C16,"×")="×","×","") | C16: =IF(IFERROR(原始数据!D16,"×")="×","×","") | D16: =IF(IFERROR(原始数据!E16,"×")="×","×","") | E16: =IF(IFERROR(原始数据!F16,"×")="×","×","") | F16: =IF(IFERROR(原始数据!G16,"×")="×","×","") | G16: =IF(IFERROR(原始数据!H16,"×")="×","×","") | H16: =IF(IFERROR(原始数据!I16,"×")="×","×","") | ... T16: =IF(IFERROR(原始数据!U16,"×")="×","×","") | U16: {=IF(原始数据!V16="-","",IF(原始数据!V16="","",IF(COUNT(FIND(原始数据!V16,原始数据!16:16))=2,"×","")))} | V16: {=IF(原始数据!W16="-","",IF(原始数据!W16="","",IF(COUNT(FIND(原始数据!W16,原始数据!16:16))=2,"×","")))} | W16: =IF(原始数据!X16="","",IF(COUNTIF(原始数据!16:16,原始数据!X16)>1,"×","")) | X16: =IF(原始数据!Y16="","",IF(COUNTIF(原始数据!16:16,原始数据!Y16)>1,"×","")) | Y16: =IF(原始数据!Z16="","",IF(COUNTIF(原始数据!16:16,原始数据!Z16)>1,"×","")) | Z16: =IF(原始数据!AA16="","",IF(COUNTIF(原始数据!16:16,原始数据!AA16)>1,"×","")) | AA16: =IF(原始数据!AB16="","",IF(COUNTIF(原始数据!16:16,原始数据!AB16)>1,"×","")) | AB16: =IF(原始数据!AC16="","",IF(COUNTIF(原始数据!16:16,原始数据!AC16)>1,"×","")) | AC16: =IF(原始数据!AD16="","",IF(COUNTIF(原始数据!16:16,原始数据!AD16)>1,"×","")) | AD16: =IF(原始数据!AE16="","",IF(COUNTIF(原始数据!16:16,原始数据!AE16)>1,"×","")) | ... AN16: =IF(原始数据!AO16="","",IF(COUNTIF(原始数据!16:16,原始数据!AO16)>1,"×",""))
A17: =IF(IFERROR(原始数据!B17,"×")="×","×","") | B17: =IF(IFERROR(原始数据!C17,"×")="×","×","") | C17: =IF(IFERROR(原始数据!D17,"×")="×","×","") | D17: =IF(IFERROR(原始数据!E17,"×")="×","×","") | E17: =IF(IFERROR(原始数据!F17,"×")="×","×","") | F17: =IF(IFERROR(原始数据!G17,"×")="×","×","") | G17: =IF(IFERROR(原始数据!H17,"×")="×","×","") | H17: =IF(IFERROR(原始数据!I17,"×")="×","×","") | ... T17: =IF(IFERROR(原始数据!U17,"×")="×","×","") | U17: {=IF(原始数据!V17="-","",IF(原始数据!V17="","",IF(COUNT(FIND(原始数据!V17,原始数据!17:17))=2,"×","")))} | V17: {=IF(原始数据!W17="-","",IF(原始数据!W17="","",IF(COUNT(FIND(原始数据!W17,原始数据!17:17))=2,"×","")))} | W17: =IF(原始数据!X17="","",IF(COUNTIF(原始数据!17:17,原始数据!X17)>1,"×","")) | X17: =IF(原始数据!Y17="","",IF(COUNTIF(原始数据!17:17,原始数据!Y17)>1,"×","")) | Y17: =IF(原始数据!Z17="","",IF(COUNTIF(原始数据!17:17,原始数据!Z17)>1,"×","")) | Z17: =IF(原始数据!AA17="","",IF(COUNTIF(原始数据!17:17,原始数据!AA17)>1,"×","")) | AA17: =IF(原始数据!AB17="","",IF(COUNTIF(原始数据!17:17,原始数据!AB17)>1,"×","")) | AB17: =IF(原始数据!AC17="","",IF(COUNTIF(原始数据!17:17,原始数据!AC17)>1,"×","")) | AC17: =IF(原始数据!AD17="","",IF(COUNTIF(原始数据!17:17,原始数据!AD17)>1,"×","")) | AD17: =IF(原始数据!AE17="","",IF(COUNTIF(原始数据!17:17,原始数据!AE17)>1,"×","")) | ... AN17: =IF(原始数据!AO17="","",IF(COUNTIF(原始数据!17:17,原始数据!AO17)>1,"×",""))
A18: =IF(IFERROR(原始数据!B18,"×")="×","×","") | B18: =IF(IFERROR(原始数据!C18,"×")="×","×","") | C18: =IF(IFERROR(原始数据!D18,"×")="×","×","") | D18: =IF(IFERROR(原始数据!E18,"×")="×","×","") | E18: =IF(IFERROR(原始数据!F18,"×")="×","×","") | F18: =IF(IFERROR(原始数据!G18,"×")="×","×","") | G18: =IF(IFERROR(原始数据!H18,"×")="×","×","") | H18: =IF(IFERROR(原始数据!I18,"×")="×","×","") | ... T18: =IF(IFERROR(原始数据!U18,"×")="×","×","") | U18: {=IF(原始数据!V18="-","",IF(原始数据!V18="","",IF(COUNT(FIND(原始数据!V18,原始数据!18:18))=2,"×","")))} | V18: {=IF(原始数据!W18="-","",IF(原始数据!W18="","",IF(COUNT(FIND(原始数据!W18,原始数据!18:18))=2,"×","")))} | W18: =IF(原始数据!X18="","",IF(COUNTIF(原始数据!18:18,原始数据!X18)>1,"×","")) | X18: =IF(原始数据!Y18="","",IF(COUNTIF(原始数据!18:18,原始数据!Y18)>1,"×","")) | Y18: =IF(原始数据!Z18="","",IF(COUNTIF(原始数据!18:18,原始数据!Z18)>1,"×","")) | Z18: =IF(原始数据!AA18="","",IF(COUNTIF(原始数据!18:18,原始数据!AA18)>1,"×","")) | AA18: =IF(原始数据!AB18="","",IF(COUNTIF(原始数据!18:18,原始数据!AB18)>1,"×","")) | AB18: =IF(原始数据!AC18="","",IF(COUNTIF(原始数据!18:18,原始数据!AC18)>1,"×","")) | AC18: =IF(原始数据!AD18="","",IF(COUNTIF(原始数据!18:18,原始数据!AD18)>1,"×","")) | AD18: =IF(原始数据!AE18="","",IF(COUNTIF(原始数据!18:18,原始数据!AE18)>1,"×","")) | ... AN18: =IF(原始数据!AO18="","",IF(COUNTIF(原始数据!18:18,原始数据!AO18)>1,"×",""))
A19: =IF(IFERROR(原始数据!B19,"×")="×","×","") | B19: =IF(IFERROR(原始数据!C19,"×")="×","×","") | C19: =IF(IFERROR(原始数据!D19,"×")="×","×","") | D19: =IF(IFERROR(原始数据!E19,"×")="×","×","") | E19: =IF(IFERROR(原始数据!F19,"×")="×","×","") | F19: =IF(IFERROR(原始数据!G19,"×")="×","×","") | G19: =IF(IFERROR(原始数据!H19,"×")="×","×","") | H19: =IF(IFERROR(原始数据!I19,"×")="×","×","") | ... T19: =IF(IFERROR(原始数据!U19,"×")="×","×","") | U19: {=IF(原始数据!V19="-","",IF(原始数据!V19="","",IF(COUNT(FIND(原始数据!V19,原始数据!19:19))=2,"×","")))} | V19: {=IF(原始数据!W19="-","",IF(原始数据!W19="","",IF(COUNT(FIND(原始数据!W19,原始数据!19:19))=2,"×","")))} | W19: =IF(原始数据!X19="","",IF(COUNTIF(原始数据!19:19,原始数据!X19)>1,"×","")) | X19: =IF(原始数据!Y19="","",IF(COUNTIF(原始数据!19:19,原始数据!Y19)>1,"×","")) | Y19: =IF(原始数据!Z19="","",IF(COUNTIF(原始数据!19:19,原始数据!Z19)>1,"×","")) | Z19: =IF(原始数据!AA19="","",IF(COUNTIF(原始数据!19:19,原始数据!AA19)>1,"×","")) | AA19: =IF(原始数据!AB19="","",IF(COUNTIF(原始数据!19:19,原始数据!AB19)>1,"×","")) | AB19: =IF(原始数据!AC19="","",IF(COUNTIF(原始数据!19:19,原始数据!AC19)>1,"×","")) | AC19: =IF(原始数据!AD19="","",IF(COUNTIF(原始数据!19:19,原始数据!AD19)>1,"×","")) | AD19: =IF(原始数据!AE19="","",IF(COUNTIF(原始数据!19:19,原始数据!AE19)>1,"×","")) | ... AN19: =IF(原始数据!AO19="","",IF(COUNTIF(原始数据!19:19,原始数据!AO19)>1,"×",""))
A20: =IF(IFERROR(原始数据!B20,"×")="×","×","") | B20: =IF(IFERROR(原始数据!C20,"×")="×","×","") | C20: =IF(IFERROR(原始数据!D20,"×")="×","×","") | D20: =IF(IFERROR(原始数据!E20,"×")="×","×","") | E20: =IF(IFERROR(原始数据!F20,"×")="×","×","") | F20: =IF(IFERROR(原始数据!G20,"×")="×","×","") | G20: =IF(IFERROR(原始数据!H20,"×")="×","×","") | H20: =IF(IFERROR(原始数据!I20,"×")="×","×","") | ... T20: =IF(IFERROR(原始数据!U20,"×")="×","×","") | U20: {=IF(原始数据!V20="-","",IF(原始数据!V20="","",IF(COUNT(FIND(原始数据!V20,原始数据!20:20))=2,"×","")))} | V20: {=IF(原始数据!W20="-","",IF(原始数据!W20="","",IF(COUNT(FIND(原始数据!W20,原始数据!20:20))=2,"×","")))} | W20: =IF(原始数据!X20="","",IF(COUNTIF(原始数据!20:20,原始数据!X20)>1,"×","")) | X20: =IF(原始数据!Y20="","",IF(COUNTIF(原始数据!20:20,原始数据!Y20)>1,"×","")) | Y20: =IF(原始数据!Z20="","",IF(COUNTIF(原始数据!20:20,原始数据!Z20)>1,"×","")) | Z20: =IF(原始数据!AA20="","",IF(COUNTIF(原始数据!20:20,原始数据!AA20)>1,"×","")) | AA20: =IF(原始数据!AB20="","",IF(COUNTIF(原始数据!20:20,原始数据!AB20)>1,"×","")) | AB20: =IF(原始数据!AC20="","",IF(COUNTIF(原始数据!20:20,原始数据!AC20)>1,"×","")) | AC20: =IF(原始数据!AD20="","",IF(COUNTIF(原始数据!20:20,原始数据!AD20)>1,"×","")) | AD20: =IF(原始数据!AE20="","",IF(COUNTIF(原始数据!20:20,原始数据!AE20)>1,"×","")) | ... AN20: =IF(原始数据!AO20="","",IF(COUNTIF(原始数据!20:20,原始数据!AO20)>1,"×",""))
A21: =IF(IFERROR(原始数据!B21,"×")="×","×","") | B21: =IF(IFERROR(原始数据!C21,"×")="×","×","") | C21: =IF(IFERROR(原始数据!D21,"×")="×","×","") | D21: =IF(IFERROR(原始数据!E21,"×")="×","×","") | E21: =IF(IFERROR(原始数据!F21,"×")="×","×","") | F21: =IF(IFERROR(原始数据!G21,"×")="×","×","") | G21: =IF(IFERROR(原始数据!H21,"×")="×","×","") | H21: =IF(IFERROR(原始数据!I21,"×")="×","×","") | ... T21: =IF(IFERROR(原始数据!U21,"×")="×","×","") | U21: {=IF(原始数据!V21="-","",IF(原始数据!V21="","",IF(COUNT(FIND(原始数据!V21,原始数据!21:21))=2,"×","")))} | V21: {=IF(原始数据!W21="-","",IF(原始数据!W21="","",IF(COUNT(FIND(原始数据!W21,原始数据!21:21))=2,"×","")))} | W21: =IF(原始数据!X21="","",IF(COUNTIF(原始数据!21:21,原始数据!X21)>1,"×","")) | X21: =IF(原始数据!Y21="","",IF(COUNTIF(原始数据!21:21,原始数据!Y21)>1,"×","")) | Y21: =IF(原始数据!Z21="","",IF(COUNTIF(原始数据!21:21,原始数据!Z21)>1,"×","")) | Z21: =IF(原始数据!AA21="","",IF(COUNTIF(原始数据!21:21,原始数据!AA21)>1,"×","")) | AA21: =IF(原始数据!AB21="","",IF(COUNTIF(原始数据!21:21,原始数据!AB21)>1,"×","")) | AB21: =IF(原始数据!AC21="","",IF(COUNTIF(原始数据!21:21,原始数据!AC21)>1,"×","")) | AC21: =IF(原始数据!AD21="","",IF(COUNTIF(原始数据!21:21,原始数据!AD21)>1,"×","")) | AD21: =IF(原始数据!AE21="","",IF(COUNTIF(原始数据!21:21,原始数据!AE21)>1,"×","")) | ... AN21: =IF(原始数据!AO21="","",IF(COUNTIF(原始数据!21:21,原始数据!AO21)>1,"×",""))
A22: =IF(IFERROR(原始数据!B22,"×")="×","×","") | B22: =IF(IFERROR(原始数据!C22,"×")="×","×","") | C22: =IF(IFERROR(原始数据!D22,"×")="×","×","") | D22: =IF(IFERROR(原始数据!E22,"×")="×","×","") | E22: =IF(IFERROR(原始数据!F22,"×")="×","×","") | F22: =IF(IFERROR(原始数据!G22,"×")="×","×","") | G22: =IF(IFERROR(原始数据!H22,"×")="×","×","") | H22: =IF(IFERROR(原始数据!I22,"×")="×","×","") | ... T22: =IF(IFERROR(原始数据!U22,"×")="×","×","") | U22: {=IF(原始数据!V22="-","",IF(原始数据!V22="","",IF(COUNT(FIND(原始数据!V22,原始数据!22:22))=2,"×","")))} | V22: {=IF(原始数据!W22="-","",IF(原始数据!W22="","",IF(COUNT(FIND(原始数据!W22,原始数据!22:22))=2,"×","")))} | W22: =IF(原始数据!X22="","",IF(COUNTIF(原始数据!22:22,原始数据!X22)>1,"×","")) | X22: =IF(原始数据!Y22="","",IF(COUNTIF(原始数据!22:22,原始数据!Y22)>1,"×","")) | Y22: =IF(原始数据!Z22="","",IF(COUNTIF(原始数据!22:22,原始数据!Z22)>1,"×","")) | Z22: =IF(原始数据!AA22="","",IF(COUNTIF(原始数据!22:22,原始数据!AA22)>1,"×","")) | AA22: =IF(原始数据!AB22="","",IF(COUNTIF(原始数据!22:22,原始数据!AB22)>1,"×","")) | AB22: =IF(原始数据!AC22="","",IF(COUNTIF(原始数据!22:22,原始数据!AC22)>1,"×","")) | AC22: =IF(原始数据!AD22="","",IF(COUNTIF(原始数据!22:22,原始数据!AD22)>1,"×","")) | AD22: =IF(原始数据!AE22="","",IF(COUNTIF(原始数据!22:22,原始数据!AE22)>1,"×","")) | ... AN22: =IF(原始数据!AO22="","",IF(COUNTIF(原始数据!22:22,原始数据!AO22)>1,"×",""))
A23: =IF(IFERROR(原始数据!B23,"×")="×","×","") | B23: =IF(IFERROR(原始数据!C23,"×")="×","×","") | C23: =IF(IFERROR(原始数据!D23,"×")="×","×","") | D23: =IF(IFERROR(原始数据!E23,"×")="×","×","") | E23: =IF(IFERROR(原始数据!F23,"×")="×","×","") | F23: =IF(IFERROR(原始数据!G23,"×")="×","×","") | G23: =IF(IFERROR(原始数据!H23,"×")="×","×","") | H23: =IF(IFERROR(原始数据!I23,"×")="×","×","") | ... T23: =IF(IFERROR(原始数据!U23,"×")="×","×","") | U23: {=IF(原始数据!V23="-","",IF(原始数据!V23="","",IF(COUNT(FIND(原始数据!V23,原始数据!23:23))=2,"×","")))} | V23: {=IF(原始数据!W23="-","",IF(原始数据!W23="","",IF(COUNT(FIND(原始数据!W23,原始数据!23:23))=2,"×","")))} | W23: =IF(原始数据!X23="","",IF(COUNTIF(原始数据!23:23,原始数据!X23)>1,"×","")) | X23: =IF(原始数据!Y23="","",IF(COUNTIF(原始数据!23:23,原始数据!Y23)>1,"×","")) | Y23: =IF(原始数据!Z23="","",IF(COUNTIF(原始数据!23:23,原始数据!Z23)>1,"×","")) | Z23: =IF(原始数据!AA23="","",IF(COUNTIF(原始数据!23:23,原始数据!AA23)>1,"×","")) | AA23: =IF(原始数据!AB23="","",IF(COUNTIF(原始数据!23:23,原始数据!AB23)>1,"×","")) | AB23: =IF(原始数据!AC23="","",IF(COUNTIF(原始数据!23:23,原始数据!AC23)>1,"×","")) | AC23: =IF(原始数据!AD23="","",IF(COUNTIF(原始数据!23:23,原始数据!AD23)>1,"×","")) | AD23: =IF(原始数据!AE23="","",IF(COUNTIF(原始数据!23:23,原始数据!AE23)>1,"×","")) | ... AN23: =IF(原始数据!AO23="","",IF(COUNTIF(原始数据!23:23,原始数据!AO23)>1,"×",""))
A24: =IF(IFERROR(原始数据!B24,"×")="×","×","") | B24: =IF(IFERROR(原始数据!C24,"×")="×","×","") | C24: =IF(IFERROR(原始数据!D24,"×")="×","×","") | D24: =IF(IFERROR(原始数据!E24,"×")="×","×","") | E24: =IF(IFERROR(原始数据!F24,"×")="×","×","") | F24: =IF(IFERROR(原始数据!G24,"×")="×","×","") | G24: =IF(IFERROR(原始数据!H24,"×")="×","×","") | H24: =IF(IFERROR(原始数据!I24,"×")="×","×","") | ... T24: =IF(IFERROR(原始数据!U24,"×")="×","×","") | U24: {=IF(原始数据!V24="-","",IF(原始数据!V24="","",IF(COUNT(FIND(原始数据!V24,原始数据!24:24))=2,"×","")))} | V24: {=IF(原始数据!W24="-","",IF(原始数据!W24="","",IF(COUNT(FIND(原始数据!W24,原始数据!24:24))=2,"×","")))} | W24: =IF(原始数据!X24="","",IF(COUNTIF(原始数据!24:24,原始数据!X24)>1,"×","")) | X24: =IF(原始数据!Y24="","",IF(COUNTIF(原始数据!24:24,原始数据!Y24)>1,"×","")) | Y24: =IF(原始数据!Z24="","",IF(COUNTIF(原始数据!24:24,原始数据!Z24)>1,"×","")) | Z24: =IF(原始数据!AA24="","",IF(COUNTIF(原始数据!24:24,原始数据!AA24)>1,"×","")) | AA24: =IF(原始数据!AB24="","",IF(COUNTIF(原始数据!24:24,原始数据!AB24)>1,"×","")) | AB24: =IF(原始数据!AC24="","",IF(COUNTIF(原始数据!24:24,原始数据!AC24)>1,"×","")) | AC24: =IF(原始数据!AD24="","",IF(COUNTIF(原始数据!24:24,原始数据!AD24)>1,"×","")) | AD24: =IF(原始数据!AE24="","",IF(COUNTIF(原始数据!24:24,原始数据!AE24)>1,"×","")) | ... AN24: =IF(原始数据!AO24="","",IF(COUNTIF(原始数据!24:24,原始数据!AO24)>1,"×",""))
A25: =IF(IFERROR(原始数据!B25,"×")="×","×","") | B25: =IF(IFERROR(原始数据!C25,"×")="×","×","") | C25: =IF(IFERROR(原始数据!D25,"×")="×","×","") | D25: =IF(IFERROR(原始数据!E25,"×")="×","×","") | E25: =IF(IFERROR(原始数据!F25,"×")="×","×","") | F25: =IF(IFERROR(原始数据!G25,"×")="×","×","") | G25: =IF(IFERROR(原始数据!H25,"×")="×","×","") | H25: =IF(IFERROR(原始数据!I25,"×")="×","×","") | ... T25: =IF(IFERROR(原始数据!U25,"×")="×","×","") | U25: {=IF(原始数据!V25="-","",IF(原始数据!V25="","",IF(COUNT(FIND(原始数据!V25,原始数据!25:25))=2,"×","")))} | V25: {=IF(原始数据!W25="-","",IF(原始数据!W25="","",IF(COUNT(FIND(原始数据!W25,原始数据!25:25))=2,"×","")))} | W25: =IF(原始数据!X25="","",IF(COUNTIF(原始数据!25:25,原始数据!X25)>1,"×","")) | X25: =IF(原始数据!Y25="","",IF(COUNTIF(原始数据!25:25,原始数据!Y25)>1,"×","")) | Y25: =IF(原始数据!Z25="","",IF(COUNTIF(原始数据!25:25,原始数据!Z25)>1,"×","")) | Z25: =IF(原始数据!AA25="","",IF(COUNTIF(原始数据!25:25,原始数据!AA25)>1,"×","")) | AA25: =IF(原始数据!AB25="","",IF(COUNTIF(原始数据!25:25,原始数据!AB25)>1,"×","")) | AB25: =IF(原始数据!AC25="","",IF(COUNTIF(原始数据!25:25,原始数据!AC25)>1,"×","")) | AC25: =IF(原始数据!AD25="","",IF(COUNTIF(原始数据!25:25,原始数据!AD25)>1,"×","")) | AD25: =IF(原始数据!AE25="","",IF(COUNTIF(原始数据!25:25,原始数据!AE25)>1,"×","")) | ... AN25: =IF(原始数据!AO25="","",IF(COUNTIF(原始数据!25:25,原始数据!AO25)>1,"×",""))
A26: =IF(IFERROR(原始数据!B26,"×")="×","×","") | B26: =IF(IFERROR(原始数据!C26,"×")="×","×","") | C26: =IF(IFERROR(原始数据!D26,"×")="×","×","") | D26: =IF(IFERROR(原始数据!E26,"×")="×","×","") | E26: =IF(IFERROR(原始数据!F26,"×")="×","×","") | F26: =IF(IFERROR(原始数据!G26,"×")="×","×","") | G26: =IF(IFERROR(原始数据!H26,"×")="×","×","") | H26: =IF(IFERROR(原始数据!I26,"×")="×","×","") | ... T26: =IF(IFERROR(原始数据!U26,"×")="×","×","") | U26: {=IF(原始数据!V26="-","",IF(原始数据!V26="","",IF(COUNT(FIND(原始数据!V26,原始数据!26:26))=2,"×","")))} | V26: {=IF(原始数据!W26="-","",IF(原始数据!W26="","",IF(COUNT(FIND(原始数据!W26,原始数据!26:26))=2,"×","")))} | W26: =IF(原始数据!X26="","",IF(COUNTIF(原始数据!26:26,原始数据!X26)>1,"×","")) | X26: =IF(原始数据!Y26="","",IF(COUNTIF(原始数据!26:26,原始数据!Y26)>1,"×","")) | Y26: =IF(原始数据!Z26="","",IF(COUNTIF(原始数据!26:26,原始数据!Z26)>1,"×","")) | Z26: =IF(原始数据!AA26="","",IF(COUNTIF(原始数据!26:26,原始数据!AA26)>1,"×","")) | AA26: =IF(原始数据!AB26="","",IF(COUNTIF(原始数据!26:26,原始数据!AB26)>1,"×","")) | AB26: =IF(原始数据!AC26="","",IF(COUNTIF(原始数据!26:26,原始数据!AC26)>1,"×","")) | AC26: =IF(原始数据!AD26="","",IF(COUNTIF(原始数据!26:26,原始数据!AD26)>1,"×","")) | AD26: =IF(原始数据!AE26="","",IF(COUNTIF(原始数据!26:26,原始数据!AE26)>1,"×","")) | ... AN26: =IF(原始数据!AO26="","",IF(COUNTIF(原始数据!26:26,原始数据!AO26)>1,"×",""))
A27: =IF(IFERROR(原始数据!B27,"×")="×","×","") | B27: =IF(IFERROR(原始数据!C27,"×")="×","×","") | C27: =IF(IFERROR(原始数据!D27,"×")="×","×","") | D27: =IF(IFERROR(原始数据!E27,"×")="×","×","") | E27: =IF(IFERROR(原始数据!F27,"×")="×","×","") | F27: =IF(IFERROR(原始数据!G27,"×")="×","×","") | G27: =IF(IFERROR(原始数据!H27,"×")="×","×","") | H27: =IF(IFERROR(原始数据!I27,"×")="×","×","") | ... T27: =IF(IFERROR(原始数据!U27,"×")="×","×","") | U27: {=IF(原始数据!V27="-","",IF(原始数据!V27="","",IF(COUNT(FIND(原始数据!V27,原始数据!27:27))=2,"×","")))} | V27: {=IF(原始数据!W27="-","",IF(原始数据!W27="","",IF(COUNT(FIND(原始数据!W27,原始数据!27:27))=2,"×","")))} | W27: =IF(原始数据!X27="","",IF(COUNTIF(原始数据!27:27,原始数据!X27)>1,"×","")) | X27: =IF(原始数据!Y27="","",IF(COUNTIF(原始数据!27:27,原始数据!Y27)>1,"×","")) | Y27: =IF(原始数据!Z27="","",IF(COUNTIF(原始数据!27:27,原始数据!Z27)>1,"×","")) | Z27: =IF(原始数据!AA27="","",IF(COUNTIF(原始数据!27:27,原始数据!AA27)>1,"×","")) | AA27: =IF(原始数据!AB27="","",IF(COUNTIF(原始数据!27:27,原始数据!AB27)>1,"×","")) | AB27: =IF(原始数据!AC27="","",IF(COUNTIF(原始数据!27:27,原始数据!AC27)>1,"×","")) | AC27: =IF(原始数据!AD27="","",IF(COUNTIF(原始数据!27:27,原始数据!AD27)>1,"×","")) | AD27: =IF(原始数据!AE27="","",IF(COUNTIF(原始数据!27:27,原始数据!AE27)>1,"×","")) | ... AN27: =IF(原始数据!AO27="","",IF(COUNTIF(原始数据!27:27,原始数据!AO27)>1,"×",""))
A28: =IF(IFERROR(原始数据!B28,"×")="×","×","") | B28: =IF(IFERROR(原始数据!C28,"×")="×","×","") | C28: =IF(IFERROR(原始数据!D28,"×")="×","×","") | D28: =IF(IFERROR(原始数据!E28,"×")="×","×","") | E28: =IF(IFERROR(原始数据!F28,"×")="×","×","") | F28: =IF(IFERROR(原始数据!G28,"×")="×","×","") | G28: =IF(IFERROR(原始数据!H28,"×")="×","×","") | H28: =IF(IFERROR(原始数据!I28,"×")="×","×","") | ... T28: =IF(IFERROR(原始数据!U28,"×")="×","×","") | U28: {=IF(原始数据!V28="-","",IF(原始数据!V28="","",IF(COUNT(FIND(原始数据!V28,原始数据!28:28))=2,"×","")))} | V28: {=IF(原始数据!W28="-","",IF(原始数据!W28="","",IF(COUNT(FIND(原始数据!W28,原始数据!28:28))=2,"×","")))} | W28: =IF(原始数据!X28="","",IF(COUNTIF(原始数据!28:28,原始数据!X28)>1,"×","")) | X28: =IF(原始数据!Y28="","",IF(COUNTIF(原始数据!28:28,原始数据!Y28)>1,"×","")) | Y28: =IF(原始数据!Z28="","",IF(COUNTIF(原始数据!28:28,原始数据!Z28)>1,"×","")) | Z28: =IF(原始数据!AA28="","",IF(COUNTIF(原始数据!28:28,原始数据!AA28)>1,"×","")) | AA28: =IF(原始数据!AB28="","",IF(COUNTIF(原始数据!28:28,原始数据!AB28)>1,"×","")) | AB28: =IF(原始数据!AC28="","",IF(COUNTIF(原始数据!28:28,原始数据!AC28)>1,"×","")) | AC28: =IF(原始数据!AD28="","",IF(COUNTIF(原始数据!28:28,原始数据!AD28)>1,"×","")) | AD28: =IF(原始数据!AE28="","",IF(COUNTIF(原始数据!28:28,原始数据!AE28)>1,"×","")) | ... AN28: =IF(原始数据!AO28="","",IF(COUNTIF(原始数据!28:28,原始数据!AO28)>1,"×",""))
A29: =IF(IFERROR(原始数据!B29,"×")="×","×","") | B29: =IF(IFERROR(原始数据!C29,"×")="×","×","") | C29: =IF(IFERROR(原始数据!D29,"×")="×","×","") | D29: =IF(IFERROR(原始数据!E29,"×")="×","×","") | E29: =IF(IFERROR(原始数据!F29,"×")="×","×","") | F29: =IF(IFERROR(原始数据!G29,"×")="×","×","") | G29: =IF(IFERROR(原始数据!H29,"×")="×","×","") | H29: =IF(IFERROR(原始数据!I29,"×")="×","×","") | ... T29: =IF(IFERROR(原始数据!U29,"×")="×","×","") | U29: {=IF(原始数据!V29="-","",IF(原始数据!V29="","",IF(COUNT(FIND(原始数据!V29,原始数据!29:29))=2,"×","")))} | V29: {=IF(原始数据!W29="-","",IF(原始数据!W29="","",IF(COUNT(FIND(原始数据!W29,原始数据!29:29))=2,"×","")))} | W29: =IF(原始数据!X29="","",IF(COUNTIF(原始数据!29:29,原始数据!X29)>1,"×","")) | X29: =IF(原始数据!Y29="","",IF(COUNTIF(原始数据!29:29,原始数据!Y29)>1,"×","")) | Y29: =IF(原始数据!Z29="","",IF(COUNTIF(原始数据!29:29,原始数据!Z29)>1,"×","")) | Z29: =IF(原始数据!AA29="","",IF(COUNTIF(原始数据!29:29,原始数据!AA29)>1,"×","")) | AA29: =IF(原始数据!AB29="","",IF(COUNTIF(原始数据!29:29,原始数据!AB29)>1,"×","")) | AB29: =IF(原始数据!AC29="","",IF(COUNTIF(原始数据!29:29,原始数据!AC29)>1,"×","")) | AC29: =IF(原始数据!AD29="","",IF(COUNTIF(原始数据!29:29,原始数据!AD29)>1,"×","")) | AD29: =IF(原始数据!AE29="","",IF(COUNTIF(原始数据!29:29,原始数据!AE29)>1,"×","")) | ... AN29: =IF(原始数据!AO29="","",IF(COUNTIF(原始数据!29:29,原始数据!AO29)>1,"×",""))
A30: =IF(IFERROR(原始数据!B30,"×")="×","×","") | B30: =IF(IFERROR(原始数据!C30,"×")="×","×","") | C30: =IF(IFERROR(原始数据!D30,"×")="×","×","") | D30: =IF(IFERROR(原始数据!E30,"×")="×","×","") | E30: =IF(IFERROR(原始数据!F30,"×")="×","×","") | F30: =IF(IFERROR(原始数据!G30,"×")="×","×","") | G30: =IF(IFERROR(原始数据!H30,"×")="×","×","") | H30: =IF(IFERROR(原始数据!I30,"×")="×","×","") | ... T30: =IF(IFERROR(原始数据!U30,"×")="×","×","") | U30: {=IF(原始数据!V30="-","",IF(原始数据!V30="","",IF(COUNT(FIND(原始数据!V30,原始数据!30:30))=2,"×","")))} | V30: {=IF(原始数据!W30="-","",IF(原始数据!W30="","",IF(COUNT(FIND(原始数据!W30,原始数据!30:30))=2,"×","")))} | W30: =IF(原始数据!X30="","",IF(COUNTIF(原始数据!30:30,原始数据!X30)>1,"×","")) | X30: =IF(原始数据!Y30="","",IF(COUNTIF(原始数据!30:30,原始数据!Y30)>1,"×","")) | Y30: =IF(原始数据!Z30="","",IF(COUNTIF(原始数据!30:30,原始数据!Z30)>1,"×","")) | Z30: =IF(原始数据!AA30="","",IF(COUNTIF(原始数据!30:30,原始数据!AA30)>1,"×","")) | AA30: =IF(原始数据!AB30="","",IF(COUNTIF(原始数据!30:30,原始数据!AB30)>1,"×","")) | AB30: =IF(原始数据!AC30="","",IF(COUNTIF(原始数据!30:30,原始数据!AC30)>1,"×","")) | AC30: =IF(原始数据!AD30="","",IF(COUNTIF(原始数据!30:30,原始数据!AD30)>1,"×","")) | AD30: =IF(原始数据!AE30="","",IF(COUNTIF(原始数据!30:30,原始数据!AE30)>1,"×","")) | ... AN30: =IF(原始数据!AO30="","",IF(COUNTIF(原始数据!30:30,原始数据!AO30)>1,"×",""))
A31: =IF(IFERROR(原始数据!B31,"×")="×","×","") | B31: =IF(IFERROR(原始数据!C31,"×")="×","×","") | C31: =IF(IFERROR(原始数据!D31,"×")="×","×","") | D31: =IF(IFERROR(原始数据!E31,"×")="×","×","") | E31: =IF(IFERROR(原始数据!F31,"×")="×","×","") | F31: =IF(IFERROR(原始数据!G31,"×")="×","×","") | G31: =IF(IFERROR(原始数据!H31,"×")="×","×","") | H31: =IF(IFERROR(原始数据!I31,"×")="×","×","") | ... T31: =IF(IFERROR(原始数据!U31,"×")="×","×","") | U31: {=IF(原始数据!V31="-","",IF(原始数据!V31="","",IF(COUNT(FIND(原始数据!V31,原始数据!31:31))=2,"×","")))} | V31: {=IF(原始数据!W31="-","",IF(原始数据!W31="","",IF(COUNT(FIND(原始数据!W31,原始数据!31:31))=2,"×","")))} | W31: =IF(原始数据!X31="","",IF(COUNTIF(原始数据!31:31,原始数据!X31)>1,"×","")) | X31: =IF(原始数据!Y31="","",IF(COUNTIF(原始数据!31:31,原始数据!Y31)>1,"×","")) | Y31: =IF(原始数据!Z31="","",IF(COUNTIF(原始数据!31:31,原始数据!Z31)>1,"×","")) | Z31: =IF(原始数据!AA31="","",IF(COUNTIF(原始数据!31:31,原始数据!AA31)>1,"×","")) | AA31: =IF(原始数据!AB31="","",IF(COUNTIF(原始数据!31:31,原始数据!AB31)>1,"×","")) | AB31: =IF(原始数据!AC31="","",IF(COUNTIF(原始数据!31:31,原始数据!AC31)>1,"×","")) | AC31: =IF(原始数据!AD31="","",IF(COUNTIF(原始数据!31:31,原始数据!AD31)>1,"×","")) | AD31: =IF(原始数据!AE31="","",IF(COUNTIF(原始数据!31:31,原始数据!AE31)>1,"×","")) | ... AN31: =IF(原始数据!AO31="","",IF(COUNTIF(原始数据!31:31,原始数据!AO31)>1,"×",""))
A32: =IF(IFERROR(原始数据!B32,"×")="×","×","") | B32: =IF(IFERROR(原始数据!C32,"×")="×","×","") | C32: =IF(IFERROR(原始数据!D32,"×")="×","×","") | D32: =IF(IFERROR(原始数据!E32,"×")="×","×","") | E32: =IF(IFERROR(原始数据!F32,"×")="×","×","") | F32: =IF(IFERROR(原始数据!G32,"×")="×","×","") | G32: =IF(IFERROR(原始数据!H32,"×")="×","×","") | H32: =IF(IFERROR(原始数据!I32,"×")="×","×","") | ... T32: =IF(IFERROR(原始数据!U32,"×")="×","×","") | U32: {=IF(原始数据!V32="-","",IF(原始数据!V32="","",IF(COUNT(FIND(原始数据!V32,原始数据!32:32))=2,"×","")))} | V32: {=IF(原始数据!W32="-","",IF(原始数据!W32="","",IF(COUNT(FIND(原始数据!W32,原始数据!32:32))=2,"×","")))} | W32: =IF(原始数据!X32="","",IF(COUNTIF(原始数据!32:32,原始数据!X32)>1,"×","")) | X32: =IF(原始数据!Y32="","",IF(COUNTIF(原始数据!32:32,原始数据!Y32)>1,"×","")) | Y32: =IF(原始数据!Z32="","",IF(COUNTIF(原始数据!32:32,原始数据!Z32)>1,"×","")) | Z32: =IF(原始数据!AA32="","",IF(COUNTIF(原始数据!32:32,原始数据!AA32)>1,"×","")) | AA32: =IF(原始数据!AB32="","",IF(COUNTIF(原始数据!32:32,原始数据!AB32)>1,"×","")) | AB32: =IF(原始数据!AC32="","",IF(COUNTIF(原始数据!32:32,原始数据!AC32)>1,"×","")) | AC32: =IF(原始数据!AD32="","",IF(COUNTIF(原始数据!32:32,原始数据!AD32)>1,"×","")) | AD32: =IF(原始数据!AE32="","",IF(COUNTIF(原始数据!32:32,原始数据!AE32)>1,"×","")) | ... AN32: =IF(原始数据!AO32="","",IF(COUNTIF(原始数据!32:32,原始数据!AO32)>1,"×",""))
A33: =IF(IFERROR(原始数据!B33,"×")="×","×","") | B33: =IF(IFERROR(原始数据!C33,"×")="×","×","") | C33: =IF(IFERROR(原始数据!D33,"×")="×","×","") | D33: =IF(IFERROR(原始数据!E33,"×")="×","×","") | E33: =IF(IFERROR(原始数据!F33,"×")="×","×","") | F33: =IF(IFERROR(原始数据!G33,"×")="×","×","") | G33: =IF(IFERROR(原始数据!H33,"×")="×","×","") | H33: =IF(IFERROR(原始数据!I33,"×")="×","×","") | ... T33: =IF(IFERROR(原始数据!U33,"×")="×","×","") | U33: {=IF(原始数据!V33="-","",IF(原始数据!V33="","",IF(COUNT(FIND(原始数据!V33,原始数据!33:33))=2,"×","")))} | V33: {=IF(原始数据!W33="-","",IF(原始数据!W33="","",IF(COUNT(FIND(原始数据!W33,原始数据!33:33))=2,"×","")))} | W33: =IF(原始数据!X33="","",IF(COUNTIF(原始数据!33:33,原始数据!X33)>1,"×","")) | X33: =IF(原始数据!Y33="","",IF(COUNTIF(原始数据!33:33,原始数据!Y33)>1,"×","")) | Y33: =IF(原始数据!Z33="","",IF(COUNTIF(原始数据!33:33,原始数据!Z33)>1,"×","")) | Z33: =IF(原始数据!AA33="","",IF(COUNTIF(原始数据!33:33,原始数据!AA33)>1,"×","")) | AA33: =IF(原始数据!AB33="","",IF(COUNTIF(原始数据!33:33,原始数据!AB33)>1,"×","")) | AB33: =IF(原始数据!AC33="","",IF(COUNTIF(原始数据!33:33,原始数据!AC33)>1,"×","")) | AC33: =IF(原始数据!AD33="","",IF(COUNTIF(原始数据!33:33,原始数据!AD33)>1,"×","")) | AD33: =IF(原始数据!AE33="","",IF(COUNTIF(原始数据!33:33,原始数据!AE33)>1,"×","")) | ... AN33: =IF(原始数据!AO33="","",IF(COUNTIF(原始数据!33:33,原始数据!AO33)>1,"×",""))
A34: =IF(IFERROR(原始数据!B34,"×")="×","×","") | B34: =IF(IFERROR(原始数据!C34,"×")="×","×","") | C34: =IF(IFERROR(原始数据!D34,"×")="×","×","") | D34: =IF(IFERROR(原始数据!E34,"×")="×","×","") | E34: =IF(IFERROR(原始数据!F34,"×")="×","×","") | F34: =IF(IFERROR(原始数据!G34,"×")="×","×","") | G34: =IF(IFERROR(原始数据!H34,"×")="×","×","") | H34: =IF(IFERROR(原始数据!I34,"×")="×","×","") | ... T34: =IF(IFERROR(原始数据!U34,"×")="×","×","") | U34: {=IF(原始数据!V34="-","",IF(原始数据!V34="","",IF(COUNT(FIND(原始数据!V34,原始数据!34:34))=2,"×","")))} | V34: {=IF(原始数据!W34="-","",IF(原始数据!W34="","",IF(COUNT(FIND(原始数据!W34,原始数据!34:34))=2,"×","")))} | W34: =IF(原始数据!X34="","",IF(COUNTIF(原始数据!34:34,原始数据!X34)>1,"×","")) | X34: =IF(原始数据!Y34="","",IF(COUNTIF(原始数据!34:34,原始数据!Y34)>1,"×","")) | Y34: =IF(原始数据!Z34="","",IF(COUNTIF(原始数据!34:34,原始数据!Z34)>1,"×","")) | Z34: =IF(原始数据!AA34="","",IF(COUNTIF(原始数据!34:34,原始数据!AA34)>1,"×","")) | AA34: =IF(原始数据!AB34="","",IF(COUNTIF(原始数据!34:34,原始数据!AB34)>1,"×","")) | AB34: =IF(原始数据!AC34="","",IF(COUNTIF(原始数据!34:34,原始数据!AC34)>1,"×","")) | AC34: =IF(原始数据!AD34="","",IF(COUNTIF(原始数据!34:34,原始数据!AD34)>1,"×","")) | AD34: =IF(原始数据!AE34="","",IF(COUNTIF(原始数据!34:34,原始数据!AE34)>1,"×","")) | ... AN34: =IF(原始数据!AO34="","",IF(COUNTIF(原始数据!34:34,原始数据!AO34)>1,"×",""))
A35: =IF(IFERROR(原始数据!B35,"×")="×","×","") | B35: =IF(IFERROR(原始数据!C35,"×")="×","×","") | C35: =IF(IFERROR(原始数据!D35,"×")="×","×","") | D35: =IF(IFERROR(原始数据!E35,"×")="×","×","") | E35: =IF(IFERROR(原始数据!F35,"×")="×","×","") | F35: =IF(IFERROR(原始数据!G35,"×")="×","×","") | G35: =IF(IFERROR(原始数据!H35,"×")="×","×","") | H35: =IF(IFERROR(原始数据!I35,"×")="×","×","") | ... T35: =IF(IFERROR(原始数据!U35,"×")="×","×","") | U35: {=IF(原始数据!V35="-","",IF(原始数据!V35="","",IF(COUNT(FIND(原始数据!V35,原始数据!35:35))=2,"×","")))} | V35: {=IF(原始数据!W35="-","",IF(原始数据!W35="","",IF(COUNT(FIND(原始数据!W35,原始数据!35:35))=2,"×","")))} | W35: =IF(原始数据!X35="","",IF(COUNTIF(原始数据!35:35,原始数据!X35)>1,"×","")) | X35: =IF(原始数据!Y35="","",IF(COUNTIF(原始数据!35:35,原始数据!Y35)>1,"×","")) | Y35: =IF(原始数据!Z35="","",IF(COUNTIF(原始数据!35:35,原始数据!Z35)>1,"×","")) | Z35: =IF(原始数据!AA35="","",IF(COUNTIF(原始数据!35:35,原始数据!AA35)>1,"×","")) | AA35: =IF(原始数据!AB35="","",IF(COUNTIF(原始数据!35:35,原始数据!AB35)>1,"×","")) | AB35: =IF(原始数据!AC35="","",IF(COUNTIF(原始数据!35:35,原始数据!AC35)>1,"×","")) | AC35: =IF(原始数据!AD35="","",IF(COUNTIF(原始数据!35:35,原始数据!AD35)>1,"×","")) | AD35: =IF(原始数据!AE35="","",IF(COUNTIF(原始数据!35:35,原始数据!AE35)>1,"×","")) | ... AN35: =IF(原始数据!AO35="","",IF(COUNTIF(原始数据!35:35,原始数据!AO35)>1,"×",""))
A36: =IF(IFERROR(原始数据!B36,"×")="×","×","") | B36: =IF(IFERROR(原始数据!C36,"×")="×","×","") | C36: =IF(IFERROR(原始数据!D36,"×")="×","×","") | D36: =IF(IFERROR(原始数据!E36,"×")="×","×","") | E36: =IF(IFERROR(原始数据!F36,"×")="×","×","") | F36: =IF(IFERROR(原始数据!G36,"×")="×","×","") | G36: =IF(IFERROR(原始数据!H36,"×")="×","×","") | H36: =IF(IFERROR(原始数据!I36,"×")="×","×","") | ... T36: =IF(IFERROR(原始数据!U36,"×")="×","×","") | U36: {=IF(原始数据!V36="-","",IF(原始数据!V36="","",IF(COUNT(FIND(原始数据!V36,原始数据!36:36))=2,"×","")))} | V36: {=IF(原始数据!W36="-","",IF(原始数据!W36="","",IF(COUNT(FIND(原始数据!W36,原始数据!36:36))=2,"×","")))} | W36: =IF(原始数据!X36="","",IF(COUNTIF(原始数据!36:36,原始数据!X36)>1,"×","")) | X36: =IF(原始数据!Y36="","",IF(COUNTIF(原始数据!36:36,原始数据!Y36)>1,"×","")) | Y36: =IF(原始数据!Z36="","",IF(COUNTIF(原始数据!36:36,原始数据!Z36)>1,"×","")) | Z36: =IF(原始数据!AA36="","",IF(COUNTIF(原始数据!36:36,原始数据!AA36)>1,"×","")) | AA36: =IF(原始数据!AB36="","",IF(COUNTIF(原始数据!36:36,原始数据!AB36)>1,"×","")) | AB36: =IF(原始数据!AC36="","",IF(COUNTIF(原始数据!36:36,原始数据!AC36)>1,"×","")) | AC36: =IF(原始数据!AD36="","",IF(COUNTIF(原始数据!36:36,原始数据!AD36)>1,"×","")) | AD36: =IF(原始数据!AE36="","",IF(COUNTIF(原始数据!36:36,原始数据!AE36)>1,"×","")) | ... AN36: =IF(原始数据!AO36="","",IF(COUNTIF(原始数据!36:36,原始数据!AO36)>1,"×",""))
A37: =IF(IFERROR(原始数据!B37,"×")="×","×","") | B37: =IF(IFERROR(原始数据!C37,"×")="×","×","") | C37: =IF(IFERROR(原始数据!D37,"×")="×","×","") | D37: =IF(IFERROR(原始数据!E37,"×")="×","×","") | E37: =IF(IFERROR(原始数据!F37,"×")="×","×","") | F37: =IF(IFERROR(原始数据!G37,"×")="×","×","") | G37: =IF(IFERROR(原始数据!H37,"×")="×","×","") | H37: =IF(IFERROR(原始数据!I37,"×")="×","×","") | ... T37: =IF(IFERROR(原始数据!U37,"×")="×","×","") | U37: {=IF(原始数据!V37="-","",IF(原始数据!V37="","",IF(COUNT(FIND(原始数据!V37,原始数据!37:37))=2,"×","")))} | V37: {=IF(原始数据!W37="-","",IF(原始数据!W37="","",IF(COUNT(FIND(原始数据!W37,原始数据!37:37))=2,"×","")))} | W37: =IF(原始数据!X37="","",IF(COUNTIF(原始数据!37:37,原始数据!X37)>1,"×","")) | X37: =IF(原始数据!Y37="","",IF(COUNTIF(原始数据!37:37,原始数据!Y37)>1,"×","")) | Y37: =IF(原始数据!Z37="","",IF(COUNTIF(原始数据!37:37,原始数据!Z37)>1,"×","")) | Z37: =IF(原始数据!AA37="","",IF(COUNTIF(原始数据!37:37,原始数据!AA37)>1,"×","")) | AA37: =IF(原始数据!AB37="","",IF(COUNTIF(原始数据!37:37,原始数据!AB37)>1,"×","")) | AB37: =IF(原始数据!AC37="","",IF(COUNTIF(原始数据!37:37,原始数据!AC37)>1,"×","")) | AC37: =IF(原始数据!AD37="","",IF(COUNTIF(原始数据!37:37,原始数据!AD37)>1,"×","")) | AD37: =IF(原始数据!AE37="","",IF(COUNTIF(原始数据!37:37,原始数据!AE37)>1,"×","")) | ... AN37: =IF(原始数据!AO37="","",IF(COUNTIF(原始数据!37:37,原始数据!AO37)>1,"×",""))
A38: =IF(IFERROR(原始数据!B38,"×")="×","×","") | B38: =IF(IFERROR(原始数据!C38,"×")="×","×","") | C38: =IF(IFERROR(原始数据!D38,"×")="×","×","") | D38: =IF(IFERROR(原始数据!E38,"×")="×","×","") | E38: =IF(IFERROR(原始数据!F38,"×")="×","×","") | F38: =IF(IFERROR(原始数据!G38,"×")="×","×","") | G38: =IF(IFERROR(原始数据!H38,"×")="×","×","") | H38: =IF(IFERROR(原始数据!I38,"×")="×","×","") | ... T38: =IF(IFERROR(原始数据!U38,"×")="×","×","") | U38: {=IF(原始数据!V38="-","",IF(原始数据!V38="","",IF(COUNT(FIND(原始数据!V38,原始数据!38:38))=2,"×","")))} | V38: {=IF(原始数据!W38="-","",IF(原始数据!W38="","",IF(COUNT(FIND(原始数据!W38,原始数据!38:38))=2,"×","")))} | W38: =IF(原始数据!X38="","",IF(COUNTIF(原始数据!38:38,原始数据!X38)>1,"×","")) | X38: =IF(原始数据!Y38="","",IF(COUNTIF(原始数据!38:38,原始数据!Y38)>1,"×","")) | Y38: =IF(原始数据!Z38="","",IF(COUNTIF(原始数据!38:38,原始数据!Z38)>1,"×","")) | Z38: =IF(原始数据!AA38="","",IF(COUNTIF(原始数据!38:38,原始数据!AA38)>1,"×","")) | AA38: =IF(原始数据!AB38="","",IF(COUNTIF(原始数据!38:38,原始数据!AB38)>1,"×","")) | AB38: =IF(原始数据!AC38="","",IF(COUNTIF(原始数据!38:38,原始数据!AC38)>1,"×","")) | AC38: =IF(原始数据!AD38="","",IF(COUNTIF(原始数据!38:38,原始数据!AD38)>1,"×","")) | AD38: =IF(原始数据!AE38="","",IF(COUNTIF(原始数据!38:38,原始数据!AE38)>1,"×","")) | ... AN38: =IF(原始数据!AO38="","",IF(COUNTIF(原始数据!38:38,原始数据!AO38)>1,"×",""))
A39: =IF(IFERROR(原始数据!B39,"×")="×","×","") | B39: =IF(IFERROR(原始数据!C39,"×")="×","×","") | C39: =IF(IFERROR(原始数据!D39,"×")="×","×","") | D39: =IF(IFERROR(原始数据!E39,"×")="×","×","") | E39: =IF(IFERROR(原始数据!F39,"×")="×","×","") | F39: =IF(IFERROR(原始数据!G39,"×")="×","×","") | G39: =IF(IFERROR(原始数据!H39,"×")="×","×","") | H39: =IF(IFERROR(原始数据!I39,"×")="×","×","") | ... T39: =IF(IFERROR(原始数据!U39,"×")="×","×","") | U39: {=IF(原始数据!V39="-","",IF(原始数据!V39="","",IF(COUNT(FIND(原始数据!V39,原始数据!39:39))=2,"×","")))} | V39: {=IF(原始数据!W39="-","",IF(原始数据!W39="","",IF(COUNT(FIND(原始数据!W39,原始数据!39:39))=2,"×","")))} | W39: =IF(原始数据!X39="","",IF(COUNTIF(原始数据!39:39,原始数据!X39)>1,"×","")) | X39: =IF(原始数据!Y39="","",IF(COUNTIF(原始数据!39:39,原始数据!Y39)>1,"×","")) | Y39: =IF(原始数据!Z39="","",IF(COUNTIF(原始数据!39:39,原始数据!Z39)>1,"×","")) | Z39: =IF(原始数据!AA39="","",IF(COUNTIF(原始数据!39:39,原始数据!AA39)>1,"×","")) | AA39: =IF(原始数据!AB39="","",IF(COUNTIF(原始数据!39:39,原始数据!AB39)>1,"×","")) | AB39: =IF(原始数据!AC39="","",IF(COUNTIF(原始数据!39:39,原始数据!AC39)>1,"×","")) | AC39: =IF(原始数据!AD39="","",IF(COUNTIF(原始数据!39:39,原始数据!AD39)>1,"×","")) | AD39: =IF(原始数据!AE39="","",IF(COUNTIF(原始数据!39:39,原始数据!AE39)>1,"×","")) | ... AN39: =IF(原始数据!AO39="","",IF(COUNTIF(原始数据!39:39,原始数据!AO39)>1,"×",""))
A40: =IF(IFERROR(原始数据!B40,"×")="×","×","") | B40: =IF(IFERROR(原始数据!C40,"×")="×","×","") | C40: =IF(IFERROR(原始数据!D40,"×")="×","×","") | D40: =IF(IFERROR(原始数据!E40,"×")="×","×","") | E40: =IF(IFERROR(原始数据!F40,"×")="×","×","") | F40: =IF(IFERROR(原始数据!G40,"×")="×","×","") | G40: =IF(IFERROR(原始数据!H40,"×")="×","×","") | H40: =IF(IFERROR(原始数据!I40,"×")="×","×","") | ... T40: =IF(IFERROR(原始数据!U40,"×")="×","×","") | U40: {=IF(原始数据!V40="-","",IF(原始数据!V40="","",IF(COUNT(FIND(原始数据!V40,原始数据!40:40))=2,"×","")))} | V40: {=IF(原始数据!W40="-","",IF(原始数据!W40="","",IF(COUNT(FIND(原始数据!W40,原始数据!40:40))=2,"×","")))} | W40: =IF(原始数据!X40="","",IF(COUNTIF(原始数据!40:40,原始数据!X40)>1,"×","")) | X40: =IF(原始数据!Y40="","",IF(COUNTIF(原始数据!40:40,原始数据!Y40)>1,"×","")) | Y40: =IF(原始数据!Z40="","",IF(COUNTIF(原始数据!40:40,原始数据!Z40)>1,"×","")) | Z40: =IF(原始数据!AA40="","",IF(COUNTIF(原始数据!40:40,原始数据!AA40)>1,"×","")) | AA40: =IF(原始数据!AB40="","",IF(COUNTIF(原始数据!40:40,原始数据!AB40)>1,"×","")) | AB40: =IF(原始数据!AC40="","",IF(COUNTIF(原始数据!40:40,原始数据!AC40)>1,"×","")) | AC40: =IF(原始数据!AD40="","",IF(COUNTIF(原始数据!40:40,原始数据!AD40)>1,"×","")) | AD40: =IF(原始数据!AE40="","",IF(COUNTIF(原始数据!40:40,原始数据!AE40)>1,"×","")) | ... AN40: =IF(原始数据!AO40="","",IF(COUNTIF(原始数据!40:40,原始数据!AO40)>1,"×",""))
...

Sheet 各类选项
A1: 赛事类型 | B1: 角色 | F1: 俱乐部 | G1: 地图 | H1: 辅助特质 | I1: 求生者阵营 | K1: 监管者阵营
A2: IVL夏季赛常规赛 | B2: ID | C2: 角色名 | D2: ID | E2: 角色名 | F2: AWG | G2: - | H2: - | I2: AWG | J2: Kaeru | K2: AWG | L2: Irohasu
A3: IVL夏季赛季后赛 | B3: 0 | C3: 空 | D3: 0 | E3: 空 | F3: AXIZ | G3: 军工厂 | H3: 聆听 | I3: AWG | J3: aez | K3: AWG | L3: Yukakina
A4: IVL秋季赛常规赛 | B4: 1 | C4: 厂长 | D4: 1 | E4: 幸运儿 | F4: FAV | G4: 红教堂 | H4: 失常 | I4: AWG | J4: Nameko | K4: AXIZ | L4: Kakaka
A5: IVL秋季赛季后赛 | B5: 2 | C5: 小丑 | D5: 2 | E5: 医生 | F5: FL | G5: 圣心医院 | H5: 兴奋 | I5: AWG | J5: Scorpion | K5: AXIZ | L5: Ryz
A6: IVS | B6: 3 | C6: 鹿头 | D6: 3 | E6: 律师 | F6: RC | G6: 湖景村 | H6: 巡视者 | I6: AWG | J6: Tawash | K6: FAV | L6: Chikin
A7: IVT | B7: 4 | C7: 杰克 | D7: 4 | E7: 慈善家 | F7: SZ | G7: 月亮河公园 | H7: 传送 | I7: AXIZ | J7: Atto | K7: FAV | L7: Yami
A8: IJL夏季赛常规赛 | B8: 5 | C8: 红蝶 | D8: 5 | E8: 园丁 | F8: ZETA | G8: 里奥的回忆 | H8: 窥视者 | I8: AXIZ | J8: Lim | K8: FL | L8: Hasha
A9: IJL夏季赛季后赛 | B9: 6 | C9: 蜘蛛 | D9: 6 | E9: 魔术师 | G9: 永眠镇 | H9: 闪现 | I9: AXIZ | J9: Nyan | K9: FL | L9: Pipicha
A10: IJL秋季赛常规赛 | B10: 7 | C10: 宿伞之魂 | D10: 7 | E10: 冒险家 | G10: 唐人街 | H10: 移形 | I10: AXIZ | J10: Takakou | K10: RC | L10: AKa
A11: IJL秋季赛季后赛 | B11: 8 | C11: 疯眼 | D11: 8 | E11: 佣兵 | I11: AXIZ | J11: Tuna | K11: RC | L11: Peter
A12: COA预选赛 | B12: 9 | C12: 摄影师 | D12: 9 | E12: 空军 | I12: FAV | J12: Appai | K12: SZ | L12: Burio
A13: COA全球总决赛小组赛 | B13: 10 | C13: 黄衣之主 | D13: 10 | E13: 机械师 | I13: FAV | J13: Dacho | K13: SZ | L13: MiraiK
A14: IVT | B14: 11 | C14: 红夫人 | D14: 11 | E14: 前锋 | I14: FAV | J14: Felix | K14: ZETA | L14: alf
A15: 其他 | B15: 12 | C15: 梦之女巫 | D15: 12 | E15: 盲女 | I15: FAV | J15: Nerisu
B16: 13 | C16: 雕刻家 | D16: 13 | E16: 祭司 | I16: FAV | J16: Riz
B17: 14 | C17: 26号守卫 | D17: 14 | E17: 调香师 | I17: FL | J17: Emmko
B18: 15 | C18: 小提琴家 | D18: 15 | E18: 牛仔 | I18: FL | J18: sasori
B19: 16 | C19: 爱哭鬼 | D19: 16 | E19: 舞女 | I19: FL | J19: Maeken
B20: 17 | C20: 孽蜥 | D20: 17 | E20: 先知 | I20: FL | J20: Yougg
B21: 18 | C21: 使徒 | D21: 18 | E21: 入殓师 | I21: RC | J21: City
B22: 19 | C22: 渔女 | D22: 19 | E22: 勘探员 | I22: RC | J22: MonoP
B23: 20 | C23: 破轮 | D23: 20 | E23: 咒术师 | I23: RC | J23: Raolie
B24: 21 | C24: 蜡像师 | D24: 21 | E24: 野人 | I24: RC | J24: Soba
B25: 22 | C25: 噩梦 | D25: 22 | E25: 杂技演员 | I25: SZ | J25: Gnk
B26: 23 | C26: 记录员 | D26: 23 | E26: 大副 | I26: SZ | J26: Kat
B27: 24 | C27: 博士 | D27: 24 | E27: 调酒师 | I27: SZ | J27: Mone
... B32: 29 | C32: 时空之影 | D32: 29 | E32: 画家 | I32: ZETA | J32: Hametu
B33: 30 | D33: 30 | E33: 击球手 | I33: ZETA | J33: Kznk
B34: 31 | D34: 31 | E34: 玩具商 | I34: ZETA | J34: Mocchi
B35: 32 | D35: 32 | E35: 心理学家 | I35: ZETA | J35: Shinami
B36: 33 | D36: 33 | E36: 病患
B37: 34 | D37: 34 | E37: 小说家
B38: 35 | D38: 35 | E38: 小女孩
B39: 36 | D39: 36 | E39: 哭泣小丑
B40: 37 | D40: 37 | E40: 教授
B41: 38 | D41: 38 | E41: 古董商
B42: 39 | D42: 39 | E42: 作曲家
B43: 40 | D43: 40 | E43: 记者
B44: 41 | D44: 41 | E44: 飞行家
...

Sheet 输入错误检查
C1: 屠夫队伍 | D1: 屠夫名字 | E1: 地图错误 | F1: 地图错误 | G1: 人BAN | K1: 屠BAN | N1: 人PICK | R1: 屠PICK | S1: 求生1 | T1: 求生2 | U1: 求生3 | V1: 求生4
A2: =COUNTIF(C2:R2,">0") -> 0 | B2: =COUNTIF(S2:V2,">0") -> 0 | C2: =IF(原始数据!K2="","",IF(ISERROR(MATCH(原始数据!K2,原始数据!E2:F2,0)),1,0)-IF(原始数据!K2="",1,0)) -> 0 | D2: =IF(原始数据!L2="","",IF(ISERROR(MATCH(原始数据!L2,各类选项!L:L,0)),1,0)-IF(原始数据!L2="",1,0)) -> 0 | E2: =IF(原始数据!V2="","",IF(ISERROR(MATCH(原始数据!V2,各类选项!G:G,0)),1,0)) -> 0 | F2: =IF(原始数据!W2="","",IF(ISERROR(MATCH(原始数据!W2,各类选项!G:G,0)),1,0)) -> 0 | G2: =IF(原始数据!AD2="","",IF(ISERROR(MATCH(原始数据!AD2,各类选项!$E:$E,0)),1,0)) -> 0 | H2: =IF(原始数据!AE2="","",IF(ISERROR(MATCH(原始数据!AE2,各类选项!$E:$E,0)),1,0)) -> 0 | I2: =IF(原始数据!AK2="","",IF(ISERROR(MATCH(原始数据!AK2,各类选项!$E:$E,0)),1,0)) -> 0 | J2: =IF(原始数据!AM2="","",IF(ISERROR(MATCH(原始数据!AM2,各类选项!$E:$E,0)),1,0)) -> 0 | K2: =IF(原始数据!AF2="","",IF(ISERROR(MATCH(原始数据!AF2,各类选项!$C:$C,0)),1,0)) | L2: =IF(原始数据!AG2="","",IF(ISERROR(MATCH(原始数据!AG2,各类选项!$C:$C,0)),1,0)) | M2: =IF(原始数据!AH2="","",IF(ISERROR(MATCH(原始数据!AH2,各类选项!$C:$C,0)),1,0)) | N2: =IF(原始数据!AI2="","",IF(ISERROR(MATCH(原始数据!AI2,各类选项!$E:$E,0)),1,0)) -> 0 | O2: =IF(原始数据!AJ2="","",IF(ISERROR(MATCH(原始数据!AJ2,各类选项!$E:$E,0)),1,0)) -> 0 | P2: =IF(原始数据!AK2="","",IF(ISERROR(MATCH(原始数据!AK2,各类选项!$E:$E,0)),1,0)) -> 0 | Q2: =IF(原始数据!AL2="","",IF(ISERROR(MATCH(原始数据!AL2,各类选项!$E:$E,0)),1,0)) -> 0 | R2: =IF(原始数据!AO2="","",IF(ISERROR(MATCH(原始数据!AO2,各类选项!$C:$C,0)),1,0)) -> 0 | S2: =IF(赛后数据!M2="","",IF(ISERROR(MATCH(赛后数据!M2,(各类选项!J:J),0)),1,0)) -> 0 | T2: =IF(赛后数据!U2="","",IF(ISERROR(MATCH(赛后数据!U2,(各类选项!J:J),0)),1,0)) -> 0 | U2: =IF(赛后数据!AC2="","",IF(ISERROR(MATCH(赛后数据!AC2,(各类选项!J:J),0)),1,0)) -> 0 | V2: =IF(赛后数据!AK2="","",IF(ISERROR(MATCH(赛后数据!AK2,(各类选项!J:J),0)),1,0)) -> 0
A3: =COUNTIF(C3:R3,">0") -> 0 | B3: =COUNTIF(S3:V3,">0") -> 0 | C3: =IF(原始数据!K3="","",IF(ISERROR(MATCH(原始数据!K3,原始数据!E3:F3,0)),1,0)-IF(原始数据!K3="",1,0)) -> 0 | D3: =IF(原始数据!L3="","",IF(ISERROR(MATCH(原始数据!L3,各类选项!L:L,0)),1,0)-IF(原始数据!L3="",1,0)) -> 0 | E3: =IF(原始数据!V3="","",IF(ISERROR(MATCH(原始数据!V3,各类选项!G:G,0)),1,0)) -> 0 | F3: =IF(原始数据!W3="","",IF(ISERROR(MATCH(原始数据!W3,各类选项!G:G,0)),1,0)) -> 0 | G3: =IF(原始数据!AD3="","",IF(ISERROR(MATCH(原始数据!AD3,各类选项!$E:$E,0)),1,0)) -> 0 | H3: =IF(原始数据!AE3="","",IF(ISERROR(MATCH(原始数据!AE3,各类选项!$E:$E,0)),1,0)) -> 0 | I3: =IF(原始数据!AK3="","",IF(ISERROR(MATCH(原始数据!AK3,各类选项!$E:$E,0)),1,0)) -> 0 | J3: =IF(原始数据!AM3="","",IF(ISERROR(MATCH(原始数据!AM3,各类选项!$E:$E,0)),1,0)) -> 0 | K3: =IF(原始数据!AF3="","",IF(ISERROR(MATCH(原始数据!AF3,各类选项!$C:$C,0)),1,0)) | L3: =IF(原始数据!AG3="","",IF(ISERROR(MATCH(原始数据!AG3,各类选项!$C:$C,0)),1,0)) | M3: =IF(原始数据!AH3="","",IF(ISERROR(MATCH(原始数据!AH3,各类选项!$C:$C,0)),1,0)) | N3: =IF(原始数据!AI3="","",IF(ISERROR(MATCH(原始数据!AI3,各类选项!$E:$E,0)),1,0)) -> 0 | O3: =IF(原始数据!AJ3="","",IF(ISERROR(MATCH(原始数据!AJ3,各类选项!$E:$E,0)),1,0)) -> 0 | P3: =IF(原始数据!AK3="","",IF(ISERROR(MATCH(原始数据!AK3,各类选项!$E:$E,0)),1,0)) -> 0 | Q3: =IF(原始数据!AL3="","",IF(ISERROR(MATCH(原始数据!AL3,各类选项!$E:$E,0)),1,0)) -> 0 | R3: =IF(原始数据!AO3="","",IF(ISERROR(MATCH(原始数据!AO3,各类选项!$C:$C,0)),1,0)) -> 0 | S3: =IF(赛后数据!M3="","",IF(ISERROR(MATCH(赛后数据!M3,(各类选项!J:J),0)),1,0)) -> 0 | T3: =IF(赛后数据!U3="","",IF(ISERROR(MATCH(赛后数据!U3,(各类选项!J:J),0)),1,0)) -> 0 | U3: =IF(赛后数据!AC3="","",IF(ISERROR(MATCH(赛后数据!AC3,(各类选项!J:J),0)),1,0)) -> 0 | V3: =IF(赛后数据!AK3="","",IF(ISERROR(MATCH(赛后数据!AK3,(各类选项!J:J),0)),1,0)) -> 0
A4: =COUNTIF(C4:R4,">0") -> 0 | B4: =COUNTIF(S4:V4,">0") -> 0 | C4: =IF(原始数据!K4="","",IF(ISERROR(MATCH(原始数据!K4,原始数据!E4:F4,0)),1,0)-IF(原始数据!K4="",1,0)) -> 0 | D4: =IF(原始数据!L4="","",IF(ISERROR(MATCH(原始数据!L4,各类选项!L:L,0)),1,0)-IF(原始数据!L4="",1,0)) -> 0 | E4: =IF(原始数据!V4="","",IF(ISERROR(MATCH(原始数据!V4,各类选项!G:G,0)),1,0)) -> 0 | F4: =IF(原始数据!W4="","",IF(ISERROR(MATCH(原始数据!W4,各类选项!G:G,0)),1,0)) -> 0 | G4: =IF(原始数据!AD4="","",IF(ISERROR(MATCH(原始数据!AD4,各类选项!$E:$E,0)),1,0)) -> 0 | H4: =IF(原始数据!AE4="","",IF(ISERROR(MATCH(原始数据!AE4,各类选项!$E:$E,0)),1,0)) -> 0 | I4: =IF(原始数据!AK4="","",IF(ISERROR(MATCH(原始数据!AK4,各类选项!$E:$E,0)),1,0)) -> 0 | J4: =IF(原始数据!AM4="","",IF(ISERROR(MATCH(原始数据!AM4,各类选项!$E:$E,0)),1,0)) -> 0 | K4: =IF(原始数据!AF4="","",IF(ISERROR(MATCH(原始数据!AF4,各类选项!$C:$C,0)),1,0)) -> 0 | L4: =IF(原始数据!AG4="","",IF(ISERROR(MATCH(原始数据!AG4,各类选项!$C:$C,0)),1,0)) | M4: =IF(原始数据!AH4="","",IF(ISERROR(MATCH(原始数据!AH4,各类选项!$C:$C,0)),1,0)) | N4: =IF(原始数据!AI4="","",IF(ISERROR(MATCH(原始数据!AI4,各类选项!$E:$E,0)),1,0)) -> 0 | O4: =IF(原始数据!AJ4="","",IF(ISERROR(MATCH(原始数据!AJ4,各类选项!$E:$E,0)),1,0)) -> 0 | P4: =IF(原始数据!AK4="","",IF(ISERROR(MATCH(原始数据!AK4,各类选项!$E:$E,0)),1,0)) -> 0 | Q4: =IF(原始数据!AL4="","",IF(ISERROR(MATCH(原始数据!AL4,各类选项!$E:$E,0)),1,0)) -> 0 | R4: =IF(原始数据!AO4="","",IF(ISERROR(MATCH(原始数据!AO4,各类选项!$C:$C,0)),1,0)) -> 0 | S4: =IF(赛后数据!M4="","",IF(ISERROR(MATCH(赛后数据!M4,(各类选项!J:J),0)),1,0)) -> 0 | T4: =IF(赛后数据!U4="","",IF(ISERROR(MATCH(赛后数据!U4,(各类选项!J:J),0)),1,0)) -> 0 | U4: =IF(赛后数据!AC4="","",IF(ISERROR(MATCH(赛后数据!AC4,(各类选项!J:J),0)),1,0)) -> 0 | V4: =IF(赛后数据!AK4="","",IF(ISERROR(MATCH(赛后数据!AK4,(各类选项!J:J),0)),1,0)) -> 0
A5: =COUNTIF(C5:R5,">0") -> 0 | B5: =COUNTIF(S5:V5,">0") -> 0 | C5: =IF(原始数据!K5="","",IF(ISERROR(MATCH(原始数据!K5,原始数据!E5:F5,0)),1,0)-IF(原始数据!K5="",1,0)) -> 0 | D5: =IF(原始数据!L5="","",IF(ISERROR(MATCH(原始数据!L5,各类选项!L:L,0)),1,0)-IF(原始数据!L5="",1,0)) -> 0 | E5: =IF(原始数据!V5="","",IF(ISERROR(MATCH(原始数据!V5,各类选项!G:G,0)),1,0)) -> 0 | F5: =IF(原始数据!W5="","",IF(ISERROR(MATCH(原始数据!W5,各类选项!G:G,0)),1,0)) -> 0 | G5: =IF(原始数据!AD5="","",IF(ISERROR(MATCH(原始数据!AD5,各类选项!$E:$E,0)),1,0)) -> 0 | H5: =IF(原始数据!AE5="","",IF(ISERROR(MATCH(原始数据!AE5,各类选项!$E:$E,0)),1,0)) -> 0 | I5: =IF(原始数据!AK5="","",IF(ISERROR(MATCH(原始数据!AK5,各类选项!$E:$E,0)),1,0)) -> 0 | J5: =IF(原始数据!AM5="","",IF(ISERROR(MATCH(原始数据!AM5,各类选项!$E:$E,0)),1,0)) -> 0 | K5: =IF(原始数据!AF5="","",IF(ISERROR(MATCH(原始数据!AF5,各类选项!$C:$C,0)),1,0)) -> 0 | L5: =IF(原始数据!AG5="","",IF(ISERROR(MATCH(原始数据!AG5,各类选项!$C:$C,0)),1,0)) | M5: =IF(原始数据!AH5="","",IF(ISERROR(MATCH(原始数据!AH5,各类选项!$C:$C,0)),1,0)) | N5: =IF(原始数据!AI5="","",IF(ISERROR(MATCH(原始数据!AI5,各类选项!$E:$E,0)),1,0)) -> 0 | O5: =IF(原始数据!AJ5="","",IF(ISERROR(MATCH(原始数据!AJ5,各类选项!$E:$E,0)),1,0)) -> 0 | P5: =IF(原始数据!AK5="","",IF(ISERROR(MATCH(原始数据!AK5,各类选项!$E:$E,0)),1,0)) -> 0 | Q5: =IF(原始数据!AL5="","",IF(ISERROR(MATCH(原始数据!AL5,各类选项!$E:$E,0)),1,0)) -> 0 | R5: =IF(原始数据!AO5="","",IF(ISERROR(MATCH(原始数据!AO5,各类选项!$C:$C,0)),1,0)) -> 0 | S5: =IF(赛后数据!M5="","",IF(ISERROR(MATCH(赛后数据!M5,(各类选项!J:J),0)),1,0)) -> 0 | T5: =IF(赛后数据!U5="","",IF(ISERROR(MATCH(赛后数据!U5,(各类选项!J:J),0)),1,0)) -> 0 | U5: =IF(赛后数据!AC5="","",IF(ISERROR(MATCH(赛后数据!AC5,(各类选项!J:J),0)),1,0)) -> 0 | V5: =IF(赛后数据!AK5="","",IF(ISERROR(MATCH(赛后数据!AK5,(各类选项!J:J),0)),1,0)) -> 0
