Workbook

Sheet 说明
A1: 制作者信息 | E1: 当前赛事 | K1: =E3&F3 -> 2025COA全球总决赛小组赛
A2: 名称 | B2: 第五人格赛事信息记录表 | C2: 比分记录 for BWIKI V2.0 | E2: 年份 | F2: 类型 | K2: 总结
A3: BWIKI欢迎各位加入w点击此表格了解BWIKI | E3: 2025 | F3: COA全球总决赛小组赛 | K3: 总场次 | M3: 总局数 | N3: 2局 | O3: 3局 | P3: BO3加赛
A4: 主分、客分列，哪怕是2：0带走，第三局和加赛那一行也必须填上数字，没比的局局分填0就行 | E4: 可上场监管者角色数 | F4: 29 | G4: 监管者indirect区域 | H4: ="'各类选项'!C3:C"&(F4+3) -> '各类选项'!C3:C32 | K4: =90-COUNTIF(赛果!K$2:K$91,"") -> 40 | M4: =720-COUNTIF(原始数据!L3:L722,"") -> 206 | N4: =COUNTIF(赛果!O2:O91,"2") -> 0 | O4: =COUNTIF(赛果!O2:O91,"3") -> 40 | P4: =COUNTIF(赛果!O2:O91,"4") -> 0
E5: 可上场求生者角色数 | F5: 43 | G5: 求生者indirect区域 | H5: ="'各类选项'!E3:E"&(F5+3) -> '各类选项'!E3:E46 | K5: 监管者BAN | M5: 求生者BAN | O5: 监管者 胜利 | P5: 胜率 | Q5: 求生者 胜利 | R5: 胜率 | S5: 平局 | T5: 平率
A6: 只有与本格子颜色相同的部分才开放编辑权限噢~记录赛事时，原始数据、牵制时长这两个表是都需要填的。若两队通过加时赛的时长比对才分出胜负，那么需要在大分&小分表格寻找和本格子颜色一样的区域，手动填写最终获胜者。除此以外，本表格其他区域所有内容均使用excel函数自动生成，无需进行任何操作~ | E6: 队伍数量 | F6: 20 | G6: indirect区域 | H6: ="'各类选项'!F2:F"&(F6+1) -> '各类选项'!F2:F21
E7: 监管者阵营人数 | F7: 30 | G7: ="'各类选项'!K2:K"&(F7+1) -> '各类选项'!K2:K31 | H7: ="'各类选项'!L2:L"&(F7+1) -> '各类选项'!L2:L31 | O7: =COUNTIFS(原始数据!U3:U722,"屠") -> 102 | P7: =O7/M4 -> 0.49514563 | Q7: =COUNTIFS(原始数据!U3:U722,"人") -> 31 | R7: =Q7/M4 -> 0.15048544 | S7: =COUNTIFS(原始数据!U3:U722,"平") -> 73 | T7: =S7/M4 -> 0.35436893
E8: 求生者阵营人数 | F8: 76 | G8: 求生者indirect区域 | H8: ="'各类选项'!J2:J"&(F8+1) -> '各类选项'!J2:J77 | K8: 第五人格BWIKI赛事组制作 | R8: 45347
A9: 填写原始数据时，如第一轮第一场上半场由DOU5队东玄先上屠夫，则在屠队列填写D5（全大写），在屠名列填写东玄id（全小写）dx。第一轮是ZQ打DOU5，因此如果东玄被三跑，则ZQ:DOU5比分为3:1，主分填3，客分填1即可。地图名字请填写全名，请勿做任何省略。地图方主客即选择地图的一方本轮处于主场或者客场。如第一轮第一场若由DOU5选图，则此处填客字即可，主/客一个字就行！！倒数第二列的剩余台数就是填写剩余密码机数量。最后一列名字是错误，这是一个简单的纠错，一旦有常见的名字输入错误的问题，这里便会计数，但只是能查到，并不是100%查得到！牵制时长表格和原始数据用类似方法填写，但求生者ID不需要带队名。 | E9: 地图数量 | F9: 8 | G9: 地图区域 | H9: ="'各类选项'!G2:G"&(F9+2) -> '各类选项'!G2:G10
E10: 辅助特质 | F10: 8 | G10: 辅助特质校验 | H10: ="'各类选项'!H2:H"&(F10+2) -> '各类选项'!H2:H10
E11: BO数 | F11: 3
A21: 当参赛的选手、角色有更新时，请更改右上黄色区域 并修改【各类选项】sheet

Sheet 原始数据
A2: 本页出错 | B2: 月 | C2: 日 | D2: 时间 | E2: 主场 | F2: 客场 | G2: 局 | H2: 半场 | I2: 屠队主客 | J2: 人队 | K2: 屠队 | L2: 屠名 | M2: 局分 | O2: 局总分 | P2: 场分 | S2: 主分 | T2: 客分 | U2: 胜利 | W2: BAN图 | X2: 地图 | Y2: 求生者全局禁用【自动生成】 | AH2: 监管者全局禁用【自动生成】 | AK2: 第一阶段人BAN | AM2: 第一阶段屠BAN | AP2: 第一阶段人PICK | AR2: 第二阶段人BAN | AS2: 第二阶段人PICK | AT2: 第三阶段人BAN | AU2: 第三阶段人PICK | AV2: 屠选 | AW2: 地图主客 | AX2: 选图队伍 | AY2: 选边队伍
A3: =输入错误检查!A2 -> 0 | B3: 4 | C3: 11 | D3: 12 | E3: AXIZ | F3: TE | G3: 1 | H3: 上 | I3: =IF(K3="","",IF(K3=E3,"主","客")) -> 客 | J3: =IF(K3="","",IF(K3=E3,F3,E3)) -> AXIZ | K3: TE | L3: ppei | M3: =S3+S4 -> 4 | N3: =T3+T4 -> 4 | O3: =M3+N3 -> 8 | P3: =IF(M3>N3,1,0) -> 0 | Q3: =IF(M3+N3=0,0,IF(M3=N3,1,0)) -> 1 | R3: =IF(M3<N3,1,0) -> 0 | S3: 1 | T3: 3 | U3: =_xlfn.IFS(S3+T3=0,"",S3>T3,IF(I3="主","屠","人"),S3<T3,IF(I3="主","人","屠"),S3=T3,"平") -> 屠 | V3: {=_xlfn.IFS(S3+T3=0,"",S3>T3,IF(I3="主",IF(S3=5,4,3),IF(S3=5,0,1)),S3<T3,IF(I3="主",IF(T3=5,0,1),IF(T3=5,4,3)),S3=T3,2)} -> 3 | W3: 月亮河公园 | X3: 里奥的回忆 | AK3: 先知 | AL3: 机械师 | AP3: 大副 | AQ3: 飞行家 | AR3: 古董商 | AS3: 咒术师 | AT3: 入殓师 | AU3: 冒险家 | AV3: 跛脚羊 | AW3: =_xlfn.IFS(AX3="","",AX3=E3,"主",AX3=F3,"客") -> 主 | AX3: =IF(说明!$F$11=3,_xlfn.IFS($G3=1,$E3,$G3=2,$F3,$G3=3,(IF(S3+T3=0,"",$E3)),$G3="加",(IF(S3+T3=0,"",$F3))),_xlfn.IFS($G3=1,$E3,$G3=2,$F3,$G3=3,$E3,$G3=4,(IF(S3+T3=0,"",$F3)),$G3=5,(IF(S3+T3=0,"",$E3)),$G3="加",(IF(S3+T3=0,"",$F3)))) -> AXIZ | AY3: =_xlfn.IFS(AX3="","",AX3=E3,F3,AX3=F3,E3) -> TE
A4: =输入错误检查!A3 -> 0 | B4: =B3 -> 4 | C4: =C3 -> 11 | D4: =D3 -> 12 | E4: =E3 -> AXIZ | F4: TE | G4: 1 | H4: 下 | I4: =IF(K4="","",IF(K4=E4,"主","客")) -> 主 | J4: =IF(K4="","",IF(K4=E4,F4,E4)) -> TE | K4: AXIZ | L4: kakiri | S4: 3 | T4: 1 | U4: =_xlfn.IFS(S4+T4=0,"",S4>T4,IF(I4="主","屠","人"),S4<T4,IF(I4="主","人","屠"),S4=T4,"平") -> 屠 | V4: {=_xlfn.IFS(S4+T4=0,"",S4>T4,IF(I4="主",IF(S4=5,4,3),IF(S4=5,0,1)),S4<T4,IF(I4="主",IF(T4=5,0,1),IF(T4=5,4,3)),S4=T4,2)} -> 3 | W4: =IF(W3="","",W3) -> 月亮河公园 | X4: =IF(X3="","",X3) -> 里奥的回忆 | AK4: 机械师 | AL4: 大副 | AP4: 冒险家 | AQ4: 入殓师 | AR4: 先知 | AS4: 木偶师 | AT4: 古董商 | AU4: 心理学家 | AV4: 跛脚羊 | AW4: =_xlfn.IFS(AX4="","",AX4=E4,"主",AX4=F4,"客") -> 主 | AX4: =IF(说明!$F$11=3,_xlfn.IFS($G4=1,$E4,$G4=2,$F4,$G4=3,(IF(S4+T4=0,"",$E4)),$G4="加",(IF(S4+T4=0,"",$F4))),_xlfn.IFS($G4=1,$E4,$G4=2,$F4,$G4=3,$E4,$G4=4,(IF(S4+T4=0,"",$F4)),$G4=5,(IF(S4+T4=0,"",$E4)),$G4="加",(IF(S4+T4=0,"",$F4)))) -> AXIZ | AY4: =_xlfn.IFS(AX4="","",AX4=E4,F4,AX4=F4,E4) -> TE
A5: =输入错误检查!A4 -> 0 | B5: =B4 -> 4 | C5: =C4 -> 11 | D5: =D4 -> 12 | E5: =E4 -> AXIZ | F5: =F4 -> TE | G5: 2 | H5: 上 | I5: =IF(K5="","",IF(K5=E5,"主","客")) -> 主 | J5: =IF(K5="","",IF(K5=E5,F5,E5)) -> TE | K5: AXIZ | L5: kakiri | M5: =S5+S6 -> 7 | N5: =T5+T6 -> 2 | O5: =M5+N5 -> 9 | P5: =IF(M5>N5,1,0) -> 1 | Q5: =IF(M5+N5=0,0,IF(M5=N5,1,0)) -> 0 | R5: =IF(M5<N5,1,0) -> 0 | S5: 5 | T5: 0 | U5: =_xlfn.IFS(S5+T5=0,"",S5>T5,IF(I5="主","屠","人"),S5<T5,IF(I5="主","人","屠"),S5=T5,"平") -> 屠 | V5: {=_xlfn.IFS(S5+T5=0,"",S5>T5,IF(I5="主",IF(S5=5,4,3),IF(S5=5,0,1)),S5<T5,IF(I5="主",IF(T5=5,0,1),IF(T5=5,4,3)),S5=T5,2)} -> 4 | W5: 月亮河公园 | X5: 唐人街 | Y5: =IF($K5="","",IF($K5=$K3,AP3,AP4)) -> 冒险家 | Z5: =IF($K5="","",IF($K5=$K3,AQ3,AQ4)) -> 入殓师 | AA5: =IF($K5="","",IF($K5=$K3,AS3,AS4)) -> 木偶师 | AH5: =IF($K5="","",IF($K5=$K3,AV3,AV4)) -> 跛脚羊 | AK5: 囚徒 | AL5: 古董商 | AM5: 喧嚣 | AP5: 病患 | AQ5: 作曲家 | AR5: 空军 | AS5: 大副 | AT5: 祭司 | AU5: 哭泣小丑 | AV5: 小丑 | AW5: =_xlfn.IFS(AX5="","",AX5=E5,"主",AX5=F5,"客") -> 客 | AX5: =IF(说明!$F$11=3,_xlfn.IFS($G5=1,$E5,$G5=2,$F5,$G5=3,(IF(S5+T5=0,"",$E5)),$G5="加",(IF(S5+T5=0,"",$F5))),_xlfn.IFS($G5=1,$E5,$G5=2,$F5,$G5=3,$E5,$G5=4,(IF(S5+T5=0,"",$F5)),$G5=5,(IF(S5+T5=0,"",$E5)),$G5="加",(IF(S5+T5=0,"",$F5)))) -> TE | AY5: =_xlfn.IFS(AX5="","",AX5=E5,F5,AX5=F5,E5) -> AXIZ
A6: =输入错误检查!A5 -> 0 | B6: =B5 -> 4 | C6: =C5 -> 11 | D6: =D5 -> 12 | E6: =E5 -> AXIZ | F6: =F5 -> TE | G6: 2 | H6: 下 | I6: =IF(K6="","",IF(K6=E6,"主","客")) -> 客 | J6: =IF(K6="","",IF(K6=E6,F6,E6)) -> AXIZ | K6: TE | L6: ppei | S6: 2 | T6: 2 | U6: =_xlfn.IFS(S6+T6=0,"",S6>T6,IF(I6="主","屠","人"),S6<T6,IF(I6="主","人","屠"),S6=T6,"平") -> 平 | V6: {=_xlfn.IFS(S6+T6=0,"",S6>T6,IF(I6="主",IF(S6=5,4,3),IF(S6=5,0,1)),S6<T6,IF(I6="主",IF(T6=5,0,1),IF(T6=5,4,3)),S6=T6,2)} -> 2 | W6: =IF(W5="","",W5) -> 月亮河公园 | X6: =IF(X5="","",X5) -> 唐人街 | Y6: =IF($K6="","",IF($K6=$K4,AP4,AP3)) -> 大副 | Z6: =IF($K6="","",IF($K6=$K4,AQ4,AQ3)) -> 飞行家 | AA6: =IF($K6="","",IF($K6=$K4,AS4,AS3)) -> 咒术师 | AH6: =IF($K6="","",IF($K6=$K4,AV4,AV3)) -> 跛脚羊 | AK6: 冒险家 | AL6: 古董商 | AM6: 喧嚣 | AP6: 野人 | AQ6: 囚徒 | AR6: 病患 | AS6: 空军 | AT6: 先知 | AU6: 木偶师 | AV6: 歌剧演员 | AW6: =_xlfn.IFS(AX6="","",AX6=E6,"主",AX6=F6,"客") -> 客 | AX6: =IF(说明!$F$11=3,_xlfn.IFS($G6=1,$E6,$G6=2,$F6,$G6=3,(IF(S6+T6=0,"",$E6)),$G6="加",(IF(S6+T6=0,"",$F6))),_xlfn.IFS($G6=1,$E6,$G6=2,$F6,$G6=3,$E6,$G6=4,(IF(S6+T6=0,"",$F6)),$G6=5,(IF(S6+T6=0,"",$E6)),$G6="加",(IF(S6+T6=0,"",$F6)))) -> TE | AY6: =_xlfn.IFS(AX6="","",AX6=E6,F6,AX6=F6,E6) -> AXIZ
A7: =输入错误检查!A6 -> 0 | B7: =B6 -> 4 | C7: =C6 -> 11 | D7: =D6 -> 12 | E7: =E6 -> AXIZ | F7: =F6 -> TE | G7: 3 | H7: 上 | I7: =IF(K7="","",IF(K7=E7,"主","客")) -> 客 | J7: =IF(K7="","",IF(K7=E7,F7,E7)) -> AXIZ | K7: TE | L7: ppei | M7: =S7+S8 -> 4 | N7: =T7+T8 -> 4 | O7: =M7+N7 -> 8 | P7: =IF(M7>N7,1,0) -> 0 | Q7: =IF(M7+N7=0,0,IF(M7=N7,1,0)) -> 1 | R7: =IF(M7<N7,1,0) -> 0 | S7: 1 | T7: 3 | U7: =_xlfn.IFS(S7+T7=0,"",S7>T7,IF(I7="主","屠","人"),S7<T7,IF(I7="主","人","屠"),S7=T7,"平") -> 屠 | V7: {=_xlfn.IFS(S7+T7=0,"",S7>T7,IF(I7="主",IF(S7=5,4,3),IF(S7=5,0,1)),S7<T7,IF(I7="主",IF(T7=5,0,1),IF(T7=5,4,3)),S7=T7,2)} -> 3 | W7: 军工厂 | X7: 红教堂 | Y7: =IF($K7="","",IF($K7=$K5,AP5,AP6)) -> 野人 | Z7: =IF($K7="","",IF($K7=$K5,AQ5,AQ6)) -> 囚徒 | AA7: =IF($K7="","",IF($K7=$K5,AS5,AS6)) -> 空军 | AB7: =IF($K7="","",IF($K7=$K5,Y5,Y6)) -> 大副 | AC7: =IF($K7="","",IF($K7=$K5,Z5,Z6)) -> 飞行家 | AD7: =IF($K7="","",IF($K7=$K5,AA5,AA6)) -> 咒术师 | AH7: =IF($K7="","",IF($K7=$K5,AV5,AV6)) -> 歌剧演员 | AI7: =IF($K7="","",IF($K7=$K5,AH5,AH6)) -> 跛脚羊 | AK7: 前锋 | AL7: 机械师 | AM7: 喧嚣 | AN7: 时空之影 | AP7: 先知 | AQ7: 古董商 | AR7: 入殓师 | AS7: 佣兵 | AT7: 小说家 | AU7: 火灾调查员 | AV7: 鹿头 | AW7: =_xlfn.IFS(AX7="","",AX7=E7,"主",AX7=F7,"客") -> 主 | AX7: =IF(说明!$F$11=3,_xlfn.IFS($G7=1,$E7,$G7=2,$F7,$G7=3,(IF(S7+T7=0,"",$E7)),$G7="加",(IF(S7+T7=0,"",$F7))),_xlfn.IFS($G7=1,$E7,$G7=2,$F7,$G7=3,$E7,$G7=4,(IF(S7+T7=0,"",$F7)),$G7=5,(IF(S7+T7=0,"",$E7)),$G7="加",(IF(S7+T7=0,"",$F7)))) -> AXIZ | AY7: =_xlfn.IFS(AX7="","",AX7=E7,F7,AX7=F7,E7) -> TE
A8: =输入错误检查!A7 -> 0 | B8: =B7 -> 4 | C8: =C7 -> 11 | D8: =D7 -> 12 | E8: =E7 -> AXIZ | F8: =F7 -> TE | G8: 3 | H8: 下 | I8: =IF(K8="","",IF(K8=E8,"主","客")) -> 主 | J8: =IF(K8="","",IF(K8=E8,F8,E8)) -> TE | K8: AXIZ | L8: kakaka | S8: 3 | T8: 1 | U8: =_xlfn.IFS(S8+T8=0,"",S8>T8,IF(I8="主","屠","人"),S8<T8,IF(I8="主","人","屠"),S8=T8,"平") -> 屠 | V8: {=_xlfn.IFS(S8+T8=0,"",S8>T8,IF(I8="主",IF(S8=5,4,3),IF(S8=5,0,1)),S8<T8,IF(I8="主",IF(T8=5,0,1),IF(T8=5,4,3)),S8=T8,2)} -> 3 | W8: 军工厂 | X8: =IF(X7="","",X7) -> 红教堂 | Y8: =IF($K8="","",IF($K8=$K6,AP6,AP5)) -> 病患 | Z8: =IF($K8="","",IF($K8=$K6,AQ6,AQ5)) -> 作曲家 | AA8: =IF($K8="","",IF($K8=$K6,AS6,AS5)) -> 大副 | AB8: =IF($K8="","",IF($K8=$K6,Y6,Y5)) -> 冒险家 | AC8: =IF($K8="","",IF($K8=$K6,Z6,Z5)) -> 入殓师 | AD8: =IF($K8="","",IF($K8=$K6,AA6,AA5)) -> 木偶师 | AH8: =IF($K8="","",IF($K8=$K6,AV6,AV5)) -> 小丑 | AI8: =IF($K8="","",IF($K8=$K6,AH6,AH5)) -> 跛脚羊 | AK8: 空军 | AL8: 火灾调查员 | AM8: 时空之影 | AN8: 喧嚣 | AP8: 佣兵 | AQ8: 小说家 | AR8: 古董商 | AS8: 杂技演员 | AT8: 先知 | AU8: 邮差 | AV8: 歌剧演员 | AW8: =_xlfn.IFS(AX8="","",AX8=E8,"主",AX8=F8,"客") -> 主 | AX8: =IF(说明!$F$11=3,_xlfn.IFS($G8=1,$E8,$G8=2,$F8,$G8=3,(IF(S8+T8=0,"",$E8)),$G8="加",(IF(S8+T8=0,"",$F8))),_xlfn.IFS($G8=1,$E8,$G8=2,$F8,$G8=3,$E8,$G8=4,(IF(S8+T8=0,"",$F8)),$G8=5,(IF(S8+T8=0,"",$E8)),$G8="加",(IF(S8+T8=0,"",$F8)))) -> AXIZ | AY8: =_xlfn.IFS(AX8="","",AX8=E8,F8,AX8=F8,E8) -> TE
A9: =输入错误检查!A8 -> 0 | B9: =B8 -> 4 | C9: =C8 -> 11 | D9: =D8 -> 12 | E9: =E8 -> AXIZ | F9: =F8 -> TE | G9: 加 | H9: 上 | I9: =IF(K9="","",IF(K9=E9,"主","客")) | J9: =IF(K9="","",IF(K9=E9,F9,E9)) | M9: =S9+S10 -> 0 | N9: =T9+T10 -> 0 | O9: =M9+N9 -> 0 | P9: =IF(M9>N9,1,0) -> 0 | Q9: =IF(M9+N9=0,0,IF(M9=N9,1,0)) -> 0 | R9: =IF(M9<N9,1,0) -> 0 | U9: =_xlfn.IFS(S9+T9=0,"",S9>T9,IF(I9="主","屠","人"),S9<T9,IF(I9="主","人","屠"),S9=T9,"平") | V9: {=_xlfn.IFS(S9+T9=0,"",S9>T9,IF(I9="主",IF(S9=5,4,3),IF(S9=5,0,1)),S9<T9,IF(I9="主",IF(T9=5,0,1),IF(T9=5,4,3)),S9=T9,2)} | Y9: =IF($K9="","",IF($K9=$K7,AP7,AP8)) | Z9: =IF($K9="","",IF($K9=$K7,AQ7,AQ8)) | AA9: =IF($K9="","",IF($K9=$K7,AS7,AS8)) | AB9: =IF($K9="","",IF($K9=$K7,Y7,Y8)) | AC9: =IF($K9="","",IF($K9=$K7,Z7,Z8)) | AD9: =IF($K9="","",IF($K9=$K7,AA7,AA8)) | AE9: =IF($K9="","",IF($K9=$K7,AB7,AB8)) | AF9: =IF($K9="","",IF($K9=$K7,AC7,AC8)) | AG9: =IF($K9="","",IF($K9=$K7,AD7,AD8)) | AH9: =IF($K9="","",IF($K9=$K7,AV7,AV8)) | AI9: =IF($K9="","",IF($K9=$K7,AH7,AH8)) | AJ9: =IF($K9="","",IF($K9=$K7,AI7,AI8)) | AW9: =_xlfn.IFS(AX9="","",AX9=E9,"主",AX9=F9,"客") | AX9: =IF(说明!$F$11=3,_xlfn.IFS($G9=1,$E9,$G9=2,$F9,$G9=3,(IF(S9+T9=0,"",$E9)),$G9="加",(IF(S9+T9=0,"",$F9))),_xlfn.IFS($G9=1,$E9,$G9=2,$F9,$G9=3,$E9,$G9=4,(IF(S9+T9=0,"",$F9)),$G9=5,(IF(S9+T9=0,"",$E9)),$G9="加",(IF(S9+T9=0,"",$F9)))) | AY9: =_xlfn.IFS(AX9="","",AX9=E9,F9,AX9=F9,E9)
A10: =输入错误检查!A9 -> 0 | B10: =B9 -> 4 | C10: =C9 -> 11 | D10: =D9 -> 12 | E10: =E9 -> AXIZ | F10: =F9 -> TE | G10: 加 | H10: 下 | I10: =IF(K10="","",IF(K10=E10,"主","客")) | J10: =IF(K10="","",IF(K10=E10,F10,E10)) | U10: =_xlfn.IFS(S10+T10=0,"",S10>T10,IF(I10="主","屠","人"),S10<T10,IF(I10="主","人","屠"),S10=T10,"平") | V10: {=_xlfn.IFS(S10+T10=0,"",S10>T10,IF(I10="主",IF(S10=5,4,3),IF(S10=5,0,1)),S10<T10,IF(I10="主",IF(T10=5,0,1),IF(T10=5,4,3)),S10=T10,2)} | X10: =IF(X9="","",X9) | Y10: =IF($K10="","",IF($K10=$K8,AP8,AP7)) | Z10: =IF($K10="","",IF($K10=$K8,AQ8,AQ7)) | AA10: =IF($K10="","",IF($K10=$K8,AS8,AS7)) | AB10: =IF($K10="","",IF($K10=$K8,Y8,Y7)) | AC10: =IF($K10="","",IF($K10=$K8,Z8,Z7)) | AD10: =IF($K10="","",IF($K10=$K8,AA8,AA7)) | AE10: =IF($K10="","",IF($K10=$K8,AB8,AB7)) | AF10: =IF($K10="","",IF($K10=$K8,AC8,AC7)) | AG10: =IF($K10="","",IF($K10=$K8,AD8,AD7)) | AH10: =IF($K10="","",IF($K10=$K8,AV8,AV7)) | AI10: =IF($K10="","",IF($K10=$K8,AH8,AH7)) | AJ10: =IF($K10="","",IF($K10=$K8,AI8,AI7)) | AW10: =_xlfn.IFS(AX10="","",AX10=E10,"主",AX10=F10,"客") | AX10: =IF(说明!$F$11=3,_xlfn.IFS($G10=1,$E10,$G10=2,$F10,$G10=3,(IF(S10+T10=0,"",$E10)),$G10="加",(IF(S10+T10=0,"",$F10))),_xlfn.IFS($G10=1,$E10,$G10=2,$F10,$G10=3,$E10,$G10=4,(IF(S10+T10=0,"",$F10)),$G10=5,(IF(S10+T10=0,"",$E10)),$G10="加",(IF(S10+T10=0,"",$F10)))) | AY10: =_xlfn.IFS(AX10="","",AX10=E10,F10,AX10=F10,E10)
A11: =输入错误检查!A10 -> 0 | B11: 4 | C11: 11 | D11: 14 | E11: RVL | F11: FT | G11: 1 | H11: 上 | I11: =IF(K11="","",IF(K11=E11,"主","客")) -> 客 | J11: =IF(K11="","",IF(K11=E11,F11,E11)) -> RVL | K11: FT | L11: heshen | M11: =S11+S12 -> 2 | N11: =T11+T12 -> 7 | O11: =M11+N11 -> 9 | P11: =IF(M11>N11,1,0) -> 0 | Q11: =IF(M11+N11=0,0,IF(M11=N11,1,0)) -> 0 | R11: =IF(S11<N11,1,0) -> 1 | S11: 0 | T11: 5 | U11: =_xlfn.IFS(S11+T11=0,"",S11>T11,IF(I11="主","屠","人"),S11<T11,IF(I11="主","人","屠"),S11=T11,"平") -> 屠 | V11: {=_xlfn.IFS(S11+T11=0,"",S11>T11,IF(I11="主",IF(S11=5,4,3),IF(S11=5,0,1)),S11<T11,IF(I11="主",IF(T11=5,0,1),IF(T11=5,4,3)),S11=T11,2)} -> 4 | W11: 军工厂 | X11: 永眠镇 | AK11: 机械师 | AL11: 大副 | AP11: 入殓师 | AQ11: 守墓人 | AR11: 先知 | AS11: 木偶师 | AT11: 飞行家 | AU11: 空军 | AV11: 跛脚羊 | AW11: =_xlfn.IFS(AX11="","",AX11=E11,"主",AX11=F11,"客") -> 主 | AX11: =IF(说明!$F$11=3,_xlfn.IFS($G11=1,$E11,$G11=2,$F11,$G11=3,(IF(S11+T11=0,"",$E11)),$G11="加",(IF(S11+T11=0,"",$F11))),_xlfn.IFS($G11=1,$E11,$G11=2,$F11,$G11=3,$E11,$G11=4,(IF(S11+T11=0,"",$F11)),$G11=5,(IF(S11+T11=0,"",$E11)),$G11="加",(IF(S11+T11=0,"",$F11)))) -> RVL | AY11: =_xlfn.IFS(AX11="","",AX11=E11,F11,AX11=F11,E11) -> FT
A12: =输入错误检查!A11 -> 0 | B12: =B11 -> 4 | C12: =C11 -> 11 | D12: =D11 -> 14 | E12: =E11 -> RVL | F12: =F11 -> FT | G12: 1 | H12: 下 | I12: =IF(K12="","",IF(K12=E12,"主","客")) -> 主 | J12: =IF(K12="","",IF(K12=E12,F12,E12)) -> FT | K12: RVL | L12: sprintzer | S12: 2 | T12: 2 | U12: =_xlfn.IFS(S12+T12=0,"",S12>T12,IF(I12="主","屠","人"),S12<T12,IF(I12="主","人","屠"),S12=T12,"平") -> 平 | V12: {=_xlfn.IFS(S12+T12=0,"",S12>T12,IF(I12="主",IF(S12=5,4,3),IF(S12=5,0,1)),S12<T12,IF(I12="主",IF(T12=5,0,1),IF(T12=5,4,3)),S12=T12,2)} -> 2 | W12: =IF(W11="","",W11) -> 军工厂 | X12: =IF(X11="","",X11) -> 永眠镇 | AK12: 先知 | AL12: 机械师 | AP12: 大副 | AQ12: 祭司 | AR12: 入殓师 | AS12: 飞行家 | AT12: 木偶师 | AU12: 心理学家 | AV12: 跛脚羊 | AW12: =_xlfn.IFS(AX12="","",AX12=E12,"主",AX12=F12,"客") -> 主 | AX12: =IF(说明!$F$11=3,_xlfn.IFS($G12=1,$E12,$G12=2,$F12,$G12=3,(IF(S12+T12=0,"",$E12)),$G12="加",(IF(S12+T12=0,"",$F12))),_xlfn.IFS($G12=1,$E12,$G12=2,$F12,$G12=3,$E12,$G12=4,(IF(S12+T12=0,"",$F12)),$G12=5,(IF(S12+T12=0,"",$E12)),$G12="加",(IF(S12+T12=0,"",$F12)))) -> RVL | AY12: =_xlfn.IFS(AX12="","",AX12=E12,F12,AX12=F12,E12) -> FT
A13: =输入错误检查!A12 -> 0 | B13: =B12 -> 4 | C13: =C12 -> 11 | D13: =D12 -> 14 | E13: =E12 -> RVL | F13: =F12 -> FT | G13: 2 | H13: 上 | I13: =IF(K13="","",IF(K13=E13,"主","客")) -> 主 | J13: =IF(K13="","",IF(K13=E13,F13,E13)) -> FT | K13: RVL | L13: sprintzer | M13: =S13+S14 -> 6 | N13: =T13+T14 -> 3 | O13: =M13+N13 -> 9 | P13: =IF(M13>N13,1,0) -> 1 | Q13: =IF(M13+N13=0,0,IF(M13=N13,1,0)) -> 0 | R13: =IF(M13<N13,1,0) -> 0 | S13: 5 | T13: 0 | U13: =_xlfn.IFS(S13+T13=0,"",S13>T13,IF(I13="主","屠","人"),S13<T13,IF(I13="主","人","屠"),S13=T13,"平") -> 屠 | V13: {=_xlfn.IFS(S13+T13=0,"",S13>T13,IF(I13="主",IF(S13=5,4,3),IF(S13=5,0,1)),S13<T13,IF(I13="主",IF(T13=5,0,1),IF(T13=5,4,3)),S13=T13,2)} -> 4 | W13: 月亮河公园 | X13: 唐人街 | Y13: =IF($K13="","",IF($K13=$K11,AP11,AP12)) -> 大副 | Z13: =IF($K13="","",IF($K13=$K11,AQ11,AQ12)) -> 祭司 | AA13: =IF($K13="","",IF($K13=$K11,AS11,AS12)) -> 飞行家 | AH13: =IF($K13="","",IF($K13=$K11,AV11,AV12)) -> 跛脚羊 | AK13: 先知 | AL13: 古董商 | AM13: 喧嚣 | AP13: 佣兵 | AQ13: 空军 | AR13: 木偶师 | AS13: 火灾调查员 | AT13: 囚徒 | AU13: 入殓师 | AV13: 歌剧演员 | AW13: =_xlfn.IFS(AX13="","",AX13=E13,"主",AX13=F13,"客") -> 客 | AX13: =IF(说明!$F$11=3,_xlfn.IFS($G13=1,$E13,$G13=2,$F13,$G13=3,(IF(S13+T13=0,"",$E13)),$G13="加",(IF(S13+T13=0,"",$F13))),_xlfn.IFS($G13=1,$E13,$G13=2,$F13,$G13=3,$E13,$G13=4,(IF(S13+T13=0,"",$F13)),$G13=5,(IF(S13+T13=0,"",$E13)),$G13="加",(IF(S13+T13=0,"",$F13)))) -> FT | AY13: =_xlfn.IFS(AX13="","",AX13=E13,F13,AX13=F13,E13) -> RVL
A14: =输入错误检查!A13 -> 0 | B14: =B13 -> 4 | C14: =C13 -> 11 | D14: =D13 -> 14 | E14: =E13 -> RVL | F14: =F13 -> FT | G14: 2 | H14: 下 | I14: =IF(K14="","",IF(K14=E14,"主","客")) -> 客 | J14: =IF(K14="","",IF(K14=E14,F14,E14)) -> RVL | K14: FT | L14: miao | S14: 1 | T14: 3 | U14: =_xlfn.IFS(S14+T14=0,"",S14>T14,IF(I14="主","屠","人"),S14<T14,IF(I14="主","人","屠"),S14=T14,"平") -> 屠 | V14: {=_xlfn.IFS(S14+T14=0,"",S14>T14,IF(I14="主",IF(S14=5,4,3),IF(S14=5,0,1)),S14<T14,IF(I14="主",IF(T14=5,0,1),IF(T14=5,4,3)),S14=T14,2)} -> 3 | W14: =IF(W13="","",W13) -> 月亮河公园 | X14: =IF(X13="","",X13) -> 唐人街 | Y14: =IF($K14="","",IF($K14=$K12,AP12,AP11)) -> 入殓师 | Z14: =IF($K14="","",IF($K14=$K12,AQ12,AQ11)) -> 守墓人 | AA14: =IF($K14="","",IF($K14=$K12,AS12,AS11)) -> 木偶师 | AH14: =IF($K14="","",IF($K14=$K12,AV12,AV11)) -> 跛脚羊 | AK14: 先知 | AL14: 祭司 | AM14: 喧嚣 | AP14: 火灾调查员 | AQ14: 大副 | AR14: 古董商 | AS14: 囚徒 | AT14: 空军 | AU14: 心理学家 | AV14: 歌剧演员 | AW14: =_xlfn.IFS(AX14="","",AX14=E14,"主",AX14=F14,"客") -> 客 | AX14: =IF(说明!$F$11=3,_xlfn.IFS($G14=1,$E14,$G14=2,$F14,$G14=3,(IF(S14+T14=0,"",$E14)),$G14="加",(IF(S14+T14=0,"",$F14))),_xlfn.IFS($G14=1,$E14,$G14=2,$F14,$G14=3,$E14,$G14=4,(IF(S14+T14=0,"",$F14)),$G14=5,(IF(S14+T14=0,"",$E14)),$G14="加",(IF(S14+T14=0,"",$F14)))) -> FT | AY14: =_xlfn.IFS(AX14="","",AX14=E14,F14,AX14=F14,E14) -> RVL
A15: =输入错误检查!A14 -> 0 | B15: =B14 -> 4 | C15: =C14 -> 11 | D15: =D14 -> 14 | E15: =E14 -> RVL | F15: =F14 -> FT | G15: 3 | H15: 上 | I15: =IF(K15="","",IF(K15=E15,"主","客")) -> 客 | J15: =IF(K15="","",IF(K15=E15,F15,E15)) -> RVL | K15: FT | L15: miao | M15: =S15+S16 -> 3 | N15: =T15+T16 -> 5 | O15: =M15+N15 -> 8 | P15: =IF(M15>N15,1,0) -> 0 | Q15: =IF(M15+N15=0,0,IF(M15=N15,1,0)) -> 0 | R15: =IF(M15<N15,1,0) -> 1 | S15: 1 | T15: 3 | U15: =_xlfn.IFS(S15+T15=0,"",S15>T15,IF(I15="主","屠","人"),S15<T15,IF(I15="主","人","屠"),S15=T15,"平") -> 屠 | V15: {=_xlfn.IFS(S15+T15=0,"",S15>T15,IF(I15="主",IF(S15=5,4,3),IF(S15=5,0,1)),S15<T15,IF(I15="主",IF(T15=5,0,1),IF(T15=5,4,3)),S15=T15,2)} -> 3 | W15: 军工厂 | X15: 湖景村 | Y15: =IF($K15="","",IF($K15=$K13,AP13,AP14)) -> 火灾调查员 | Z15: =IF($K15="","",IF($K15=$K13,AQ13,AQ14)) -> 大副 | AA15: =IF($K15="","",IF($K15=$K13,AS13,AS14)) -> 囚徒 | AB15: =IF($K15="","",IF($K15=$K13,Y13,Y14)) -> 入殓师 | AC15: =IF($K15="","",IF($K15=$K13,Z13,Z14)) -> 守墓人 | AD15: =IF($K15="","",IF($K15=$K13,AA13,AA14)) -> 木偶师 | AH15: =IF($K15="","",IF($K15=$K13,AV13,AV14)) -> 歌剧演员 | AI15: =IF($K15="","",IF($K15=$K13,AH13,AH14)) -> 跛脚羊 | AK15: 先知 | AL15: 小说家 | AM15: 喧嚣 | AN15: 时空之影 | AP15: 佣兵 | AQ15: 空军 | AR15: 杂技演员 | AS15: 心理学家 | AT15: 骑士 | AU15: 机械师 | AV15: 红夫人 | AW15: =_xlfn.IFS(AX15="","",AX15=E15,"主",AX15=F15,"客") -> 主 | AX15: =IF(说明!$F$11=3,_xlfn.IFS($G15=1,$E15,$G15=2,$F15,$G15=3,(IF(S15+T15=0,"",$E15)),$G15="加",(IF(S15+T15=0,"",$F15))),_xlfn.IFS($G15=1,$E15,$G15=2,$F15,$G15=3,$E15,$G15=4,(IF(S15+T15=0,"",$F15)),$G15=5,(IF(S15+T15=0,"",$E15)),$G15="加",(IF(S15+T15=0,"",$F15)))) -> RVL | AY15: =_xlfn.IFS(AX15="","",AX15=E15,F15,AX15=F15,E15) -> FT
A16: =输入错误检查!A15 -> 0 | B16: =B15 -> 4 | C16: =C15 -> 11 | D16: =D15 -> 14 | E16: =E15 -> RVL | F16: =F15 -> FT | G16: 3 | H16: 下 | I16: =IF(K16="","",IF(K16=E16,"主","客")) -> 主 | J16: =IF(K16="","",IF(K16=E16,F16,E16)) -> FT | K16: RVL | L16: sprintzer | S16: 2 | T16: 2 | U16: =_xlfn.IFS(S16+T16=0,"",S16>T16,IF(I16="主","屠","人"),S16<T16,IF(I16="主","人","屠"),S16=T16,"平") -> 平 | V16: {=_xlfn.IFS(S16+T16=0,"",S16>T16,IF(I16="主",IF(S16=5,4,3),IF(S16=5,0,1)),S16<T16,IF(I16="主",IF(T16=5,0,1),IF(T16=5,4,3)),S16=T16,2)} -> 2 | W16: 军工厂 | X16: =IF(X15="","",X15) -> 湖景村 | Y16: =IF($K16="","",IF($K16=$K14,AP14,AP13)) -> 佣兵 | Z16: =IF($K16="","",IF($K16=$K14,AQ14,AQ13)) -> 空军 | AA16: =IF($K16="","",IF($K16=$K14,AS14,AS13)) -> 火灾调查员 | AB16: =IF($K16="","",IF($K16=$K14,Y14,Y13)) -> 大副 | AC16: =IF($K16="","",IF($K16=$K14,Z14,Z13)) -> 祭司 | AD16: =IF($K16="","",IF($K16=$K14,AA14,AA13)) -> 飞行家 | AH16: =IF($K16="","",IF($K16=$K14,AV14,AV13)) -> 歌剧演员 | AI16: =IF($K16="","",IF($K16=$K14,AH14,AH13)) -> 跛脚羊 | AK16: 先知 | AL16: 古董商 | AM16: 时空之影 | AN16: 喧嚣 | AP16: 心理学家 | AQ16: 杂技演员 | AR16: 守墓人 | AS16: 入殓师 | AT16: 前锋 | AU16: 野人 | AV16: 梦之女巫 | AW16: =_xlfn.IFS(AX16="","",AX16=E16,"主",AX16=F16,"客") -> 主 | AX16: =IF(说明!$F$11=3,_xlfn.IFS($G16=1,$E16,$G16=2,$F16,$G16=3,(IF(S16+T16=0,"",$E16)),$G16="加",(IF(S16+T16=0,"",$F16))),_xlfn.IFS($G16=1,$E16,$G16=2,$F16,$G16=3,$E16,$G16=4,(IF(S16+T16=0,"",$F16)),$G16=5,(IF(S16+T16=0,"",$E16)),$G16="加",(IF(S16+T16=0,"",$F16)))) -> RVL | AY16: =_xlfn.IFS(AX16="","",AX16=E16,F16,AX16=F16,E16) -> FT
A17: =输入错误检查!A16 -> 0 | B17: =B16 -> 4 | C17: =C16 -> 11 | D17: =D16 -> 14 | E17: =E16 -> RVL | F17: =F16 -> FT | G17: 加 | H17: 上 | I17: =IF(K17="","",IF(K17=E17,"主","客")) | J17: =IF(K17="","",IF(K17=E17,F17,E17)) | M17: =S17+S18 -> 0 | N17: =T17+T18 -> 0 | O17: =M17+N17 -> 0 | P17: =IF(M17>N17,1,0) -> 0 | Q17: =IF(M17+N17=0,0,IF(M17=N17,1,0)) -> 0 | R17: =IF(M17<N17,1,0) -> 0 | U17: =_xlfn.IFS(S17+T17=0,"",S17>T17,IF(I17="主","屠","人"),S17<T17,IF(I17="主","人","屠"),S17=T17,"平") | V17: {=_xlfn.IFS(S17+T17=0,"",S17>T17,IF(I17="主",IF(S17=5,4,3),IF(S17=5,0,1)),S17<T17,IF(I17="主",IF(T17=5,0,1),IF(T17=5,4,3)),S17=T17,2)} | Y17: =IF($K17="","",IF($K17=$K15,AP15,AP16)) | Z17: =IF($K17="","",IF($K17=$K15,AQ15,AQ16)) | AA17: =IF($K17="","",IF($K17=$K15,AS15,AS16)) | AB17: =IF($K17="","",IF($K17=$K15,Y15,Y16)) | AC17: =IF($K17="","",IF($K17=$K15,Z15,Z16)) | AD17: =IF($K17="","",IF($K17=$K15,AA15,AA16)) | AE17: =IF($K17="","",IF($K17=$K15,AB15,AB16)) | AF17: =IF($K17="","",IF($K17=$K15,AC15,AC16)) | AG17: =IF($K17="","",IF($K17=$K15,AD15,AD16)) | AH17: =IF($K17="","",IF($K17=$K15,AV15,AV16)) | AI17: =IF($K17="","",IF($K17=$K15,AH15,AH16)) | AJ17: =IF($K17="","",IF($K17=$K15,AI15,AI16)) | AW17: =_xlfn.IFS(AX17="","",AX17=E17,"主",AX17=F17,"客") | AX17: =IF(说明!$F$11=3,_xlfn.IFS($G17=1,$E17,$G17=2,$F17,$G17=3,(IF(S17+T17=0,"",$E17)),$G17="加",(IF(S17+T17=0,"",$F17))),_xlfn.IFS($G17=1,$E17,$G17=2,$F17,$G17=3,$E17,$G17=4,(IF(S17+T17=0,"",$F17)),$G17=5,(IF(S17+T17=0,"",$E17)),$G17="加",(IF(S17+T17=0,"",$F17)))) | AY17: =_xlfn.IFS(AX17="","",AX17=E17,F17,AX17=F17,E17)
A18: =输入错误检查!A17 -> 0 | B18: =B17 -> 4 | C18: =C17 -> 11 | D18: =D17 -> 14 | E18: =E17 -> RVL | F18: =F17 -> FT | G18: 加 | H18: 下 | I18: =IF(K18="","",IF(K18=E18,"主","客")) | J18: =IF(K18="","",IF(K18=E18,F18,E18)) | U18: =_xlfn.IFS(S18+T18=0,"",S18>T18,IF(I18="主","屠","人"),S18<T18,IF(I18="主","人","屠"),S18=T18,"平") | V18: {=_xlfn.IFS(S18+T18=0,"",S18>T18,IF(I18="主",IF(S18=5,4,3),IF(S18=5,0,1)),S18<T18,IF(I18="主",IF(T18=5,0,1),IF(T18=5,4,3)),S18=T18,2)} | X18: =IF(X17="","",X17) | Y18: =IF($K18="","",IF($K18=$K16,AP16,AP15)) | Z18: =IF($K18="","",IF($K18=$K16,AQ16,AQ15)) | AA18: =IF($K18="","",IF($K18=$K16,AS16,AS15)) | AB18: =IF($K18="","",IF($K18=$K16,Y16,Y15)) | AC18: =IF($K18="","",IF($K18=$K16,Z16,Z15)) | AD18: =IF($K18="","",IF($K18=$K16,AA16,AA15)) | AE18: =IF($K18="","",IF($K18=$K16,AB16,AB15)) | AF18: =IF($K18="","",IF($K18=$K16,AC16,AC15)) | AG18: =IF($K18="","",IF($K18=$K16,AD16,AD15)) | AH18: =IF($K18="","",IF($K18=$K16,AV16,AV15)) | AI18: =IF($K18="","",IF($K18=$K16,AH16,AH15)) | AJ18: =IF($K18="","",IF($K18=$K16,AI16,AI15)) | AW18: =_xlfn.IFS(AX18="","",AX18=E18,"主",AX18=F18,"客") | AX18: =IF(说明!$F$11=3,_xlfn.IFS($G18=1,$E18,$G18=2,$F18,$G18=3,(IF(S18+T18=0,"",$E18)),$G18="加",(IF(S18+T18=0,"",$F18))),_xlfn.IFS($G18=1,$E18,$G18=2,$F18,$G18=3,$E18,$G18=4,(IF(S18+T18=0,"",$F18)),$G18=5,(IF(S18+T18=0,"",$E18)),$G18="加",(IF(S18+T18=0,"",$F18)))) | AY18: =_xlfn.IFS(AX18="","",AX18=E18,F18,AX18=F18,E18)
A19: =输入错误检查!A18 -> 0 | B19: 4 | C19: 11 | D19: 16 | E19: ZZZ | F19: RD | G19: 1 | H19: 上 | I19: =IF(K19="","",IF(K19=E19,"主","客")) -> 客 | J19: =IF(K19="","",IF(K19=E19,F19,E19)) -> ZZZ | K19: RD | L19: hajimi | M19: =S19+S20 -> 1 | N19: =T19+T20 -> 8 | O19: =M19+N19 -> 9 | P19: =IF(M19>N19,1,0) -> 0 | Q19: =IF(M19+N19=0,0,IF(M19=N19,1,0)) -> 0 | R19: =IF(M19<N19,1,0) -> 1 | S19: 0 | T19: 5 | U19: =_xlfn.IFS(S19+T19=0,"",S19>T19,IF(I19="主","屠","人"),S19<T19,IF(I19="主","人","屠"),S19=T19,"平") -> 屠 | V19: {=_xlfn.IFS(S19+T19=0,"",S19>T19,IF(I19="主",IF(S19=5,4,3),IF(S19=5,0,1)),S19<T19,IF(I19="主",IF(T19=5,0,1),IF(T19=5,4,3)),S19=T19,2)} -> 4 | W19: 圣心医院 | X19: 永眠镇 | AK19: 机械师 | AL19: 大副 | AP19: 空军 | AQ19: 骑士 | AR19: 心理学家 | AS19: 入殓师 | AT19: 飞行家 | AU19: 园丁 | AV19: 喧嚣 | AW19: =_xlfn.IFS(AX19="","",AX19=E19,"主",AX19=F19,"客") -> 主 | AX19: =IF(说明!$F$11=3,_xlfn.IFS($G19=1,$E19,$G19=2,$F19,$G19=3,(IF(S19+T19=0,"",$E19)),$G19="加",(IF(S19+T19=0,"",$F19))),_xlfn.IFS($G19=1,$E19,$G19=2,$F19,$G19=3,$E19,$G19=4,(IF(S19+T19=0,"",$F19)),$G19=5,(IF(S19+T19=0,"",$E19)),$G19="加",(IF(S19+T19=0,"",$F19)))) -> ZZZ | AY19: =_xlfn.IFS(AX19="","",AX19=E19,F19,AX19=F19,E19) -> RD
A20: =输入错误检查!A19 -> 0 | B20: =B19 -> 4 | C20: =C19 -> 11 | D20: =D19 -> 16 | E20: =E19 -> ZZZ | F20: =F19 -> RD | G20: 1 | H20: 下 | I20: =IF(K20="","",IF(K20=E20,"主","客")) -> 主 | J20: =IF(K20="","",IF(K20=E20,F20,E20)) -> RD | K20: ZZZ | L20: mz | S20: 1 | T20: 3 | U20: =_xlfn.IFS(S20+T20=0,"",S20>T20,IF(I20="主","屠","人"),S20<T20,IF(I20="主","人","屠"),S20=T20,"平") -> 人 | V20: {=_xlfn.IFS(S20+T20=0,"",S20>T20,IF(I20="主",IF(S20=5,4,3),IF(S20=5,0,1)),S20<T20,IF(I20="主",IF(T20=5,0,1),IF(T20=5,4,3)),S20=T20,2)} -> 1 | W20: =IF(W19="","",W19) -> 圣心医院 | X20: =IF(X19="","",X19) -> 永眠镇 | AK20: 空军 | AL20: 机械师 | AP20: 守墓人 | AQ20: 古董商 | AR20: 骑士 | AS20: 飞行家 | AT20: 先知 | AU20: 入殓师 | AV20: 歌剧演员 | AW20: =_xlfn.IFS(AX20="","",AX20=E20,"主",AX20=F20,"客") -> 主 | AX20: =IF(说明!$F$11=3,_xlfn.IFS($G20=1,$E20,$G20=2,$F20,$G20=3,(IF(S20+T20=0,"",$E20)),$G20="加",(IF(S20+T20=0,"",$F20))),_xlfn.IFS($G20=1,$E20,$G20=2,$F20,$G20=3,$E20,$G20=4,(IF(S20+T20=0,"",$F20)),$G20=5,(IF(S20+T20=0,"",$E20)),$G20="加",(IF(S20+T20=0,"",$F20)))) -> ZZZ | AY20: =_xlfn.IFS(AX20="","",AX20=E20,F20,AX20=F20,E20) -> RD
A21: =输入错误检查!A20 -> 0 | B21: =B20 -> 4 | C21: =C20 -> 11 | D21: =D20 -> 16 | E21: =E20 -> ZZZ | F21: =F20 -> RD | G21: 2 | H21: 上 | I21: =IF(K21="","",IF(K21=E21,"主","客")) -> 客 | J21: =IF(K21="","",IF(K21=E21,F21,E21)) -> ZZZ | K21: RD | L21: binbin | M21: =S21+S22 -> 2 | N21: =T21+T22 -> 6 | O21: =M21+N21 -> 8 | P21: =IF(M21>N21,1,0) -> 0 | Q21: =IF(M21+N21=0,0,IF(M21=N21,1,0)) -> 0 | R21: =IF(M21<N21,1,0) -> 1 | S21: 1 | T21: 3 | U21: =_xlfn.IFS(S21+T21=0,"",S21>T21,IF(I21="主","屠","人"),S21<T21,IF(I21="主","人","屠"),S21=T21,"平") -> 屠 | V21: {=_xlfn.IFS(S21+T21=0,"",S21>T21,IF(I21="主",IF(S21=5,4,3),IF(S21=5,0,1)),S21<T21,IF(I21="主",IF(T21=5,0,1),IF(T21=5,4,3)),S21=T21,2)} -> 3 | W21: 月亮河公园 | X21: 湖景村 | Y21: =IF($K21="","",IF($K21=$K19,AP19,AP20)) -> 空军 | Z21: =IF($K21="","",IF($K21=$K19,AQ19,AQ20)) -> 骑士 | AA21: =IF($K21="","",IF($K21=$K19,AS19,AS20)) -> 入殓师 | AH21: =IF($K21="","",IF($K21=$K19,AV19,AV20)) -> 喧嚣 | AK21: 先知 | AL21: 古董商 | AM21: 歌剧演员 | AP21: 舞女 | AQ21: 魔术师 | AR21: 木偶师 | AS21: 机械师 | AT21: 大副 | AU21: 守墓人 | AV21: 跛脚羊 | AW21: =_xlfn.IFS(AX21="","",AX21=E21,"主",AX21=F21,"客") -> 客 | AX21: =IF(说明!$F$11=3,_xlfn.IFS($G21=1,$E21,$G21=2,$F21,$G21=3,(IF(S21+T21=0,"",$E21)),$G21="加",(IF(S21+T21=0,"",$F21))),_xlfn.IFS($G21=1,$E21,$G21=2,$F21,$G21=3,$E21,$G21=4,(IF(S21+T21=0,"",$F21)),$G21=5,(IF(S21+T21=0,"",$E21)),$G21="加",(IF(S21+T21=0,"",$F21)))) -> RD | AY21: =_xlfn.IFS(AX21="","",AX21=E21,F21,AX21=F21,E21) -> ZZZ
A22: =输入错误检查!A21 -> 0 | B22: =B21 -> 4 | C22: =C21 -> 11 | D22: =D21 -> 16 | E22: =E21 -> ZZZ | F22: =F21 -> RD | G22: 2 | H22: 下 | I22: =IF(K22="","",IF(K22=E22,"主","客")) -> 主 | J22: =IF(K22="","",IF(K22=E22,F22,E22)) -> RD | K22: ZZZ | L22: mz | S22: 1 | T22: 3 | U22: =_xlfn.IFS(S22+T22=0,"",S22>T22,IF(I22="主","屠","人"),S22<T22,IF(I22="主","人","屠"),S22=T22,"平") -> 人 | V22: {=_xlfn.IFS(S22+T22=0,"",S22>T22,IF(I22="主",IF(S22=5,4,3),IF(S22=5,0,1)),S22<T22,IF(I22="主",IF(T22=5,0,1),IF(T22=5,4,3)),S22=T22,2)} -> 1 | W22: =IF(W21="","",W21) -> 月亮河公园 | X22: =IF(X21="","",X21) -> 湖景村 | Y22: =IF($K22="","",IF($K22=$K20,AP20,AP19)) -> 守墓人 | Z22: =IF($K22="","",IF($K22=$K20,AQ20,AQ19)) -> 古董商 | AA22: =IF($K22="","",IF($K22=$K20,AS20,AS19)) -> 飞行家 | AH22: =IF($K22="","",IF($K22=$K20,AV20,AV19)) -> 歌剧演员 | AK22: 空军 | AL22: 火灾调查员 | AM22: 喧嚣 | AP22: 大副 | AQ22: 心理学家 | AR22: 入殓师 | AS22: 先知 | AT22: 机械师 | AU22: 教授 | AV22: 记录员 | AW22: =_xlfn.IFS(AX22="","",AX22=E22,"主",AX22=F22,"客") -> 客 | AX22: =IF(说明!$F$11=3,_xlfn.IFS($G22=1,$E22,$G22=2,$F22,$G22=3,(IF(S22+T22=0,"",$E22)),$G22="加",(IF(S22+T22=0,"",$F22))),_xlfn.IFS($G22=1,$E22,$G22=2,$F22,$G22=3,$E22,$G22=4,(IF(S22+T22=0,"",$F22)),$G22=5,(IF(S22+T22=0,"",$E22)),$G22="加",(IF(S22+T22=0,"",$F22)))) -> RD | AY22: =_xlfn.IFS(AX22="","",AX22=E22,F22,AX22=F22,E22) -> ZZZ
A23: =输入错误检查!A22 -> 0 | B23: =B22 -> 4 | C23: =C22 -> 11 | D23: =D22 -> 16 | E23: =E22 -> ZZZ | F23: =F22 -> RD | G23: 3 | H23: 上 | I23: =IF(K23="","",IF(K23=E23,"主","客")) | J23: =IF(K23="","",IF(K23=E23,F23,E23)) | M23: =S23+S24 -> 0 | N23: =T23+T24 -> 0 | O23: =M23+N23 -> 0 | P23: =IF(M23>N23,1,0) -> 0 | Q23: =IF(M23+N23=0,0,IF(M23=N23,1,0)) -> 0 | R23: =IF(M23<N23,1,0) -> 0 | U23: =_xlfn.IFS(S23+T23=0,"",S23>T23,IF(I23="主","屠","人"),S23<T23,IF(I23="主","人","屠"),S23=T23,"平") | V23: {=_xlfn.IFS(S23+T23=0,"",S23>T23,IF(I23="主",IF(S23=5,4,3),IF(S23=5,0,1)),S23<T23,IF(I23="主",IF(T23=5,0,1),IF(T23=5,4,3)),S23=T23,2)} | Y23: =IF($K23="","",IF($K23=$K21,AP21,AP22)) | Z23: =IF($K23="","",IF($K23=$K21,AQ21,AQ22)) | AA23: =IF($K23="","",IF($K23=$K21,AS21,AS22)) | AB23: =IF($K23="","",IF($K23=$K21,Y21,Y22)) | AC23: =IF($K23="","",IF($K23=$K21,Z21,Z22)) | AD23: =IF($K23="","",IF($K23=$K21,AA21,AA22)) | AH23: =IF($K23="","",IF($K23=$K21,AV21,AV22)) | AI23: =IF($K23="","",IF($K23=$K21,AH21,AH22)) | AW23: =_xlfn.IFS(AX23="","",AX23=E23,"主",AX23=F23,"客") | AX23: =IF(说明!$F$11=3,_xlfn.IFS($G23=1,$E23,$G23=2,$F23,$G23=3,(IF(S23+T23=0,"",$E23)),$G23="加",(IF(S23+T23=0,"",$F23))),_xlfn.IFS($G23=1,$E23,$G23=2,$F23,$G23=3,$E23,$G23=4,(IF(S23+T23=0,"",$F23)),$G23=5,(IF(S23+T23=0,"",$E23)),$G23="加",(IF(S23+T23=0,"",$F23)))) | AY23: =_xlfn.IFS(AX23="","",AX23=E23,F23,AX23=F23,E23)
A24: =输入错误检查!A23 -> 0 | B24: =B23 -> 4 | C24: =C23 -> 11 | D24: =D23 -> 16 | E24: =E23 -> ZZZ | F24: =F23 -> RD | G24: 3 | H24: 下 | I24: =IF(K24="","",IF(K24=E24,"主","客")) | J24: =IF(K24="","",IF(K24=E24,F24,E24)) | U24: =_xlfn.IFS(S24+T24=0,"",S24>T24,IF(I24="主","屠","人"),S24<T24,IF(I24="主","人","屠"),S24=T24,"平") | V24: {=_xlfn.IFS(S24+T24=0,"",S24>T24,IF(I24="主",IF(S24=5,4,3),IF(S24=5,0,1)),S24<T24,IF(I24="主",IF(T24=5,0,1),IF(T24=5,4,3)),S24=T24,2)} | X24: =IF(X23="","",X23) | Y24: =IF($K24="","",IF($K24=$K22,AP22,AP21)) | Z24: =IF($K24="","",IF($K24=$K22,AQ22,AQ21)) | AA24: =IF($K24="","",IF($K24=$K22,AS22,AS21)) | AB24: =IF($K24="","",IF($K24=$K22,Y22,Y21)) | AC24: =IF($K24="","",IF($K24=$K22,Z22,Z21)) | AD24: =IF($K24="","",IF($K24=$K22,AA22,AA21)) | AH24: =IF($K24="","",IF($K24=$K22,AV22,AV21)) | AI24: =IF($K24="","",IF($K24=$K22,AH22,AH21)) | AW24: =_xlfn.IFS(AX24="","",AX24=E24,"主",AX24=F24,"客") | AX24: =IF(说明!$F$11=3,_xlfn.IFS($G24=1,$E24,$G24=2,$F24,$G24=3,(IF(S24+T24=0,"",$E24)),$G24="加",(IF(S24+T24=0,"",$F24))),_xlfn.IFS($G24=1,$E24,$G24=2,$F24,$G24=3,$E24,$G24=4,(IF(S24+T24=0,"",$F24)),$G24=5,(IF(S24+T24=0,"",$E24)),$G24="加",(IF(S24+T24=0,"",$F24)))) | AY24: =_xlfn.IFS(AX24="","",AX24=E24,F24,AX24=F24,E24)
A25: =输入错误检查!A24 -> 0 | B25: =B24 -> 4 | C25: =C24 -> 11 | D25: =D24 -> 16 | E25: =E24 -> ZZZ | F25: =F24 -> RD | G25: 加 | H25: 上 | I25: =IF(K25="","",IF(K25=E25,"主","客")) | J25: =IF(K25="","",IF(K25=E25,F25,E25)) | M25: =S25+S26 -> 0 | N25: =T25+T26 -> 0 | O25: =M25+N25 -> 0 | P25: =IF(M25>N25,1,0) -> 0 | Q25: =IF(M25+N25=0,0,IF(M25=N25,1,0)) -> 0 | R25: =IF(M25<N25,1,0) -> 0 | U25: =_xlfn.IFS(S25+T25=0,"",S25>T25,IF(I25="主","屠","人"),S25<T25,IF(I25="主","人","屠"),S25=T25,"平") | V25: {=_xlfn.IFS(S25+T25=0,"",S25>T25,IF(I25="主",IF(S25=5,4,3),IF(S25=5,0,1)),S25<T25,IF(I25="主",IF(T25=5,0,1),IF(T25=5,4,3)),S25=T25,2)} | Y25: =IF($K25="","",IF($K25=$K23,AP23,AP24)) | Z25: =IF($K25="","",IF($K25=$K23,AQ23,AQ24)) | AA25: =IF($K25="","",IF($K25=$K23,AS23,AS24)) | AB25: =IF($K25="","",IF($K25=$K23,Y23,Y24)) | AC25: =IF($K25="","",IF($K25=$K23,Z23,Z24)) | AD25: =IF($K25="","",IF($K25=$K23,AA23,AA24)) | AE25: =IF($K25="","",IF($K25=$K23,AB23,AB24)) | AF25: =IF($K25="","",IF($K25=$K23,AC23,AC24)) | AG25: =IF($K25="","",IF($K25=$K23,AD23,AD24)) | AH25: =IF($K25="","",IF($K25=$K23,AV23,AV24)) | AI25: =IF($K25="","",IF($K25=$K23,AH23,AH24)) | AJ25: =IF($K25="","",IF($K25=$K23,AI23,AI24)) | AW25: =_xlfn.IFS(AX25="","",AX25=E25,"主",AX25=F25,"客") | AX25: =IF(说明!$F$11=3,_xlfn.IFS($G25=1,$E25,$G25=2,$F25,$G25=3,(IF(S25+T25=0,"",$E25)),$G25="加",(IF(S25+T25=0,"",$F25))),_xlfn.IFS($G25=1,$E25,$G25=2,$F25,$G25=3,$E25,$G25=4,(IF(S25+T25=0,"",$F25)),$G25=5,(IF(S25+T25=0,"",$E25)),$G25="加",(IF(S25+T25=0,"",$F25)))) | AY25: =_xlfn.IFS(AX25="","",AX25=E25,F25,AX25=F25,E25)
A26: =输入错误检查!A25 -> 0 | B26: =B25 -> 4 | C26: =C25 -> 11 | D26: =D25 -> 16 | E26: =E25 -> ZZZ | F26: =F25 -> RD | G26: 加 | H26: 下 | I26: =IF(K26="","",IF(K26=E26,"主","客")) | J26: =IF(K26="","",IF(K26=E26,F26,E26)) | U26: =_xlfn.IFS(S26+T26=0,"",S26>T26,IF(I26="主","屠","人"),S26<T26,IF(I26="主","人","屠"),S26=T26,"平") | V26: {=_xlfn.IFS(S26+T26=0,"",S26>T26,IF(I26="主",IF(S26=5,4,3),IF(S26=5,0,1)),S26<T26,IF(I26="主",IF(T26=5,0,1),IF(T26=5,4,3)),S26=T26,2)} | X26: =IF(X25="","",X25) | Y26: =IF($K26="","",IF($K26=$K24,AP24,AP23)) | Z26: =IF($K26="","",IF($K26=$K24,AQ24,AQ23)) | AA26: =IF($K26="","",IF($K26=$K24,AS24,AS23)) | AB26: =IF($K26="","",IF($K26=$K24,Y24,Y23)) | AC26: =IF($K26="","",IF($K26=$K24,Z24,Z23)) | AD26: =IF($K26="","",IF($K26=$K24,AA24,AA23)) | AE26: =IF($K26="","",IF($K26=$K24,AB24,AB23)) | AF26: =IF($K26="","",IF($K26=$K24,AC24,AC23)) | AG26: =IF($K26="","",IF($K26=$K24,AD24,AD23)) | AH26: =IF($K26="","",IF($K26=$K24,AV24,AV23)) | AI26: =IF($K26="","",IF($K26=$K24,AH24,AH23)) | AJ26: =IF($K26="","",IF($K26=$K24,AI24,AI23)) | AW26: =_xlfn.IFS(AX26="","",AX26=E26,"主",AX26=F26,"客") | AX26: =IF(说明!$F$11=3,_xlfn.IFS($G26=1,$E26,$G26=2,$F26,$G26=3,(IF(S26+T26=0,"",$E26)),$G26="加",(IF(S26+T26=0,"",$F26))),_xlfn.IFS($G26=1,$E26,$G26=2,$F26,$G26=3,$E26,$G26=4,(IF(S26+T26=0,"",$F26)),$G26=5,(IF(S26+T26=0,"",$E26)),$G26="加",(IF(S26+T26=0,"",$F26)))) | AY26: =_xlfn.IFS(AX26="","",AX26=E26,F26,AX26=F26,E26)
A27: =输入错误检查!A26 -> 0 | B27: 4 | C27: 11 | D27: 18 | E27: GG | F27: RC | G27: 1 | H27: 上 | I27: =IF(K27="","",IF(K27=E27,"主","客")) -> 主 | J27: =IF(K27="","",IF(K27=E27,F27,E27)) -> RC | K27: GG | L27: xawm | M27: =S27+S28 -> 7 | N27: =T27+T28 -> 2 | O27: =M27+N27 -> 9 | P27: =IF(M27>N27,1,0) -> 1 | Q27: =IF(M27+N27=0,0,IF(M27=N27,1,0)) -> 0 | R27: =IF(M27<N27,1,0) -> 0 | S27: 5 | T27: 0 | U27: =_xlfn.IFS(S27+T27=0,"",S27>T27,IF(I27="主","屠","人"),S27<T27,IF(I27="主","人","屠"),S27=T27,"平") -> 屠 | V27: {=_xlfn.IFS(S27+T27=0,"",S27>T27,IF(I27="主",IF(S27=5,4,3),IF(S27=5,0,1)),S27<T27,IF(I27="主",IF(T27=5,0,1),IF(T27=5,4,3)),S27=T27,2)} -> 4 | W27: 里奥的回忆 | X27: 唐人街 | AK27: 先知 | AL27: 冒险家 | AP27: 祭司 | AQ27: 律师 | AR27: 机械师 | AS27: 大副 | AT27: 古董商 | AU27: 飞行家 | AV27: 跛脚羊 | AW27: =_xlfn.IFS(AX27="","",AX27=E27,"主",AX27=F27,"客") -> 主 | AX27: =IF(说明!$F$11=3,_xlfn.IFS($G27=1,$E27,$G27=2,$F27,$G27=3,(IF(S27+T27=0,"",$E27)),$G27="加",(IF(S27+T27=0,"",$F27))),_xlfn.IFS($G27=1,$E27,$G27=2,$F27,$G27=3,$E27,$G27=4,(IF(S27+T27=0,"",$F27)),$G27=5,(IF(S27+T27=0,"",$E27)),$G27="加",(IF(S27+T27=0,"",$F27)))) -> GG | AY27: =_xlfn.IFS(AX27="","",AX27=E27,F27,AX27=F27,E27) -> RC
A28: =输入错误检查!A27 -> 0 | B28: =B27 -> 4 | C28: =C27 -> 11 | D28: =D27 -> 18 | E28: =E27 -> GG | F28: =F27 -> RC | G28: 1 | H28: 下 | I28: =IF(K28="","",IF(K28=E28,"主","客")) -> 客 | J28: =IF(K28="","",IF(K28=E28,F28,E28)) -> GG | K28: RC | L28: aka | S28: 2 | T28: 2 | U28: =_xlfn.IFS(S28+T28=0,"",S28>T28,IF(I28="主","屠","人"),S28<T28,IF(I28="主","人","屠"),S28=T28,"平") -> 平 | V28: {=_xlfn.IFS(S28+T28=0,"",S28>T28,IF(I28="主",IF(S28=5,4,3),IF(S28=5,0,1)),S28<T28,IF(I28="主",IF(T28=5,0,1),IF(T28=5,4,3)),S28=T28,2)} -> 2 | W28: =IF(W27="","",W27) -> 里奥的回忆 | X28: =IF(X27="","",X27) -> 唐人街 | AK28: 机械师 | AL28: 祭司 | AP28: 冒险家 | AQ28: 大副 | AR28: 入殓师 | AS28: 先知 | AT28: 古董商 | AU28: 心理学家 | AV28: 隐士 | AW28: =_xlfn.IFS(AX28="","",AX28=E28,"主",AX28=F28,"客") -> 主 | AX28: =IF(说明!$F$11=3,_xlfn.IFS($G28=1,$E28,$G28=2,$F28,$G28=3,(IF(S28+T28=0,"",$E28)),$G28="加",(IF(S28+T28=0,"",$F28))),_xlfn.IFS($G28=1,$E28,$G28=2,$F28,$G28=3,$E28,$G28=4,(IF(S28+T28=0,"",$F28)),$G28=5,(IF(S28+T28=0,"",$E28)),$G28="加",(IF(S28+T28=0,"",$F28)))) -> GG | AY28: =_xlfn.IFS(AX28="","",AX28=E28,F28,AX28=F28,E28) -> RC
A29: =输入错误检查!A28 -> 0 | B29: =B28 -> 4 | C29: =C28 -> 11 | D29: =D28 -> 18 | E29: =E28 -> GG | F29: =F28 -> RC | G29: 2 | H29: 上 | I29: =IF(K29="","",IF(K29=E29,"主","客")) -> 主 | J29: =IF(K29="","",IF(K29=E29,F29,E29)) -> RC | K29: GG | L29: xawm | M29: =S29+S30 -> 2 | N29: =T29+T30 -> 7 | O29: =M29+N29 -> 9 | P29: =IF(M29>N29,1,0) -> 0 | Q29: =IF(M29+N29=0,0,IF(M29=N29,1,0)) -> 0 | R29: =IF(M29<N29,1,0) -> 1 | S29: 2 | T29: 2 | U29: =_xlfn.IFS(S29+T29=0,"",S29>T29,IF(I29="主","屠","人"),S29<T29,IF(I29="主","人","屠"),S29=T29,"平") -> 平 | V29: {=_xlfn.IFS(S29+T29=0,"",S29>T29,IF(I29="主",IF(S29=5,4,3),IF(S29=5,0,1)),S29<T29,IF(I29="主",IF(T29=5,0,1),IF(T29=5,4,3)),S29=T29,2)} -> 2 | W29: 永眠镇 | X29: 月亮河公园 | Y29: =IF($K29="","",IF($K29=$K27,AP27,AP28)) -> 祭司 | Z29: =IF($K29="","",IF($K29=$K27,AQ27,AQ28)) -> 律师 | AA29: =IF($K29="","",IF($K29=$K27,AS27,AS28)) -> 大副 | AH29: =IF($K29="","",IF($K29=$K27,AV27,AV28)) -> 跛脚羊 | AK29: 先知 | AL29: 古董商 | AM29: 喧嚣 | AP29: 木偶师 | AQ29: 杂技演员 | AR29: 入殓师 | AS29: 野人 | AT29: 飞行家 | AU29: 幸运儿 | AV29: 歌剧演员 | AW29: =_xlfn.IFS(AX29="","",AX29=E29,"主",AX29=F29,"客") -> 客 | AX29: =IF(说明!$F$11=3,_xlfn.IFS($G29=1,$E29,$G29=2,$F29,$G29=3,(IF(S29+T29=0,"",$E29)),$G29="加",(IF(S29+T29=0,"",$F29))),_xlfn.IFS($G29=1,$E29,$G29=2,$F29,$G29=3,$E29,$G29=4,(IF(S29+T29=0,"",$F29)),$G29=5,(IF(S29+T29=0,"",$E29)),$G29="加",(IF(S29+T29=0,"",$F29)))) -> RC | AY29: =_xlfn.IFS(AX29="","",AX29=E29,F29,AX29=F29,E29) -> GG
A30: =输入错误检查!A29 -> 0 | B30: =B29 -> 4 | C30: =C29 -> 11 | D30: =D29 -> 18 | E30: =E29 -> GG | F30: =F29 -> RC | G30: 2 | H30: 下 | I30: =IF(K30="","",IF(K30=E30,"主","客")) -> 客 | J30: =IF(K30="","",IF(K30=E30,F30,E30)) -> GG | K30: RC | L30: aka | S30: 0 | T30: 5 | U30: =_xlfn.IFS(S30+T30=0,"",S30>T30,IF(I30="主","屠","人"),S30<T30,IF(I30="主","人","屠"),S30=T30,"平") -> 屠 | V30: {=_xlfn.IFS(S30+T30=0,"",S30>T30,IF(I30="主",IF(S30=5,4,3),IF(S30=5,0,1)),S30<T30,IF(I30="主",IF(T30=5,0,1),IF(T30=5,4,3)),S30=T30,2)} -> 4 | W30: =IF(W29="","",W29) -> 永眠镇 | X30: =IF(X29="","",X29) -> 月亮河公园 | Y30: =IF($K30="","",IF($K30=$K28,AP28,AP27)) -> 冒险家 | Z30: =IF($K30="","",IF($K30=$K28,AQ28,AQ27)) -> 大副 | AA30: =IF($K30="","",IF($K30=$K28,AS28,AS27)) -> 先知 | AH30: =IF($K30="","",IF($K30=$K28,AV28,AV27)) -> 隐士 | AK30: 祭司 | AL30: 古董商 | AM30: 跛脚羊 | AP30: 佣兵 | AQ30: 入殓师 | AR30: 火灾调查员 | AS30: 空军 | AT30: 飞行家 | AU30: 心理学家 | AV30: 喧嚣 | AW30: =_xlfn.IFS(AX30="","",AX30=E30,"主",AX30=F30,"客") -> 客 | AX30: =IF(说明!$F$11=3,_xlfn.IFS($G30=1,$E30,$G30=2,$F30,$G30=3,(IF(S30+T30=0,"",$E30)),$G30="加",(IF(S30+T30=0,"",$F30))),_xlfn.IFS($G30=1,$E30,$G30=2,$F30,$G30=3,$E30,$G30=4,(IF(S30+T30=0,"",$F30)),$G30=5,(IF(S30+T30=0,"",$E30)),$G30="加",(IF(S30+T30=0,"",$F30)))) -> RC | AY30: =_xlfn.IFS(AX30="","",AX30=E30,F30,AX30=F30,E30) -> GG
A31: =输入错误检查!A30 -> 0 | B31: =B30 -> 4 | C31: =C30 -> 11 | D31: =D30 -> 18 | E31: =E30 -> GG | F31: =F30 -> RC | G31: 3 | H31: 上 | I31: =IF(K31="","",IF(K31=E31,"主","客")) -> 主 | J31: =IF(K31="","",IF(K31=E31,F31,E31)) -> RC | K31: GG | L31: xawm | M31: =S31+S32 -> 4 | N31: =T31+T32 -> 4 | O31: =M31+N31 -> 8 | P31: =IF(M31>N31,1,0) -> 0 | Q31: =IF(M31+N31=0,0,IF(M31=N31,1,0)) -> 1 | R31: =IF(M31<N31,1,0) -> 0 | S31: 1 | T31: 3 | U31: =_xlfn.IFS(S31+T31=0,"",S31>T31,IF(I31="主","屠","人"),S31<T31,IF(I31="主","人","屠"),S31=T31,"平") -> 人 | V31: {=_xlfn.IFS(S31+T31=0,"",S31>T31,IF(I31="主",IF(S31=5,4,3),IF(S31=5,0,1)),S31<T31,IF(I31="主",IF(T31=5,0,1),IF(T31=5,4,3)),S31=T31,2)} -> 1 | X31: 军工厂 | Y31: =IF($K31="","",IF($K31=$K29,AP29,AP30)) -> 木偶师 | Z31: =IF($K31="","",IF($K31=$K29,AQ29,AQ30)) -> 杂技演员 | AA31: =IF($K31="","",IF($K31=$K29,AS29,AS30)) -> 野人 | AB31: =IF($K31="","",IF($K31=$K29,Y29,Y30)) -> 祭司 | AC31: =IF($K31="","",IF($K31=$K29,Z29,Z30)) -> 律师 | AD31: =IF($K31="","",IF($K31=$K29,AA29,AA30)) -> 大副 | AH31: =IF($K31="","",IF($K31=$K29,AV29,AV30)) -> 歌剧演员 | AI31: =IF($K31="","",IF($K31=$K29,AH29,AH30)) -> 跛脚羊 | AK31: 先知 | AL31: 勘探员 | AM31: 喧嚣 | AN31: 使徒 | AP31: 佣兵 | AQ31: 火灾调查员 | AR31: 空军 | AS31: 冒险家 | AT31: 心理学家 | AU31: 囚徒 | AV31: 时空之影 | AW31: =_xlfn.IFS(AX31="","",AX31=E31,"主",AX31=F31,"客") -> 主 | AX31: =IF(说明!$F$11=3,_xlfn.IFS($G31=1,$E31,$G31=2,$F31,$G31=3,(IF(S31+T31=0,"",$E31)),$G31="加",(IF(S31+T31=0,"",$F31))),_xlfn.IFS($G31=1,$E31,$G31=2,$F31,$G31=3,$E31,$G31=4,(IF(S31+T31=0,"",$F31)),$G31=5,(IF(S31+T31=0,"",$E31)),$G31="加",(IF(S31+T31=0,"",$F31)))) -> GG | AY31: =_xlfn.IFS(AX31="","",AX31=E31,F31,AX31=F31,E31) -> RC
A32: =输入错误检查!A31 -> 0 | B32: =B31 -> 4 | C32: =C31 -> 11 | D32: =D31 -> 18 | E32: =E31 -> GG | F32: =F31 -> RC | G32: 3 | H32: 下 | I32: =IF(K32="","",IF(K32=E32,"主","客")) -> 客 | J32: =IF(K32="","",IF(K32=E32,F32,E32)) -> GG | K32: RC | L32: aka | S32: 3 | T32: 1 | U32: =_xlfn.IFS(S32+T32=0,"",S32>T32,IF(I32="主","屠","人"),S32<T32,IF(I32="主","人","屠"),S32=T32,"平") -> 人 | V32: {=_xlfn.IFS(S32+T32=0,"",S32>T32,IF(I32="主",IF(S32=5,4,3),IF(S32=5,0,1)),S32<T32,IF(I32="主",IF(T32=5,0,1),IF(T32=5,4,3)),S32=T32,2)} -> 1 | X32: =IF(X31="","",X31) -> 军工厂 | Y32: =IF($K32="","",IF($K32=$K30,AP30,AP29)) -> 佣兵 | Z32: =IF($K32="","",IF($K32=$K30,AQ30,AQ29)) -> 入殓师 | AA32: =IF($K32="","",IF($K32=$K30,AS30,AS29)) -> 空军 | AB32: =IF($K32="","",IF($K32=$K30,Y30,Y29)) -> 冒险家 | AC32: =IF($K32="","",IF($K32=$K30,Z30,Z29)) -> 大副 | AD32: =IF($K32="","",IF($K32=$K30,AA30,AA29)) -> 先知 | AH32: =IF($K32="","",IF($K32=$K30,AV30,AV29)) -> 喧嚣 | AI32: =IF($K32="","",IF($K32=$K30,AH30,AH29)) -> 隐士 | AK32: 前锋 | AL32: 勘探员 | AM32: 跛脚羊 | AN32: 时空之影 | AP32: 古董商 | AQ32: 心理学家 | AR32: 火灾调查员 | AS32: 飞行家 | AT32: 哭泣小丑 | AU32: 骑士 | AV32: 使徒 | AW32: =_xlfn.IFS(AX32="","",AX32=E32,"主",AX32=F32,"客") -> 主 | AX32: =IF(说明!$F$11=3,_xlfn.IFS($G32=1,$E32,$G32=2,$F32,$G32=3,(IF(S32+T32=0,"",$E32)),$G32="加",(IF(S32+T32=0,"",$F32))),_xlfn.IFS($G32=1,$E32,$G32=2,$F32,$G32=3,$E32,$G32=4,(IF(S32+T32=0,"",$F32)),$G32=5,(IF(S32+T32=0,"",$E32)),$G32="加",(IF(S32+T32=0,"",$F32)))) -> GG | AY32: =_xlfn.IFS(AX32="","",AX32=E32,F32,AX32=F32,E32) -> RC
A33: =输入错误检查!A32 -> 0 | B33: =B32 -> 4 | C33: =C32 -> 11 | D33: =D32 -> 18 | E33: =E32 -> GG | F33: =F32 -> RC | G33: 加 | H33: 上 | I33: =IF(K33="","",IF(K33=E33,"主","客")) -> 客 | J33: =IF(K33="","",IF(K33=E33,F33,E33)) -> GG | K33: RC | L33: aka | M33: =S33+S34 -> 5 | N33: =T33+T34 -> 3 | O33: =M33+N33 -> 8 | P33: =IF(M33>N33,1,0) -> 1 | Q33: =IF(M33+N33=0,0,IF(M33=N33,1,0)) -> 0 | R33: =IF(M33<N33,1,0) -> 0 | S33: 2 | T33: 2 | U33: =_xlfn.IFS(S33+T33=0,"",S33>T33,IF(I33="主","屠","人"),S33<T33,IF(I33="主","人","屠"),S33=T33,"平") -> 平 | V33: {=_xlfn.IFS(S33+T33=0,"",S33>T33,IF(I33="主",IF(S33=5,4,3),IF(S33=5,0,1)),S33<T33,IF(I33="主",IF(T33=5,0,1),IF(T33=5,4,3)),S33=T33,2)} -> 2 | X33: 永眠镇 | Y33: =IF($K33="","",IF($K33=$K31,AP31,AP32)) -> 古董商 | Z33: =IF($K33="","",IF($K33=$K31,AQ31,AQ32)) -> 心理学家 | AA33: =IF($K33="","",IF($K33=$K31,AS31,AS32)) -> 飞行家 | AB33: =IF($K33="","",IF($K33=$K31,Y31,Y32)) -> 佣兵 | AC33: =IF($K33="","",IF($K33=$K31,Z31,Z32)) -> 入殓师 | AD33: =IF($K33="","",IF($K33=$K31,AA31,AA32)) -> 空军 | AE33: =IF($K33="","",IF($K33=$K31,AB31,AB32)) -> 冒险家 | AF33: =IF($K33="","",IF($K33=$K31,AC31,AC32)) -> 大副 | AG33: =IF($K33="","",IF($K33=$K31,AD31,AD32)) -> 先知 | AH33: =IF($K33="","",IF($K33=$K31,AV31,AV32)) -> 使徒 | AI33: =IF($K33="","",IF($K33=$K31,AH31,AH32)) -> 喧嚣 | AJ33: =IF($K33="","",IF($K33=$K31,AI31,AI32)) -> 隐士 | AK33: 祭司 | AL33: 火灾调查员 | AM33: 跛脚羊 | AN33: 疯眼 | AP33: 野人 | AQ33: 囚徒 | AR33: 勘探员 | AS33: 杂技演员 | AT33: 画家 | AU33: 幸运儿 | AV33: 歌剧演员 | AW33: =_xlfn.IFS(AX33="","",AX33=E33,"主",AX33=F33,"客") -> 客 | AX33: =IF(说明!$F$11=3,_xlfn.IFS($G33=1,$E33,$G33=2,$F33,$G33=3,(IF(S33+T33=0,"",$E33)),$G33="加",(IF(S33+T33=0,"",$F33))),_xlfn.IFS($G33=1,$E33,$G33=2,$F33,$G33=3,$E33,$G33=4,(IF(S33+T33=0,"",$F33)),$G33=5,(IF(S33+T33=0,"",$E33)),$G33="加",(IF(S33+T33=0,"",$F33)))) -> RC | AY33: =_xlfn.IFS(AX33="","",AX33=E33,F33,AX33=F33,E33) -> GG
A34: =输入错误检查!A33 -> 0 | B34: =B33 -> 4 | C34: =C33 -> 11 | D34: =D33 -> 18 | E34: =E33 -> GG | F34: =F33 -> RC | G34: 加 | H34: 下 | I34: =IF(K34="","",IF(K34=E34,"主","客")) -> 主 | J34: =IF(K34="","",IF(K34=E34,F34,E34)) -> RC | K34: GG | L34: xawm | S34: 3 | T34: 1 | U34: =_xlfn.IFS(S34+T34=0,"",S34>T34,IF(I34="主","屠","人"),S34<T34,IF(I34="主","人","屠"),S34=T34,"平") -> 屠 | V34: {=_xlfn.IFS(S34+T34=0,"",S34>T34,IF(I34="主",IF(S34=5,4,3),IF(S34=5,0,1)),S34<T34,IF(I34="主",IF(T34=5,0,1),IF(T34=5,4,3)),S34=T34,2)} -> 3 | X34: =IF(X33="","",X33) -> 永眠镇 | Y34: =IF($K34="","",IF($K34=$K32,AP32,AP31)) -> 佣兵 | Z34: =IF($K34="","",IF($K34=$K32,AQ32,AQ31)) -> 火灾调查员 | AA34: =IF($K34="","",IF($K34=$K32,AS32,AS31)) -> 冒险家 | AB34: =IF($K34="","",IF($K34=$K32,Y32,Y31)) -> 木偶师 | AC34: =IF($K34="","",IF($K34=$K32,Z32,Z31)) -> 杂技演员 | AD34: =IF($K34="","",IF($K34=$K32,AA32,AA31)) -> 野人 | AE34: =IF($K34="","",IF($K34=$K32,AB32,AB31)) -> 祭司 | AF34: =IF($K34="","",IF($K34=$K32,AC32,AC31)) -> 律师 | AG34: =IF($K34="","",IF($K34=$K32,AD32,AD31)) -> 大副 | AH34: =IF($K34="","",IF($K34=$K32,AV32,AV31)) -> 时空之影 | AI34: =IF($K34="","",IF($K34=$K32,AH32,AH31)) -> 歌剧演员 | AJ34: =IF($K34="","",IF($K34=$K32,AI32,AI31)) -> 跛脚羊 | AK34: 机械师 | AL34: 先知 | AM34: 喧嚣 | AN34: 使徒 | AP34: 入殓师 | AQ34: 前锋 | AR34: 心理学家 | AS34: 舞女 | AT34: 飞行家 | AU34: 病患 | AV34: 鹿头 | AW34: =_xlfn.IFS(AX34="","",AX34=E34,"主",AX34=F34,"客") -> 客 | AX34: =IF(说明!$F$11=3,_xlfn.IFS($G34=1,$E34,$G34=2,$F34,$G34=3,(IF(S34+T34=0,"",$E34)),$G34="加",(IF(S34+T34=0,"",$F34))),_xlfn.IFS($G34=1,$E34,$G34=2,$F34,$G34=3,$E34,$G34=4,(IF(S34+T34=0,"",$F34)),$G34=5,(IF(S34+T34=0,"",$E34)),$G34="加",(IF(S34+T34=0,"",$F34)))) -> RC | AY34: =_xlfn.IFS(AX34="","",AX34=E34,F34,AX34=F34,E34) -> GG
A35: =输入错误检查!A34 -> 0 | B35: 4 | C35: 12 | D35: 12 | E35: DOU5 | F35: AWG | G35: 1 | H35: 上 | I35: =IF(K35="","",IF(K35=E35,"主","客")) -> 客 | J35: =IF(K35="","",IF(K35=E35,F35,E35)) -> DOU5 | K35: AWG | L35: brontal | M35: =S35+S36 -> 2 | N35: =T35+T36 -> 7 | O35: =M35+N35 -> 9 | P35: =IF(M35>N35,1,0) -> 0 | Q35: =IF(M35+N35=0,0,IF(M35=N35,1,0)) -> 0 | R35: =IF(M35<N35,1,0) -> 1 | S35: 0 | T35: 5 | U35: =_xlfn.IFS(S35+T35=0,"",S35>T35,IF(I35="主","屠","人"),S35<T35,IF(I35="主","人","屠"),S35=T35,"平") -> 屠 | V35: {=_xlfn.IFS(S35+T35=0,"",S35>T35,IF(I35="主",IF(S35=5,4,3),IF(S35=5,0,1)),S35<T35,IF(I35="主",IF(T35=5,0,1),IF(T35=5,4,3)),S35=T35,2)} -> 4 | W35: 湖景村 | X35: 里奥的回忆 | AK35: 大副 | AL35: 机械师 | AP35: 冒险家 | AQ35: 古董商 | AR35: 空军 | AS35: 飞行家 | AT35: 心理学家 | AU35: 前锋 | AV35: 喧嚣 | AW35: =_xlfn.IFS(AX35="","",AX35=E35,"主",AX35=F35,"客") -> 主 | AX35: =IF(说明!$F$11=3,_xlfn.IFS($G35=1,$E35,$G35=2,$F35,$G35=3,(IF(S35+T35=0,"",$E35)),$G35="加",(IF(S35+T35=0,"",$F35))),_xlfn.IFS($G35=1,$E35,$G35=2,$F35,$G35=3,$E35,$G35=4,(IF(S35+T35=0,"",$F35)),$G35=5,(IF(S35+T35=0,"",$E35)),$G35="加",(IF(S35+T35=0,"",$F35)))) -> DOU5 | AY35: =_xlfn.IFS(AX35="","",AX35=E35,F35,AX35=F35,E35) -> AWG
A36: =输入错误检查!A35 -> 0 | B36: =B35 -> 4 | C36: =C35 -> 12 | D36: =D35 -> 12 | E36: =E35 -> DOU5 | F36: =F35 -> AWG | G36: 1 | H36: 下 | I36: =IF(K36="","",IF(K36=E36,"主","客")) -> 主 | J36: =IF(K36="","",IF(K36=E36,F36,E36)) -> AWG | K36: DOU5 | L36: yan | S36: 2 | T36: 2 | U36: =_xlfn.IFS(S36+T36=0,"",S36>T36,IF(I36="主","屠","人"),S36<T36,IF(I36="主","人","屠"),S36=T36,"平") -> 平 | V36: {=_xlfn.IFS(S36+T36=0,"",S36>T36,IF(I36="主",IF(S36=5,4,3),IF(S36=5,0,1)),S36<T36,IF(I36="主",IF(T36=5,0,1),IF(T36=5,4,3)),S36=T36,2)} -> 2 | W36: 湖景村 | X36: 里奥的回忆 | AK36: 机械师 | AL36: 先知 | AP36: 守墓人 | AQ36: 木偶师 | AR36: 冒险家 | AS36: 咒术师 | AT36: 入殓师 | AU36: 杂技演员 | AV36: 跛脚羊 | AW36: =_xlfn.IFS(AX36="","",AX36=E36,"主",AX36=F36,"客") -> 主 | AX36: =IF(说明!$F$11=3,_xlfn.IFS($G36=1,$E36,$G36=2,$F36,$G36=3,(IF(S36+T36=0,"",$E36)),$G36="加",(IF(S36+T36=0,"",$F36))),_xlfn.IFS($G36=1,$E36,$G36=2,$F36,$G36=3,$E36,$G36=4,(IF(S36+T36=0,"",$F36)),$G36=5,(IF(S36+T36=0,"",$E36)),$G36="加",(IF(S36+T36=0,"",$F36)))) -> DOU5 | AY36: =_xlfn.IFS(AX36="","",AX36=E36,F36,AX36=F36,E36) -> AWG
A37: =输入错误检查!A36 -> 0 | B37: =B36 -> 4 | C37: =C36 -> 12 | D37: =D36 -> 12 | E37: =E36 -> DOU5 | F37: =F36 -> AWG | G37: 2 | H37: 上 | I37: =IF(K37="","",IF(K37=E37,"主","客")) -> 主 | J37: =IF(K37="","",IF(K37=E37,F37,E37)) -> AWG | K37: DOU5 | L37: yan | M37: =S37+S38 -> 3 | N37: =T37+T38 -> 5 | O37: =M37+N37 -> 8 | P37: =IF(M37>N37,1,0) -> 0 | Q37: =IF(M37+N37=0,0,IF(M37=N37,1,0)) -> 0 | R37: =IF(M37<N37,1,0) -> 1 | S37: 1 | T37: 3 | U37: =_xlfn.IFS(S37+T37=0,"",S37>T37,IF(I37="主","屠","人"),S37<T37,IF(I37="主","人","屠"),S37=T37,"平") -> 人 | V37: {=_xlfn.IFS(S37+T37=0,"",S37>T37,IF(I37="主",IF(S37=5,4,3),IF(S37=5,0,1)),S37<T37,IF(I37="主",IF(T37=5,0,1),IF(T37=5,4,3)),S37=T37,2)} -> 1 | W37: 唐人街 | X37: 月亮河公园 | Y37: =IF($K37="","",IF($K37=$K35,AP35,AP36)) -> 守墓人 | Z37: =IF($K37="","",IF($K37=$K35,AQ35,AQ36)) -> 木偶师 | AA37: =IF($K37="","",IF($K37=$K35,AS35,AS36)) -> 咒术师 | AH37: =IF($K37="","",IF($K37=$K35,AV35,AV36)) -> 跛脚羊 | AK37: 先知 | AL37: 空军 | AM37: 喧嚣 | AP37: 大副 | AQ37: 古董商 | AR37: 火灾调查员 | AS37: 飞行家 | AT37: 入殓师 | AU37: 心理学家 | AV37: 时空之影 | AW37: =_xlfn.IFS(AX37="","",AX37=E37,"主",AX37=F37,"客") -> 客 | AX37: =IF(说明!$F$11=3,_xlfn.IFS($G37=1,$E37,$G37=2,$F37,$G37=3,(IF(S37+T37=0,"",$E37)),$G37="加",(IF(S37+T37=0,"",$F37))),_xlfn.IFS($G37=1,$E37,$G37=2,$F37,$G37=3,$E37,$G37=4,(IF(S37+T37=0,"",$F37)),$G37=5,(IF(S37+T37=0,"",$E37)),$G37="加",(IF(S37+T37=0,"",$F37)))) -> AWG | AY37: =_xlfn.IFS(AX37="","",AX37=E37,F37,AX37=F37,E37) -> DOU5
A38: =输入错误检查!A37 -> 0 | B38: =B37 -> 4 | C38: =C37 -> 12 | D38: =D37 -> 12 | E38: =E37 -> DOU5 | F38: =F37 -> AWG | G38: 2 | H38: 下 | I38: =IF(K38="","",IF(K38=E38,"主","客")) -> 客 | J38: =IF(K38="","",IF(K38=E38,F38,E38)) -> DOU5 | K38: AWG | L38: brontal | S38: 2 | T38: 2 | U38: =_xlfn.IFS(S38+T38=0,"",S38>T38,IF(I38="主","屠","人"),S38<T38,IF(I38="主","人","屠"),S38=T38,"平") -> 平 | V38: {=_xlfn.IFS(S38+T38=0,"",S38>T38,IF(I38="主",IF(S38=5,4,3),IF(S38=5,0,1)),S38<T38,IF(I38="主",IF(T38=5,0,1),IF(T38=5,4,3)),S38=T38,2)} -> 2 | W38: 唐人街 | X38: 月亮河公园 | Y38: =IF($K38="","",IF($K38=$K36,AP36,AP35)) -> 冒险家 | Z38: =IF($K38="","",IF($K38=$K36,AQ36,AQ35)) -> 古董商 | AA38: =IF($K38="","",IF($K38=$K36,AS36,AS35)) -> 飞行家 | AH38: =IF($K38="","",IF($K38=$K36,AV36,AV35)) -> 喧嚣 | AK38: 空军 | AL38: 祭司 | AM38: 跛脚羊 | AP38: 病患 | AQ38: 野人 | AR38: 先知 | AS38: 调酒师 | AT38: 骑士 | AU38: 杂技演员 | AV38: 歌剧演员 | AW38: =_xlfn.IFS(AX38="","",AX38=E38,"主",AX38=F38,"客") -> 客 | AX38: =IF(说明!$F$11=3,_xlfn.IFS($G38=1,$E38,$G38=2,$F38,$G38=3,(IF(S38+T38=0,"",$E38)),$G38="加",(IF(S38+T38=0,"",$F38))),_xlfn.IFS($G38=1,$E38,$G38=2,$F38,$G38=3,$E38,$G38=4,(IF(S38+T38=0,"",$F38)),$G38=5,(IF(S38+T38=0,"",$E38)),$G38="加",(IF(S38+T38=0,"",$F38)))) -> AWG | AY38: =_xlfn.IFS(AX38="","",AX38=E38,F38,AX38=F38,E38) -> DOU5
A39: =输入错误检查!A38 -> 0 | B39: =B38 -> 4 | C39: =C38 -> 12 | D39: =D38 -> 12 | E39: =E38 -> DOU5 | F39: =F38 -> AWG | G39: 3 | H39: 上 | I39: =IF(K39="","",IF(K39=E39,"主","客")) | J39: =IF(K39="","",IF(K39=E39,F39,E39)) | M39: =S39+S40 -> 0 | N39: =T39+T40 -> 0 | O39: =M39+N39 -> 0 | P39: =IF(M39>N39,1,0) -> 0 | Q39: =IF(M39+N39=0,0,IF(M39=N39,1,0)) -> 0 | R39: =IF(M39<N39,1,0) -> 0 | U39: =_xlfn.IFS(S39+T39=0,"",S39>T39,IF(I39="主","屠","人"),S39<T39,IF(I39="主","人","屠"),S39=T39,"平") | V39: {=_xlfn.IFS(S39+T39=0,"",S39>T39,IF(I39="主",IF(S39=5,4,3),IF(S39=5,0,1)),S39<T39,IF(I39="主",IF(T39=5,0,1),IF(T39=5,4,3)),S39=T39,2)} | Y39: =IF($K39="","",IF($K39=$K37,AP37,AP38)) | Z39: =IF($K39="","",IF($K39=$K37,AQ37,AQ38)) | AA39: =IF($K39="","",IF($K39=$K37,AS37,AS38)) | AB39: =IF($K39="","",IF($K39=$K37,Y37,Y38)) | AC39: =IF($K39="","",IF($K39=$K37,Z37,Z38)) | AD39: =IF($K39="","",IF($K39=$K37,AA37,AA38)) | AH39: =IF($K39="","",IF($K39=$K37,AV37,AV38)) | AI39: =IF($K39="","",IF($K39=$K37,AH37,AH38)) | AW39: =_xlfn.IFS(AX39="","",AX39=E39,"主",AX39=F39,"客") | AX39: =IF(说明!$F$11=3,_xlfn.IFS($G39=1,$E39,$G39=2,$F39,$G39=3,(IF(S39+T39=0,"",$E39)),$G39="加",(IF(S39+T39=0,"",$F39))),_xlfn.IFS($G39=1,$E39,$G39=2,$F39,$G39=3,$E39,$G39=4,(IF(S39+T39=0,"",$F39)),$G39=5,(IF(S39+T39=0,"",$E39)),$G39="加",(IF(S39+T39=0,"",$F39)))) | AY39: =_xlfn.IFS(AX39="","",AX39=E39,F39,AX39=F39,E39)
A40: =输入错误检查!A39 -> 0 | B40: =B39 -> 4 | C40: =C39 -> 12 | D40: =D39 -> 12 | E40: =E39 -> DOU5 | F40: =F39 -> AWG | G40: 3 | H40: 下 | I40: =IF(K40="","",IF(K40=E40,"主","客")) | J40: =IF(K40="","",IF(K40=E40,F40,E40)) | U40: =_xlfn.IFS(S40+T40=0,"",S40>T40,IF(I40="主","屠","人"),S40<T40,IF(I40="主","人","屠"),S40=T40,"平") | V40: {=_xlfn.IFS(S40+T40=0,"",S40>T40,IF(I40="主",IF(S40=5,4,3),IF(S40=5,0,1)),S40<T40,IF(I40="主",IF(T40=5,0,1),IF(T40=5,4,3)),S40=T40,2)} | Y40: =IF($K40="","",IF($K40=$K38,AP38,AP37)) | Z40: =IF($K40="","",IF($K40=$K38,AQ38,AQ37)) | AA40: =IF($K40="","",IF($K40=$K38,AS38,AS37)) | AB40: =IF($K40="","",IF($K40=$K38,Y38,Y37)) | AC40: =IF($K40="","",IF($K40=$K38,Z38,Z37)) | AD40: =IF($K40="","",IF($K40=$K38,AA38,AA37)) | AH40: =IF($K40="","",IF($K40=$K38,AV38,AV37)) | AI40: =IF($K40="","",IF($K40=$K38,AH38,AH37)) | AW40: =_xlfn.IFS(AX40="","",AX40=E40,"主",AX40=F40,"客") | AX40: =IF(说明!$F$11=3,_xlfn.IFS($G40=1,$E40,$G40=2,$F40,$G40=3,(IF(S40+T40=0,"",$E40)),$G40="加",(IF(S40+T40=0,"",$F40))),_xlfn.IFS($G40=1,$E40,$G40=2,$F40,$G40=3,$E40,$G40=4,(IF(S40+T40=0,"",$F40)),$G40=5,(IF(S40+T40=0,"",$E40)),$G40="加",(IF(S40+T40=0,"",$F40)))) | AY40: =_xlfn.IFS(AX40="","",AX40=E40,F40,AX40=F40,E40)
A41: =输入错误检查!A40 -> 0 | B41: =B40 -> 4 | C41: =C40 -> 12 | D41: =D40 -> 12 | E41: =E40 -> DOU5 | F41: =F40 -> AWG | G41: 加 | H41: 上 | I41: =IF(K41="","",IF(K41=E41,"主","客")) | J41: =IF(K41="","",IF(K41=E41,F41,E41)) | M41: =S41+S42 -> 0 | N41: =T41+T42 -> 0 | O41: =M41+N41 -> 0 | P41: =IF(M41>N41,1,0) -> 0 | Q41: =IF(M41+N41=0,0,IF(M41=N41,1,0)) -> 0 | R41: =IF(M41<N41,1,0) -> 0 | U41: =_xlfn.IFS(S41+T41=0,"",S41>T41,IF(I41="主","屠","人"),S41<T41,IF(I41="主","人","屠"),S41=T41,"平") | V41: {=_xlfn.IFS(S41+T41=0,"",S41>T41,IF(I41="主",IF(S41=5,4,3),IF(S41=5,0,1)),S41<T41,IF(I41="主",IF(T41=5,0,1),IF(T41=5,4,3)),S41=T41,2)} | Y41: =IF($K41="","",IF($K41=$K39,AP39,AP40)) | Z41: =IF($K41="","",IF($K41=$K39,AQ39,AQ40)) | AA41: =IF($K41="","",IF($K41=$K39,AS39,AS40)) | AB41: =IF($K41="","",IF($K41=$K39,Y39,Y40)) | AC41: =IF($K41="","",IF($K41=$K39,Z39,Z40)) | AD41: =IF($K41="","",IF($K41=$K39,AA39,AA40)) | AE41: =IF($K41="","",IF($K41=$K39,AB39,AB40)) | AF41: =IF($K41="","",IF($K41=$K39,AC39,AC40)) | AG41: =IF($K41="","",IF($K41=$K39,AD39,AD40)) | AH41: =IF($K41="","",IF($K41=$K39,AV39,AV40)) | AI41: =IF($K41="","",IF($K41=$K39,AH39,AH40)) | AJ41: =IF($K41="","",IF($K41=$K39,AI39,AI40)) | AW41: =_xlfn.IFS(AX41="","",AX41=E41,"主",AX41=F41,"客") | AX41: =IF(说明!$F$11=3,_xlfn.IFS($G41=1,$E41,$G41=2,$F41,$G41=3,(IF(S41+T41=0,"",$E41)),$G41="加",(IF(S41+T41=0,"",$F41))),_xlfn.IFS($G41=1,$E41,$G41=2,$F41,$G41=3,$E41,$G41=4,(IF(S41+T41=0,"",$F41)),$G41=5,(IF(S41+T41=0,"",$E41)),$G41="加",(IF(S41+T41=0,"",$F41)))) | AY41: =_xlfn.IFS(AX41="","",AX41=E41,F41,AX41=F41,E41)
...

Sheet 对局数据
D1: 大天赋填写：飞轮，大心脏，搏命，双弹 | AE1: 大天赋填写：封窗，底牌，一刀，张狂 | AM1: 不建议实时记录时记录
A2: 本页出错 | B2: 日期 | D2: 时间 | E2: 主场 | F2: 客场 | G2: 局 | H2: 半场 | I2: 地图 | J2: 人队 | K2: 人ID1 | L2: 人1 | M2: 区域选择号1 | N2: 大天赋1 | O2: 大天赋2 | P2: 人ID2 | Q2: 人2 | R2: 区域选择号2 | S2: 大天赋1 | T2: 大天赋2 | U2: 人ID3 | V2: 人3 | W2: 区域选择号3 | X2: 大天赋1 | Y2: 大天赋2 | Z2: 人ID4 | AA2: 人4 | AB2: 区域选择号4 | AC2: 大天赋1 | AD2: 大天赋2 | AE2: 屠队 | AF2: 屠ID | AG2: 屠选 | AH2: 区域选择 | AI2: 大天赋1 | AJ2: 大天赋2 | AK2: 辅助特质1 | AL2: 底牌 没带写 未携带 | AM2: 首倒人ID | AN2: 开追时间(分) | AO2: 开追时间(秒) | AP2: 特殊状况备忘 | AQ2: 首倒用时 (分) | AR2: 首倒用时 (秒) | AS2: 首倒时 修机进度 | AT2: 特殊状况备忘 | AU2: 破译加速当刻进度 | AV2: 计时器时间(分) | AW2: 计时器时间(秒) | AX2: 特殊状况备忘 | AY2: 破译完成当刻时间（分） | AZ2: 破译完成当刻时间（秒） | BA2: 暂停或重赛 | BB2: 管理员用时间检查 | BC2: 首倒一溜时间 | BD2: 计时器延时 | BF2: 比赛用时 (分) | BG2: 比赛用时 (秒)
A3: =输入错误检查!C2 -> 0 | B3: =原始数据!B3 -> 4 | C3: =原始数据!C3 -> 11 | D3: =原始数据!D3 -> 12 | E3: =原始数据!E3 -> AXIZ | F3: =原始数据!F3 -> TE | G3: =原始数据!G3 -> 1 | H3: =原始数据!H3 -> 上 | I3: =IF(原始数据!X3="","",原始数据!X3) -> 里奥的回忆 | J3: =原始数据!J3 -> AXIZ | K3: =IF(赛后数据!$M3="","",_xlfn.IFS(L3=赛后数据!$N3,赛后数据!$M3,L3=赛后数据!$V3,赛后数据!$U3,L3=赛后数据!$AD3,赛后数据!$AC3,L3=赛后数据!$AL3,赛后数据!$AK3)) -> takakou | L3: =IF(原始数据!AP3="","",原始数据!AP3) -> 大副 | M3: 6 | N3: 大心脏 | O3: 搏命 | P3: =IF(赛后数据!$M3="","",_xlfn.IFS(Q3=赛后数据!$N3,赛后数据!$M3,Q3=赛后数据!$V3,赛后数据!$U3,Q3=赛后数据!$AD3,赛后数据!$AC3,Q3=赛后数据!$AL3,赛后数据!$AK3)) -> tuna | Q3: =IF(原始数据!AQ3="","",原始数据!AQ3) -> 飞行家 | R3: 8 | S3: 飞轮 | T3: 搏命 | U3: =IF(赛后数据!$M3="","",_xlfn.IFS(V3=赛后数据!$N3,赛后数据!$M3,V3=赛后数据!$V3,赛后数据!$U3,V3=赛后数据!$AD3,赛后数据!$AC3,V3=赛后数据!$AL3,赛后数据!$AK3)) -> nyan | V3: =IF(原始数据!AS3="","",原始数据!AS3) -> 咒术师 | W3: 4 | X3: 双弹 | Y3: 飞轮 | Z3: =IF(赛后数据!$M3="","",_xlfn.IFS(AA3=赛后数据!$N3,赛后数据!$M3,AA3=赛后数据!$V3,赛后数据!$U3,AA3=赛后数据!$AD3,赛后数据!$AC3,AA3=赛后数据!$AL3,赛后数据!$AK3)) -> atto | AA3: =IF(原始数据!AU3="","",原始数据!AU3) -> 冒险家 | AB3: 5 | AC3: 搏命 | AD3: 双弹 | AE3: =IF(原始数据!K3="","",原始数据!K3) -> TE | AF3: =IF(原始数据!L3="","",原始数据!L3) -> ppei | AG3: =IF(原始数据!AV3="","",原始数据!AV3) -> 跛脚羊 | AH3: 7 | AI3: 底牌 | AJ3: 一刀 | AK3: 窥视者 | AL3: 闪现 | AM3: tuna | AN3: 0 | AO3: 10 | AP3: 看见脚印 | AQ3: 0 | AR3: 59 | AS3: 163 | AU3: 390 | AV3: 3 | AW3: 22 | AY3: 5 | AZ3: 15 | BC3: =AQ3*60+AR3-AN3*60-AO3 -> 49 | BD3: =IF(AV3="","",AV3*60+AW3-200) -> 2 | BF3: 6 | BG3: 47
A4: =输入错误检查!C3 -> 0 | B4: =原始数据!B4 -> 4 | C4: =原始数据!C4 -> 11 | D4: =原始数据!D4 -> 12 | E4: =原始数据!E4 -> AXIZ | F4: =原始数据!F4 -> TE | G4: =原始数据!G4 -> 1 | H4: =原始数据!H4 -> 下 | I4: =IF(原始数据!X4="","",原始数据!X4) -> 里奥的回忆 | J4: =原始数据!J4 -> TE | K4: =IF(赛后数据!$M4="","",_xlfn.IFS(L4=赛后数据!$N4,赛后数据!$M4,L4=赛后数据!$V4,赛后数据!$U4,L4=赛后数据!$AD4,赛后数据!$AC4,L4=赛后数据!$AL4,赛后数据!$AK4)) -> yihua | L4: =IF(原始数据!AP4="","",原始数据!AP4) -> 冒险家 | M4: 8 | N4: 飞轮 | O4: 搏命 | P4: =IF(赛后数据!$M4="","",_xlfn.IFS(Q4=赛后数据!$N4,赛后数据!$M4,Q4=赛后数据!$V4,赛后数据!$U4,Q4=赛后数据!$AD4,赛后数据!$AC4,Q4=赛后数据!$AL4,赛后数据!$AK4)) -> libao | Q4: =IF(原始数据!AQ4="","",原始数据!AQ4) -> 入殓师 | R4: 5 | S4: 飞轮 | T4: 双弹 | U4: =IF(赛后数据!$M4="","",_xlfn.IFS(V4=赛后数据!$N4,赛后数据!$M4,V4=赛后数据!$V4,赛后数据!$U4,V4=赛后数据!$AD4,赛后数据!$AC4,V4=赛后数据!$AL4,赛后数据!$AK4)) -> maom | V4: =IF(原始数据!AS4="","",原始数据!AS4) -> 木偶师 | W4: 4 | X4: 搏命 | Y4: 双弹 | Z4: =IF(赛后数据!$M4="","",_xlfn.IFS(AA4=赛后数据!$N4,赛后数据!$M4,AA4=赛后数据!$V4,赛后数据!$U4,AA4=赛后数据!$AD4,赛后数据!$AC4,AA4=赛后数据!$AL4,赛后数据!$AK4)) -> yangy | AA4: =IF(原始数据!AU4="","",原始数据!AU4) -> 心理学家 | AB4: 6 | AC4: 搏命 | AD4: 双弹 | AE4: =IF(原始数据!K4="","",原始数据!K4) -> AXIZ | AF4: =IF(原始数据!L4="","",原始数据!L4) -> kakiri | AG4: =IF(原始数据!AV4="","",原始数据!AV4) -> 跛脚羊 | AH4: 7 | AI4: 底牌 | AJ4: 一刀 | AK4: 闪现 | AL4: 传送 | AM4: yihua | AN4: 0 | AO4: 20 | AP4: 放笼 | AQ4: 0 | AR4: 58 | AS4: 145 | AU4: 426 | AV4: 3 | AW4: 22 | AY4: 5 | AZ4: 21 | BC4: =AQ4*60+AR4-AN4*60-AO4 -> 38 | BD4: =IF(AV4="","",AV4*60+AW4-200) -> 2 | BF4: 6 | BG4: 12
