Workbook

Sheet 说明
A1: 制作者信息 | E1: 当前赛事 | K1: =E3&F3 -> 2026COA总决赛
A2: 名称 | B2: 第五人格赛事信息记录表 | C2: 比分记录 for BWIKI V2.0 | E2: 年份 | F2: 类型 | K2: 总结
A3: BWIKI欢迎各位加入w点击此表格了解BWIKI | E3: 2026 | F3: COA总决赛 | K3: 总场次 | M3: 总局数 | N3: 2局 | O3: 3局 | P3: 4局 | Q3: 5局 | R3: 加赛
A4: 主分、客分列，哪怕是2：0带走，第三局和加赛那一行也必须填上数字，没比的局局分填0就行 | E4: 可上场监管者角色数 | F4: 33 | G4: 监管者indirect区域 | H4: ="'各类选项'!C3:C"&(F4+3) -> '各类选项'!C3:C36 | K4: =90-COUNTIF(赛果!K$2:K$91,"") -> 12 | M4: =720-COUNTIF(原始数据!L3:L722,"") -> 92 | N4: =COUNTIF(赛果!O2:O91,"2") -> 0 | O4: =COUNTIF(赛果!O2:O91,"3") -> 0 | P4: =COUNTIF(赛果!O2:O91,"4") -> 0 | Q4: =COUNTIF(赛果!O2:O91,"5") -> 90 | R4: =COUNTIF(赛果!O2:O91,"6") -> 0
E5: 可上场求生者角色数 | F5: 49 | G5: 求生者indirect区域 | H5: ="'各类选项'!E3:E"&(F5+3) -> '各类选项'!E3:E52 | K5: 监管者BAN | M5: 求生者BAN | O5: 监管者 胜利 | P5: 胜率 | Q5: 求生者 胜利 | R5: 胜率 | S5: 平局 | T5: 平率
A6: 只有与本格子颜色相同的部分才开放编辑权限噢~记录赛事时，原始数据、牵制时长这两个表是都需要填的。若两队通过加时赛的时长比对才分出胜负，那么需要在大分&小分表格寻找和本格子颜色一样的区域，手动填写最终获胜者。除此以外，本表格其他区域所有内容均使用excel函数自动生成，无需进行任何操作~ | E6: 队伍数量 | F6: 12 | G6: indirect区域 | H6: ="'各类选项'!F2:F"&(F6+1) -> '各类选项'!F2:F13
E7: 监管者阵营人数 | F7: 22 | G7: ="'各类选项'!K2:K"&(F7+1) -> '各类选项'!K2:K23 | H7: ="'各类选项'!L2:L"&(F7+1) -> '各类选项'!L2:L23 | O7: =COUNTIFS(原始数据!U3:U722,"屠") -> 41 | P7: =O7/M4 -> 0.44565217 | Q7: =COUNTIFS(原始数据!U3:U722,"人") -> 14 | R7: =Q7/M4 -> 0.15217391 | S7: =COUNTIFS(原始数据!U3:U722,"平") -> 37 | T7: =S7/M4 -> 0.40217391
E8: 求生者阵营人数 | F8: 58 | G8: 求生者indirect区域 | H8: ="'各类选项'!J2:J"&(F8+1) -> '各类选项'!J2:J59 | K8: 第五人格BWIKI赛事组制作 | R8: 45347
A9: 填写原始数据时，如第一轮第一场上半场由DOU5队东玄先上屠夫，则在屠队列填写D5（全大写），在屠名列填写东玄id（全小写）dx。第一轮是ZQ打DOU5，因此如果东玄被三跑，则ZQ:DOU5比分为3:1，主分填3，客分填1即可。地图名字请填写全名，请勿做任何省略。地图方主客即选择地图的一方本轮处于主场或者客场。如第一轮第一场若由DOU5选图，则此处填客字即可，主/客一个字就行！！倒数第二列的剩余台数就是填写剩余密码机数量。最后一列名字是错误，这是一个简单的纠错，一旦有常见的名字输入错误的问题，这里便会计数，但只是能查到，并不是100%查得到！牵制时长表格和原始数据用类似方法填写，但求生者ID不需要带队名。 | E9: 地图数量 | F9: 9 | G9: 地图区域 | H9: ="'各类选项'!G2:G"&(F9+2) -> '各类选项'!G2:G11
E10: 辅助特质 | F10: 7 | G10: 辅助特质校验 | H10: ="'各类选项'!H2:H"&(F10+2) -> '各类选项'!H2:H9
E11: BO数 | F11: 5
A21: 当参赛的选手、角色有更新时，请更改右上黄色区域 并修改【各类选项】sheet

Sheet 重复内容检查
A1: =COUNTIF(A2:A721,"×") -> 0 | B1: =COUNTIF(B2:B721,"×") -> 0 | C1: =COUNTIF(C2:C721,"×") -> 0 | D1: =COUNTIF(D2:D721,"×") -> 0 | E1: =COUNTIF(E2:E721,"×") -> 0 | F1: =COUNTIF(F2:F721,"×") -> 0 | G1: =COUNTIF(G2:G721,"×") -> 0 | H1: =COUNTIF(H2:H721,"×") -> 0 | ... AN1: =COUNTIF(AN2:AN721,"×") -> 3
A2: =IF(IFERROR(原始数据!B3,"×")="×","×","") | B2: =IF(IFERROR(原始数据!C3,"×")="×","×","") | C2: =IF(IFERROR(原始数据!D3,"×")="×","×","") | D2: =IF(IFERROR(原始数据!E3,"×")="×","×","") | E2: =IF(IFERROR(原始数据!F3,"×")="×","×","") | F2: =IF(IFERROR(原始数据!G3,"×")="×","×","") | G2: =IF(IFERROR(原始数据!H3,"×")="×","×","") | H2: =IF(IFERROR(原始数据!I3,"×")="×","×","") | ... T2: =IF(IFERROR(原始数据!U3,"×")="×","×","") | U2: {=IF(原始数据!W3="-","",IF(原始数据!W3="","",IF(COUNT(FIND(原始数据!W3,原始数据!3:3))=2,"×","")))} | V2: {=IF(原始数据!Y3="-","",IF(原始数据!Y3="","",IF(COUNT(FIND(原始数据!Y3,原始数据!3:3))=2,"×","")))} | W2: =IF(原始数据!Z3="","",IF(COUNTIF(原始数据!3:3,原始数据!Z3)>1,"×","")) | X2: =IF(原始数据!AA3="","",IF(COUNTIF(原始数据!3:3,原始数据!AA3)>1,"×","")) | Y2: =IF(原始数据!AE3="","",IF(COUNTIF(原始数据!3:3,原始数据!AE3)>1,"×","")) | Z2: =IF(原始数据!AF3="","",IF(COUNTIF(原始数据!3:3,原始数据!AF3)>1,"×","")) | AA2: =IF(原始数据!AI3="","",IF(COUNTIF(原始数据!3:3,原始数据!AI3)>1,"×","")) | AB2: =IF(原始数据!AJ3="","",IF(COUNTIF(原始数据!3:3,原始数据!AJ3)>1,"×","")) | AC2: =IF(原始数据!AO3="","",IF(COUNTIF(原始数据!3:3,原始数据!AO3)>1,"×","")) | AD2: =IF(原始数据!AP3="","",IF(COUNTIF(原始数据!3:3,原始数据!AP3)>1,"×","")) | AE2: =IF(原始数据!AQ3="","",IF(COUNTIF(原始数据!3:3,原始数据!AQ3)>1,"×","")) | AF2: =IF(原始数据!AR3="","",IF(COUNTIF(原始数据!3:3,原始数据!AR3)>1,"×","")) | AG2: =IF(原始数据!AS3="","",IF(COUNTIF(原始数据!3:3,原始数据!AS3)>1,"×","")) | AH2: =IF(原始数据!AT3="","",IF(COUNTIF(原始数据!3:3,原始数据!AT3)>1,"×","")) | AI2: =IF(原始数据!AU3="","",IF(COUNTIF(原始数据!3:3,原始数据!AU3)>1,"×","")) | AJ2: =IF(原始数据!AV3="","",IF(COUNTIF(原始数据!3:3,原始数据!AV3)>1,"×","")) | ... AN2: =IF(原始数据!AZ3="","",IF(COUNTIF(原始数据!3:3,原始数据!AZ3)>1,"×",""))
A3: =IF(IFERROR(原始数据!B4,"×")="×","×","") | B3: =IF(IFERROR(原始数据!C4,"×")="×","×","") | C3: =IF(IFERROR(原始数据!D4,"×")="×","×","") | D3: =IF(IFERROR(原始数据!E4,"×")="×","×","") | E3: =IF(IFERROR(原始数据!F4,"×")="×","×","") | F3: =IF(IFERROR(原始数据!G4,"×")="×","×","") | G3: =IF(IFERROR(原始数据!H4,"×")="×","×","") | H3: =IF(IFERROR(原始数据!I4,"×")="×","×","") | ... T3: =IF(IFERROR(原始数据!U4,"×")="×","×","") | U3: {=IF(原始数据!W4="-","",IF(原始数据!W4="","",IF(COUNT(FIND(原始数据!W4,原始数据!4:4))=2,"×","")))} | V3: {=IF(原始数据!Y4="-","",IF(原始数据!Y4="","",IF(COUNT(FIND(原始数据!Y4,原始数据!4:4))=2,"×","")))} | W3: =IF(原始数据!Z4="","",IF(COUNTIF(原始数据!4:4,原始数据!Z4)>1,"×","")) | X3: =IF(原始数据!AA4="","",IF(COUNTIF(原始数据!4:4,原始数据!AA4)>1,"×","")) | Y3: =IF(原始数据!AE4="","",IF(COUNTIF(原始数据!4:4,原始数据!AE4)>1,"×","")) | Z3: =IF(原始数据!AF4="","",IF(COUNTIF(原始数据!4:4,原始数据!AF4)>1,"×","")) | AA3: =IF(原始数据!AI4="","",IF(COUNTIF(原始数据!4:4,原始数据!AI4)>1,"×","")) | AB3: =IF(原始数据!AJ4="","",IF(COUNTIF(原始数据!4:4,原始数据!AJ4)>1,"×","")) | AC3: =IF(原始数据!AO4="","",IF(COUNTIF(原始数据!4:4,原始数据!AO4)>1,"×","")) | AD3: =IF(原始数据!AP4="","",IF(COUNTIF(原始数据!4:4,原始数据!AP4)>1,"×","")) | AE3: =IF(原始数据!AQ4="","",IF(COUNTIF(原始数据!4:4,原始数据!AQ4)>1,"×","")) | AF3: =IF(原始数据!AR4="","",IF(COUNTIF(原始数据!4:4,原始数据!AR4)>1,"×","")) | AG3: =IF(原始数据!AS4="","",IF(COUNTIF(原始数据!4:4,原始数据!AS4)>1,"×","")) | AH3: =IF(原始数据!AT4="","",IF(COUNTIF(原始数据!4:4,原始数据!AT4)>1,"×","")) | AI3: =IF(原始数据!AU4="","",IF(COUNTIF(原始数据!4:4,原始数据!AU4)>1,"×","")) | AJ3: =IF(原始数据!AV4="","",IF(COUNTIF(原始数据!4:4,原始数据!AV4)>1,"×","")) | ... AN3: =IF(原始数据!AZ4="","",IF(COUNTIF(原始数据!4:4,原始数据!AZ4)>1,"×",""))
A4: =IF(IFERROR(原始数据!B5,"×")="×","×","") | B4: =IF(IFERROR(原始数据!C5,"×")="×","×","") | C4: =IF(IFERROR(原始数据!D5,"×")="×","×","") | D4: =IF(IFERROR(原始数据!E5,"×")="×","×","") | E4: =IF(IFERROR(原始数据!F5,"×")="×","×","") | F4: =IF(IFERROR(原始数据!G5,"×")="×","×","") | G4: =IF(IFERROR(原始数据!H5,"×")="×","×","") | H4: =IF(IFERROR(原始数据!I5,"×")="×","×","") | ... T4: =IF(IFERROR(原始数据!U5,"×")="×","×","") | U4: {=IF(原始数据!W5="-","",IF(原始数据!W5="","",IF(COUNT(FIND(原始数据!W5,原始数据!5:5))=2,"×","")))} | V4: {=IF(原始数据!Y5="-","",IF(原始数据!Y5="","",IF(COUNT(FIND(原始数据!Y5,原始数据!5:5))=2,"×","")))} | W4: =IF(原始数据!Z5="","",IF(COUNTIF(原始数据!5:5,原始数据!Z5)>1,"×","")) | X4: =IF(原始数据!AA5="","",IF(COUNTIF(原始数据!5:5,原始数据!AA5)>1,"×","")) | Y4: =IF(原始数据!AE5="","",IF(COUNTIF(原始数据!5:5,原始数据!AE5)>1,"×","")) | Z4: =IF(原始数据!AF5="","",IF(COUNTIF(原始数据!5:5,原始数据!AF5)>1,"×","")) | AA4: =IF(原始数据!AI5="","",IF(COUNTIF(原始数据!5:5,原始数据!AI5)>1,"×","")) | AB4: =IF(原始数据!AJ5="","",IF(COUNTIF(原始数据!5:5,原始数据!AJ5)>1,"×","")) | AC4: =IF(原始数据!AO5="","",IF(COUNTIF(原始数据!5:5,原始数据!AO5)>1,"×","")) | AD4: =IF(原始数据!AP5="","",IF(COUNTIF(原始数据!5:5,原始数据!AP5)>1,"×","")) | AE4: =IF(原始数据!AQ5="","",IF(COUNTIF(原始数据!5:5,原始数据!AQ5)>1,"×","")) | AF4: =IF(原始数据!AR5="","",IF(COUNTIF(原始数据!5:5,原始数据!AR5)>1,"×","")) | AG4: =IF(原始数据!AS5="","",IF(COUNTIF(原始数据!5:5,原始数据!AS5)>1,"×","")) | AH4: =IF(原始数据!AT5="","",IF(COUNTIF(原始数据!5:5,原始数据!AT5)>1,"×","")) | AI4: =IF(原始数据!AU5="","",IF(COUNTIF(原始数据!5:5,原始数据!AU5)>1,"×","")) | AJ4: =IF(原始数据!AV5="","",IF(COUNTIF(原始数据!5:5,原始数据!AV5)>1,"×","")) | ... AN4: =IF(原始数据!AZ5="","",IF(COUNTIF(原始数据!5:5,原始数据!AZ5)>1,"×",""))
A5: =IF(IFERROR(原始数据!B6,"×")="×","×","") | B5: =IF(IFERROR(原始数据!C6,"×")="×","×","") | C5: =IF(IFERROR(原始数据!D6,"×")="×","×","") | D5: =IF(IFERROR(原始数据!E6,"×")="×","×","") | E5: =IF(IFERROR(原始数据!F6,"×")="×","×","") | F5: =IF(IFERROR(原始数据!G6,"×")="×","×","") | G5: =IF(IFERROR(原始数据!H6,"×")="×","×","") | H5: =IF(IFERROR(原始数据!I6,"×")="×","×","") | ... T5: =IF(IFERROR(原始数据!U6,"×")="×","×","") | U5: {=IF(原始数据!W6="-","",IF(原始数据!W6="","",IF(COUNT(FIND(原始数据!W6,原始数据!6:6))=2,"×","")))} | V5: {=IF(原始数据!Y6="-","",IF(原始数据!Y6="","",IF(COUNT(FIND(原始数据!Y6,原始数据!6:6))=2,"×","")))} | W5: =IF(原始数据!Z6="","",IF(COUNTIF(原始数据!6:6,原始数据!Z6)>1,"×","")) | X5: =IF(原始数据!AA6="","",IF(COUNTIF(原始数据!6:6,原始数据!AA6)>1,"×","")) | Y5: =IF(原始数据!AE6="","",IF(COUNTIF(原始数据!6:6,原始数据!AE6)>1,"×","")) | Z5: =IF(原始数据!AF6="","",IF(COUNTIF(原始数据!6:6,原始数据!AF6)>1,"×","")) | AA5: =IF(原始数据!AI6="","",IF(COUNTIF(原始数据!6:6,原始数据!AI6)>1,"×","")) | AB5: =IF(原始数据!AJ6="","",IF(COUNTIF(原始数据!6:6,原始数据!AJ6)>1,"×","")) | AC5: =IF(原始数据!AO6="","",IF(COUNTIF(原始数据!6:6,原始数据!AO6)>1,"×","")) | AD5: =IF(原始数据!AP6="","",IF(COUNTIF(原始数据!6:6,原始数据!AP6)>1,"×","")) | AE5: =IF(原始数据!AQ6="","",IF(COUNTIF(原始数据!6:6,原始数据!AQ6)>1,"×","")) | AF5: =IF(原始数据!AR6="","",IF(COUNTIF(原始数据!6:6,原始数据!AR6)>1,"×","")) | AG5: =IF(原始数据!AS6="","",IF(COUNTIF(原始数据!6:6,原始数据!AS6)>1,"×","")) | AH5: =IF(原始数据!AT6="","",IF(COUNTIF(原始数据!6:6,原始数据!AT6)>1,"×","")) | AI5: =IF(原始数据!AU6="","",IF(COUNTIF(原始数据!6:6,原始数据!AU6)>1,"×","")) | AJ5: =IF(原始数据!AV6="","",IF(COUNTIF(原始数据!6:6,原始数据!AV6)>1,"×","")) | ... AN5: =IF(原始数据!AZ6="","",IF(COUNTIF(原始数据!6:6,原始数据!AZ6)>1,"×",""))
A6: =IF(IFERROR(原始数据!B7,"×")="×","×","") | B6: =IF(IFERROR(原始数据!C7,"×")="×","×","") | C6: =IF(IFERROR(原始数据!D7,"×")="×","×","") | D6: =IF(IFERROR(原始数据!E7,"×")="×","×","") | E6: =IF(IFERROR(原始数据!F7,"×")="×","×","") | F6: =IF(IFERROR(原始数据!G7,"×")="×","×","") | G6: =IF(IFERROR(原始数据!H7,"×")="×","×","") | H6: =IF(IFERROR(原始数据!I7,"×")="×","×","") | ... T6: =IF(IFERROR(原始数据!U7,"×")="×","×","") | U6: {=IF(原始数据!W7="-","",IF(原始数据!W7="","",IF(COUNT(FIND(原始数据!W7,原始数据!7:7))=2,"×","")))} | V6: {=IF(原始数据!Y7="-","",IF(原始数据!Y7="","",IF(COUNT(FIND(原始数据!Y7,原始数据!7:7))=2,"×","")))} | W6: =IF(原始数据!Z7="","",IF(COUNTIF(原始数据!7:7,原始数据!Z7)>1,"×","")) | X6: =IF(原始数据!AA7="","",IF(COUNTIF(原始数据!7:7,原始数据!AA7)>1,"×","")) | Y6: =IF(原始数据!AE7="","",IF(COUNTIF(原始数据!7:7,原始数据!AE7)>1,"×","")) | Z6: =IF(原始数据!AF7="","",IF(COUNTIF(原始数据!7:7,原始数据!AF7)>1,"×","")) | AA6: =IF(原始数据!AI7="","",IF(COUNTIF(原始数据!7:7,原始数据!AI7)>1,"×","")) | AB6: =IF(原始数据!AJ7="","",IF(COUNTIF(原始数据!7:7,原始数据!AJ7)>1,"×","")) | AC6: =IF(原始数据!AO7="","",IF(COUNTIF(原始数据!7:7,原始数据!AO7)>1,"×","")) | AD6: =IF(原始数据!AP7="","",IF(COUNTIF(原始数据!7:7,原始数据!AP7)>1,"×","")) | AE6: =IF(原始数据!AQ7="","",IF(COUNTIF(原始数据!7:7,原始数据!AQ7)>1,"×","")) | AF6: =IF(原始数据!AR7="","",IF(COUNTIF(原始数据!7:7,原始数据!AR7)>1,"×","")) | AG6: =IF(原始数据!AS7="","",IF(COUNTIF(原始数据!7:7,原始数据!AS7)>1,"×","")) | AH6: =IF(原始数据!AT7="","",IF(COUNTIF(原始数据!7:7,原始数据!AT7)>1,"×","")) | AI6: =IF(原始数据!AU7="","",IF(COUNTIF(原始数据!7:7,原始数据!AU7)>1,"×","")) | AJ6: =IF(原始数据!AV7="","",IF(COUNTIF(原始数据!7:7,原始数据!AV7)>1,"×","")) | ... AN6: =IF(原始数据!AZ7="","",IF(COUNTIF(原始数据!7:7,原始数据!AZ7)>1,"×",""))
A7: =IF(IFERROR(原始数据!B8,"×")="×","×","") | B7: =IF(IFERROR(原始数据!C8,"×")="×","×","") | C7: =IF(IFERROR(原始数据!D8,"×")="×","×","") | D7: =IF(IFERROR(原始数据!E8,"×")="×","×","") | E7: =IF(IFERROR(原始数据!F8,"×")="×","×","") | F7: =IF(IFERROR(原始数据!G8,"×")="×","×","") | G7: =IF(IFERROR(原始数据!H8,"×")="×","×","") | H7: =IF(IFERROR(原始数据!I8,"×")="×","×","") | ... T7: =IF(IFERROR(原始数据!U8,"×")="×","×","") | U7: {=IF(原始数据!W8="-","",IF(原始数据!W8="","",IF(COUNT(FIND(原始数据!W8,原始数据!8:8))=2,"×","")))} | V7: {=IF(原始数据!Y8="-","",IF(原始数据!Y8="","",IF(COUNT(FIND(原始数据!Y8,原始数据!8:8))=2,"×","")))} | W7: =IF(原始数据!Z8="","",IF(COUNTIF(原始数据!8:8,原始数据!Z8)>1,"×","")) | X7: =IF(原始数据!AA8="","",IF(COUNTIF(原始数据!8:8,原始数据!AA8)>1,"×","")) | Y7: =IF(原始数据!AE8="","",IF(COUNTIF(原始数据!8:8,原始数据!AE8)>1,"×","")) | Z7: =IF(原始数据!AF8="","",IF(COUNTIF(原始数据!8:8,原始数据!AF8)>1,"×","")) | AA7: =IF(原始数据!AI8="","",IF(COUNTIF(原始数据!8:8,原始数据!AI8)>1,"×","")) | AB7: =IF(原始数据!AJ8="","",IF(COUNTIF(原始数据!8:8,原始数据!AJ8)>1,"×","")) | AC7: =IF(原始数据!AO8="","",IF(COUNTIF(原始数据!8:8,原始数据!AO8)>1,"×","")) | AD7: =IF(原始数据!AP8="","",IF(COUNTIF(原始数据!8:8,原始数据!AP8)>1,"×","")) | AE7: =IF(原始数据!AQ8="","",IF(COUNTIF(原始数据!8:8,原始数据!AQ8)>1,"×","")) | AF7: =IF(原始数据!AR8="","",IF(COUNTIF(原始数据!8:8,原始数据!AR8)>1,"×","")) | AG7: =IF(原始数据!AS8="","",IF(COUNTIF(原始数据!8:8,原始数据!AS8)>1,"×","")) | AH7: =IF(原始数据!AT8="","",IF(COUNTIF(原始数据!8:8,原始数据!AT8)>1,"×","")) | AI7: =IF(原始数据!AU8="","",IF(COUNTIF(原始数据!8:8,原始数据!AU8)>1,"×","")) | AJ7: =IF(原始数据!AV8="","",IF(COUNTIF(原始数据!8:8,原始数据!AV8)>1,"×","")) | ... AN7: =IF(原始数据!AZ8="","",IF(COUNTIF(原始数据!8:8,原始数据!AZ8)>1,"×",""))
A8: =IF(IFERROR(原始数据!B9,"×")="×","×","") | B8: =IF(IFERROR(原始数据!C9,"×")="×","×","") | C8: =IF(IFERROR(原始数据!D9,"×")="×","×","") | D8: =IF(IFERROR(原始数据!E9,"×")="×","×","") | E8: =IF(IFERROR(原始数据!F9,"×")="×","×","") | F8: =IF(IFERROR(原始数据!G9,"×")="×","×","") | G8: =IF(IFERROR(原始数据!H9,"×")="×","×","") | H8: =IF(IFERROR(原始数据!I9,"×")="×","×","") | ... T8: =IF(IFERROR(原始数据!U9,"×")="×","×","") | U8: {=IF(原始数据!W9="-","",IF(原始数据!W9="","",IF(COUNT(FIND(原始数据!W9,原始数据!9:9))=2,"×","")))} | V8: {=IF(原始数据!Y9="-","",IF(原始数据!Y9="","",IF(COUNT(FIND(原始数据!Y9,原始数据!9:9))=2,"×","")))} | W8: =IF(原始数据!Z9="","",IF(COUNTIF(原始数据!9:9,原始数据!Z9)>1,"×","")) | X8: =IF(原始数据!AA9="","",IF(COUNTIF(原始数据!9:9,原始数据!AA9)>1,"×","")) | Y8: =IF(原始数据!AE9="","",IF(COUNTIF(原始数据!9:9,原始数据!AE9)>1,"×","")) | Z8: =IF(原始数据!AF9="","",IF(COUNTIF(原始数据!9:9,原始数据!AF9)>1,"×","")) | AA8: =IF(原始数据!AI9="","",IF(COUNTIF(原始数据!9:9,原始数据!AI9)>1,"×","")) | AB8: =IF(原始数据!AJ9="","",IF(COUNTIF(原始数据!9:9,原始数据!AJ9)>1,"×","")) | AC8: =IF(原始数据!AO9="","",IF(COUNTIF(原始数据!9:9,原始数据!AO9)>1,"×","")) | AD8: =IF(原始数据!AP9="","",IF(COUNTIF(原始数据!9:9,原始数据!AP9)>1,"×","")) | AE8: =IF(原始数据!AQ9="","",IF(COUNTIF(原始数据!9:9,原始数据!AQ9)>1,"×","")) | AF8: =IF(原始数据!AR9="","",IF(COUNTIF(原始数据!9:9,原始数据!AR9)>1,"×","")) | AG8: =IF(原始数据!AS9="","",IF(COUNTIF(原始数据!9:9,原始数据!AS9)>1,"×","")) | AH8: =IF(原始数据!AT9="","",IF(COUNTIF(原始数据!9:9,原始数据!AT9)>1,"×","")) | AI8: =IF(原始数据!AU9="","",IF(COUNTIF(原始数据!9:9,原始数据!AU9)>1,"×","")) | AJ8: =IF(原始数据!AV9="","",IF(COUNTIF(原始数据!9:9,原始数据!AV9)>1,"×","")) | ... AN8: =IF(原始数据!AZ9="","",IF(COUNTIF(原始数据!9:9,原始数据!AZ9)>1,"×",""))
A9: =IF(IFERROR(原始数据!B10,"×")="×","×","") | B9: =IF(IFERROR(原始数据!C10,"×")="×","×","") | C9: =IF(IFERROR(原始数据!D10,"×")="×","×","") | D9: =IF(IFERROR(原始数据!E10,"×")="×","×","") | E9: =IF(IFERROR(原始数据!F10,"×")="×","×","") | F9: =IF(IFERROR(原始数据!G10,"×")="×","×","") | G9: =IF(IFERROR(原始数据!H10,"×")="×","×","") | H9: =IF(IFERROR(原始数据!I10,"×")="×","×","") | ... T9: =IF(IFERROR(原始数据!U10,"×")="×","×","") | U9: {=IF(原始数据!W10="-","",IF(原始数据!W10="","",IF(COUNT(FIND(原始数据!W10,原始数据!10:10))=2,"×","")))} | V9: {=IF(原始数据!Y10="-","",IF(原始数据!Y10="","",IF(COUNT(FIND(原始数据!Y10,原始数据!10:10))=2,"×","")))} | W9: =IF(原始数据!Z10="","",IF(COUNTIF(原始数据!10:10,原始数据!Z10)>1,"×","")) | X9: =IF(原始数据!AA10="","",IF(COUNTIF(原始数据!10:10,原始数据!AA10)>1,"×","")) | Y9: =IF(原始数据!AE10="","",IF(COUNTIF(原始数据!10:10,原始数据!AE10)>1,"×","")) | Z9: =IF(原始数据!AF10="","",IF(COUNTIF(原始数据!10:10,原始数据!AF10)>1,"×","")) | AA9: =IF(原始数据!AI10="","",IF(COUNTIF(原始数据!10:10,原始数据!AI10)>1,"×","")) | AB9: =IF(原始数据!AJ10="","",IF(COUNTIF(原始数据!10:10,原始数据!AJ10)>1,"×","")) | AC9: =IF(原始数据!AO10="","",IF(COUNTIF(原始数据!10:10,原始数据!AO10)>1,"×","")) | AD9: =IF(原始数据!AP10="","",IF(COUNTIF(原始数据!10:10,原始数据!AP10)>1,"×","")) | AE9: =IF(原始数据!AQ10="","",IF(COUNTIF(原始数据!10:10,原始数据!AQ10)>1,"×","")) | AF9: =IF(原始数据!AR10="","",IF(COUNTIF(原始数据!10:10,原始数据!AR10)>1,"×","")) | AG9: =IF(原始数据!AS10="","",IF(COUNTIF(原始数据!10:10,原始数据!AS10)>1,"×","")) | AH9: =IF(原始数据!AT10="","",IF(COUNTIF(原始数据!10:10,原始数据!AT10)>1,"×","")) | AI9: =IF(原始数据!AU10="","",IF(COUNTIF(原始数据!10:10,原始数据!AU10)>1,"×","")) | AJ9: =IF(原始数据!AV10="","",IF(COUNTIF(原始数据!10:10,原始数据!AV10)>1,"×","")) | ... AN9: =IF(原始数据!AZ10="","",IF(COUNTIF(原始数据!10:10,原始数据!AZ10)>1,"×",""))
A10: =IF(IFERROR(原始数据!B11,"×")="×","×","") | B10: =IF(IFERROR(原始数据!C11,"×")="×","×","") | C10: =IF(IFERROR(原始数据!D11,"×")="×","×","") | D10: =IF(IFERROR(原始数据!E11,"×")="×","×","") | E10: =IF(IFERROR(原始数据!F11,"×")="×","×","") | F10: =IF(IFERROR(原始数据!G11,"×")="×","×","") | G10: =IF(IFERROR(原始数据!H11,"×")="×","×","") | H10: =IF(IFERROR(原始数据!I11,"×")="×","×","") | ... T10: =IF(IFERROR(原始数据!U11,"×")="×","×","") | U10: {=IF(原始数据!W11="-","",IF(原始数据!W11="","",IF(COUNT(FIND(原始数据!W11,原始数据!11:11))=2,"×","")))} | V10: {=IF(原始数据!Y11="-","",IF(原始数据!Y11="","",IF(COUNT(FIND(原始数据!Y11,原始数据!11:11))=2,"×","")))} | W10: =IF(原始数据!Z11="","",IF(COUNTIF(原始数据!11:11,原始数据!Z11)>1,"×","")) | X10: =IF(原始数据!AA11="","",IF(COUNTIF(原始数据!11:11,原始数据!AA11)>1,"×","")) | Y10: =IF(原始数据!AE11="","",IF(COUNTIF(原始数据!11:11,原始数据!AE11)>1,"×","")) | Z10: =IF(原始数据!AF11="","",IF(COUNTIF(原始数据!11:11,原始数据!AF11)>1,"×","")) | AA10: =IF(原始数据!AI11="","",IF(COUNTIF(原始数据!11:11,原始数据!AI11)>1,"×","")) | AB10: =IF(原始数据!AJ11="","",IF(COUNTIF(原始数据!11:11,原始数据!AJ11)>1,"×","")) | AC10: =IF(原始数据!AO11="","",IF(COUNTIF(原始数据!11:11,原始数据!AO11)>1,"×","")) | AD10: =IF(原始数据!AP11="","",IF(COUNTIF(原始数据!11:11,原始数据!AP11)>1,"×","")) | AE10: =IF(原始数据!AQ11="","",IF(COUNTIF(原始数据!11:11,原始数据!AQ11)>1,"×","")) | AF10: =IF(原始数据!AR11="","",IF(COUNTIF(原始数据!11:11,原始数据!AR11)>1,"×","")) | AG10: =IF(原始数据!AS11="","",IF(COUNTIF(原始数据!11:11,原始数据!AS11)>1,"×","")) | AH10: =IF(原始数据!AT11="","",IF(COUNTIF(原始数据!11:11,原始数据!AT11)>1,"×","")) | AI10: =IF(原始数据!AU11="","",IF(COUNTIF(原始数据!11:11,原始数据!AU11)>1,"×","")) | AJ10: =IF(原始数据!AV11="","",IF(COUNTIF(原始数据!11:11,原始数据!AV11)>1,"×","")) | ... AN10: =IF(原始数据!AZ11="","",IF(COUNTIF(原始数据!11:11,原始数据!AZ11)>1,"×",""))
A11: =IF(IFERROR(原始数据!B12,"×")="×","×","") | B11: =IF(IFERROR(原始数据!C12,"×")="×","×","") | C11: =IF(IFERROR(原始数据!D12,"×")="×","×","") | D11: =IF(IFERROR(原始数据!E12,"×")="×","×","") | E11: =IF(IFERROR(原始数据!F12,"×")="×","×","") | F11: =IF(IFERROR(原始数据!G12,"×")="×","×","") | G11: =IF(IFERROR(原始数据!H12,"×")="×","×","") | H11: =IF(IFERROR(原始数据!I12,"×")="×","×","") | ... T11: =IF(IFERROR(原始数据!U12,"×")="×","×","") | U11: {=IF(原始数据!W12="-","",IF(原始数据!W12="","",IF(COUNT(FIND(原始数据!W12,原始数据!12:12))=2,"×","")))} | V11: {=IF(原始数据!Y12="-","",IF(原始数据!Y12="","",IF(COUNT(FIND(原始数据!Y12,原始数据!12:12))=2,"×","")))} | W11: =IF(原始数据!Z12="","",IF(COUNTIF(原始数据!12:12,原始数据!Z12)>1,"×","")) | X11: =IF(原始数据!AA12="","",IF(COUNTIF(原始数据!12:12,原始数据!AA12)>1,"×","")) | Y11: =IF(原始数据!AE12="","",IF(COUNTIF(原始数据!12:12,原始数据!AE12)>1,"×","")) | Z11: =IF(原始数据!AF12="","",IF(COUNTIF(原始数据!12:12,原始数据!AF12)>1,"×","")) | AA11: =IF(原始数据!AI12="","",IF(COUNTIF(原始数据!12:12,原始数据!AI12)>1,"×","")) | AB11: =IF(原始数据!AJ12="","",IF(COUNTIF(原始数据!12:12,原始数据!AJ12)>1,"×","")) | AC11: =IF(原始数据!AO12="","",IF(COUNTIF(原始数据!12:12,原始数据!AO12)>1,"×","")) | AD11: =IF(原始数据!AP12="","",IF(COUNTIF(原始数据!12:12,原始数据!AP12)>1,"×","")) | AE11: =IF(原始数据!AQ12="","",IF(COUNTIF(原始数据!12:12,原始数据!AQ12)>1,"×","")) | AF11: =IF(原始数据!AR12="","",IF(COUNTIF(原始数据!12:12,原始数据!AR12)>1,"×","")) | AG11: =IF(原始数据!AS12="","",IF(COUNTIF(原始数据!12:12,原始数据!AS12)>1,"×","")) | AH11: =IF(原始数据!AT12="","",IF(COUNTIF(原始数据!12:12,原始数据!AT12)>1,"×","")) | AI11: =IF(原始数据!AU12="","",IF(COUNTIF(原始数据!12:12,原始数据!AU12)>1,"×","")) | AJ11: =IF(原始数据!AV12="","",IF(COUNTIF(原始数据!12:12,原始数据!AV12)>1,"×","")) | ... AN11: =IF(原始数据!AZ12="","",IF(COUNTIF(原始数据!12:12,原始数据!AZ12)>1,"×",""))
A12: =IF(IFERROR(原始数据!B13,"×")="×","×","") | B12: =IF(IFERROR(原始数据!C13,"×")="×","×","") | C12: =IF(IFERROR(原始数据!D13,"×")="×","×","") | D12: =IF(IFERROR(原始数据!E13,"×")="×","×","") | E12: =IF(IFERROR(原始数据!F13,"×")="×","×","") | F12: =IF(IFERROR(原始数据!G13,"×")="×","×","") | G12: =IF(IFERROR(原始数据!H13,"×")="×","×","") | H12: =IF(IFERROR(原始数据!I13,"×")="×","×","") | ... T12: =IF(IFERROR(原始数据!U13,"×")="×","×","") | U12: {=IF(原始数据!W13="-","",IF(原始数据!W13="","",IF(COUNT(FIND(原始数据!W13,原始数据!13:13))=2,"×","")))} | V12: {=IF(原始数据!Y13="-","",IF(原始数据!Y13="","",IF(COUNT(FIND(原始数据!Y13,原始数据!13:13))=2,"×","")))} | W12: =IF(原始数据!Z13="","",IF(COUNTIF(原始数据!13:13,原始数据!Z13)>1,"×","")) | X12: =IF(原始数据!AA13="","",IF(COUNTIF(原始数据!13:13,原始数据!AA13)>1,"×","")) | Y12: =IF(原始数据!AE13="","",IF(COUNTIF(原始数据!13:13,原始数据!AE13)>1,"×","")) | Z12: =IF(原始数据!AF13="","",IF(COUNTIF(原始数据!13:13,原始数据!AF13)>1,"×","")) | AA12: =IF(原始数据!AI13="","",IF(COUNTIF(原始数据!13:13,原始数据!AI13)>1,"×","")) | AB12: =IF(原始数据!AJ13="","",IF(COUNTIF(原始数据!13:13,原始数据!AJ13)>1,"×","")) | AC12: =IF(原始数据!AO13="","",IF(COUNTIF(原始数据!13:13,原始数据!AO13)>1,"×","")) | AD12: =IF(原始数据!AP13="","",IF(COUNTIF(原始数据!13:13,原始数据!AP13)>1,"×","")) | AE12: =IF(原始数据!AQ13="","",IF(COUNTIF(原始数据!13:13,原始数据!AQ13)>1,"×","")) | AF12: =IF(原始数据!AR13="","",IF(COUNTIF(原始数据!13:13,原始数据!AR13)>1,"×","")) | AG12: =IF(原始数据!AS13="","",IF(COUNTIF(原始数据!13:13,原始数据!AS13)>1,"×","")) | AH12: =IF(原始数据!AT13="","",IF(COUNTIF(原始数据!13:13,原始数据!AT13)>1,"×","")) | AI12: =IF(原始数据!AU13="","",IF(COUNTIF(原始数据!13:13,原始数据!AU13)>1,"×","")) | AJ12: =IF(原始数据!AV13="","",IF(COUNTIF(原始数据!13:13,原始数据!AV13)>1,"×","")) | ... AN12: =IF(原始数据!AZ13="","",IF(COUNTIF(原始数据!13:13,原始数据!AZ13)>1,"×",""))
A13: =IF(IFERROR(原始数据!B14,"×")="×","×","") | B13: =IF(IFERROR(原始数据!C14,"×")="×","×","") | C13: =IF(IFERROR(原始数据!D14,"×")="×","×","") | D13: =IF(IFERROR(原始数据!E14,"×")="×","×","") | E13: =IF(IFERROR(原始数据!F14,"×")="×","×","") | F13: =IF(IFERROR(原始数据!G14,"×")="×","×","") | G13: =IF(IFERROR(原始数据!H14,"×")="×","×","") | H13: =IF(IFERROR(原始数据!I14,"×")="×","×","") | ... T13: =IF(IFERROR(原始数据!U14,"×")="×","×","") | U13: {=IF(原始数据!W14="-","",IF(原始数据!W14="","",IF(COUNT(FIND(原始数据!W14,原始数据!14:14))=2,"×","")))} | V13: {=IF(原始数据!Y14="-","",IF(原始数据!Y14="","",IF(COUNT(FIND(原始数据!Y14,原始数据!14:14))=2,"×","")))} | W13: =IF(原始数据!Z14="","",IF(COUNTIF(原始数据!14:14,原始数据!Z14)>1,"×","")) | X13: =IF(原始数据!AA14="","",IF(COUNTIF(原始数据!14:14,原始数据!AA14)>1,"×","")) | Y13: =IF(原始数据!AE14="","",IF(COUNTIF(原始数据!14:14,原始数据!AE14)>1,"×","")) | Z13: =IF(原始数据!AF14="","",IF(COUNTIF(原始数据!14:14,原始数据!AF14)>1,"×","")) | AA13: =IF(原始数据!AI14="","",IF(COUNTIF(原始数据!14:14,原始数据!AI14)>1,"×","")) | AB13: =IF(原始数据!AJ14="","",IF(COUNTIF(原始数据!14:14,原始数据!AJ14)>1,"×","")) | AC13: =IF(原始数据!AO14="","",IF(COUNTIF(原始数据!14:14,原始数据!AO14)>1,"×","")) | AD13: =IF(原始数据!AP14="","",IF(COUNTIF(原始数据!14:14,原始数据!AP14)>1,"×","")) | AE13: =IF(原始数据!AQ14="","",IF(COUNTIF(原始数据!14:14,原始数据!AQ14)>1,"×","")) | AF13: =IF(原始数据!AR14="","",IF(COUNTIF(原始数据!14:14,原始数据!AR14)>1,"×","")) | AG13: =IF(原始数据!AS14="","",IF(COUNTIF(原始数据!14:14,原始数据!AS14)>1,"×","")) | AH13: =IF(原始数据!AT14="","",IF(COUNTIF(原始数据!14:14,原始数据!AT14)>1,"×","")) | AI13: =IF(原始数据!AU14="","",IF(COUNTIF(原始数据!14:14,原始数据!AU14)>1,"×","")) | AJ13: =IF(原始数据!AV14="","",IF(COUNTIF(原始数据!14:14,原始数据!AV14)>1,"×","")) | ... AN13: =IF(原始数据!AZ14="","",IF(COUNTIF(原始数据!14:14,原始数据!AZ14)>1,"×",""))
A14: =IF(IFERROR(原始数据!B15,"×")="×","×","") | B14: =IF(IFERROR(原始数据!C15,"×")="×","×","") | C14: =IF(IFERROR(原始数据!D15,"×")="×","×","") | D14: =IF(IFERROR(原始数据!E15,"×")="×","×","") | E14: =IF(IFERROR(原始数据!F15,"×")="×","×","") | F14: =IF(IFERROR(原始数据!G15,"×")="×","×","") | G14: =IF(IFERROR(原始数据!H15,"×")="×","×","") | H14: =IF(IFERROR(原始数据!I15,"×")="×","×","") | ... T14: =IF(IFERROR(原始数据!U15,"×")="×","×","") | U14: {=IF(原始数据!W15="-","",IF(原始数据!W15="","",IF(COUNT(FIND(原始数据!W15,原始数据!15:15))=2,"×","")))} | V14: {=IF(原始数据!Y15="-","",IF(原始数据!Y15="","",IF(COUNT(FIND(原始数据!Y15,原始数据!15:15))=2,"×","")))} | W14: =IF(原始数据!Z15="","",IF(COUNTIF(原始数据!15:15,原始数据!Z15)>1,"×","")) | X14: =IF(原始数据!AA15="","",IF(COUNTIF(原始数据!15:15,原始数据!AA15)>1,"×","")) | Y14: =IF(原始数据!AE15="","",IF(COUNTIF(原始数据!15:15,原始数据!AE15)>1,"×","")) | Z14: =IF(原始数据!AF15="","",IF(COUNTIF(原始数据!15:15,原始数据!AF15)>1,"×","")) | AA14: =IF(原始数据!AI15="","",IF(COUNTIF(原始数据!15:15,原始数据!AI15)>1,"×","")) | AB14: =IF(原始数据!AJ15="","",IF(COUNTIF(原始数据!15:15,原始数据!AJ15)>1,"×","")) | AC14: =IF(原始数据!AO15="","",IF(COUNTIF(原始数据!15:15,原始数据!AO15)>1,"×","")) | AD14: =IF(原始数据!AP15="","",IF(COUNTIF(原始数据!15:15,原始数据!AP15)>1,"×","")) | AE14: =IF(原始数据!AQ15="","",IF(COUNTIF(原始数据!15:15,原始数据!AQ15)>1,"×","")) | AF14: =IF(原始数据!AR15="","",IF(COUNTIF(原始数据!15:15,原始数据!AR15)>1,"×","")) | AG14: =IF(原始数据!AS15="","",IF(COUNTIF(原始数据!15:15,原始数据!AS15)>1,"×","")) | AH14: =IF(原始数据!AT15="","",IF(COUNTIF(原始数据!15:15,原始数据!AT15)>1,"×","")) | AI14: =IF(原始数据!AU15="","",IF(COUNTIF(原始数据!15:15,原始数据!AU15)>1,"×","")) | AJ14: =IF(原始数据!AV15="","",IF(COUNTIF(原始数据!15:15,原始数据!AV15)>1,"×","")) | ... AN14: =IF(原始数据!AZ15="","",IF(COUNTIF(原始数据!15:15,原始数据!AZ15)>1,"×",""))
A15: =IF(IFERROR(原始数据!B16,"×")="×","×","") | B15: =IF(IFERROR(原始数据!C16,"×")="×","×","") | C15: =IF(IFERROR(原始数据!D16,"×")="×","×","") | D15: =IF(IFERROR(原始数据!E16,"×")="×","×","") | E15: =IF(IFERROR(原始数据!F16,"×")="×","×","") | F15: =IF(IFERROR(原始数据!G16,"×")="×","×","") | G15: =IF(IFERROR(原始数据!H16,"×")="×","×","") | H15: =IF(IFERROR(原始数据!I16,"×")="×","×","") | ... T15: =IF(IFERROR(原始数据!U16,"×")="×","×","") | U15: {=IF(原始数据!W16="-","",IF(原始数据!W16="","",IF(COUNT(FIND(原始数据!W16,原始数据!16:16))=2,"×","")))} | V15: {=IF(原始数据!Y16="-","",IF(原始数据!Y16="","",IF(COUNT(FIND(原始数据!Y16,原始数据!16:16))=2,"×","")))} | W15: =IF(原始数据!Z16="","",IF(COUNTIF(原始数据!16:16,原始数据!Z16)>1,"×","")) | X15: =IF(原始数据!AA16="","",IF(COUNTIF(原始数据!16:16,原始数据!AA16)>1,"×","")) | Y15: =IF(原始数据!AE16="","",IF(COUNTIF(原始数据!16:16,原始数据!AE16)>1,"×","")) | Z15: =IF(原始数据!AF16="","",IF(COUNTIF(原始数据!16:16,原始数据!AF16)>1,"×","")) | AA15: =IF(原始数据!AI16="","",IF(COUNTIF(原始数据!16:16,原始数据!AI16)>1,"×","")) | AB15: =IF(原始数据!AJ16="","",IF(COUNTIF(原始数据!16:16,原始数据!AJ16)>1,"×","")) | AC15: =IF(原始数据!AO16="","",IF(COUNTIF(原始数据!16:16,原始数据!AO16)>1,"×","")) | AD15: =IF(原始数据!AP16="","",IF(COUNTIF(原始数据!16:16,原始数据!AP16)>1,"×","")) | AE15: =IF(原始数据!AQ16="","",IF(COUNTIF(原始数据!16:16,原始数据!AQ16)>1,"×","")) | AF15: =IF(原始数据!AR16="","",IF(COUNTIF(原始数据!16:16,原始数据!AR16)>1,"×","")) | AG15: =IF(原始数据!AS16="","",IF(COUNTIF(原始数据!16:16,原始数据!AS16)>1,"×","")) | AH15: =IF(原始数据!AT16="","",IF(COUNTIF(原始数据!16:16,原始数据!AT16)>1,"×","")) | AI15: =IF(原始数据!AU16="","",IF(COUNTIF(原始数据!16:16,原始数据!AU16)>1,"×","")) | AJ15: =IF(原始数据!AV16="","",IF(COUNTIF(原始数据!16:16,原始数据!AV16)>1,"×","")) | ... AN15: =IF(原始数据!AZ16="","",IF(COUNTIF(原始数据!16:16,原始数据!AZ16)>1,"×",""))
A16: =IF(IFERROR(原始数据!B17,"×")="×","×","") | B16: =IF(IFERROR(原始数据!C17,"×")="×","×","") | C16: =IF(IFERROR(原始数据!D17,"×")="×","×","") | D16: =IF(IFERROR(原始数据!E17,"×")="×","×","") | E16: =IF(IFERROR(原始数据!F17,"×")="×","×","") | F16: =IF(IFERROR(原始数据!G17,"×")="×","×","") | G16: =IF(IFERROR(原始数据!H17,"×")="×","×","") | H16: =IF(IFERROR(原始数据!I17,"×")="×","×","") | ... T16: =IF(IFERROR(原始数据!U17,"×")="×","×","") | U16: {=IF(原始数据!W17="-","",IF(原始数据!W17="","",IF(COUNT(FIND(原始数据!W17,原始数据!17:17))=2,"×","")))} | V16: {=IF(原始数据!Y17="-","",IF(原始数据!Y17="","",IF(COUNT(FIND(原始数据!Y17,原始数据!17:17))=2,"×","")))} | W16: =IF(原始数据!Z17="","",IF(COUNTIF(原始数据!17:17,原始数据!Z17)>1,"×","")) | X16: =IF(原始数据!AA17="","",IF(COUNTIF(原始数据!17:17,原始数据!AA17)>1,"×","")) | Y16: =IF(原始数据!AE17="","",IF(COUNTIF(原始数据!17:17,原始数据!AE17)>1,"×","")) | Z16: =IF(原始数据!AF17="","",IF(COUNTIF(原始数据!17:17,原始数据!AF17)>1,"×","")) | AA16: =IF(原始数据!AI17="","",IF(COUNTIF(原始数据!17:17,原始数据!AI17)>1,"×","")) | AB16: =IF(原始数据!AJ17="","",IF(COUNTIF(原始数据!17:17,原始数据!AJ17)>1,"×","")) | AC16: =IF(原始数据!AO17="","",IF(COUNTIF(原始数据!17:17,原始数据!AO17)>1,"×","")) | AD16: =IF(原始数据!AP17="","",IF(COUNTIF(原始数据!17:17,原始数据!AP17)>1,"×","")) | AE16: =IF(原始数据!AQ17="","",IF(COUNTIF(原始数据!17:17,原始数据!AQ17)>1,"×","")) | AF16: =IF(原始数据!AR17="","",IF(COUNTIF(原始数据!17:17,原始数据!AR17)>1,"×","")) | AG16: =IF(原始数据!AS17="","",IF(COUNTIF(原始数据!17:17,原始数据!AS17)>1,"×","")) | AH16: =IF(原始数据!AT17="","",IF(COUNTIF(原始数据!17:17,原始数据!AT17)>1,"×","")) | AI16: =IF(原始数据!AU17="","",IF(COUNTIF(原始数据!17:17,原始数据!AU17)>1,"×","")) | AJ16: =IF(原始数据!AV17="","",IF(COUNTIF(原始数据!17:17,原始数据!AV17)>1,"×","")) | ... AN16: =IF(原始数据!AZ17="","",IF(COUNTIF(原始数据!17:17,原始数据!AZ17)>1,"×",""))
A17: =IF(IFERROR(原始数据!B18,"×")="×","×","") | B17: =IF(IFERROR(原始数据!C18,"×")="×","×","") | C17: =IF(IFERROR(原始数据!D18,"×")="×","×","") | D17: =IF(IFERROR(原始数据!E18,"×")="×","×","") | E17: =IF(IFERROR(原始数据!F18,"×")="×","×","") | F17: =IF(IFERROR(原始数据!G18,"×")="×","×","") | G17: =IF(IFERROR(原始数据!H18,"×")="×","×","") | H17: =IF(IFERROR(原始数据!I18,"×")="×","×","") | ... T17: =IF(IFERROR(原始数据!U18,"×")="×","×","") | U17: {=IF(原始数据!W18="-","",IF(原始数据!W18="","",IF(COUNT(FIND(原始数据!W18,原始数据!18:18))=2,"×","")))} | V17: {=IF(原始数据!Y18="-","",IF(原始数据!Y18="","",IF(COUNT(FIND(原始数据!Y18,原始数据!18:18))=2,"×","")))} | W17: =IF(原始数据!Z18="","",IF(COUNTIF(原始数据!18:18,原始数据!Z18)>1,"×","")) | X17: =IF(原始数据!AA18="","",IF(COUNTIF(原始数据!18:18,原始数据!AA18)>1,"×","")) | Y17: =IF(原始数据!AE18="","",IF(COUNTIF(原始数据!18:18,原始数据!AE18)>1,"×","")) | Z17: =IF(原始数据!AF18="","",IF(COUNTIF(原始数据!18:18,原始数据!AF18)>1,"×","")) | AA17: =IF(原始数据!AI18="","",IF(COUNTIF(原始数据!18:18,原始数据!AI18)>1,"×","")) | AB17: =IF(原始数据!AJ18="","",IF(COUNTIF(原始数据!18:18,原始数据!AJ18)>1,"×","")) | AC17: =IF(原始数据!AO18="","",IF(COUNTIF(原始数据!18:18,原始数据!AO18)>1,"×","")) | AD17: =IF(原始数据!AP18="","",IF(COUNTIF(原始数据!18:18,原始数据!AP18)>1,"×","")) | AE17: =IF(原始数据!AQ18="","",IF(COUNTIF(原始数据!18:18,原始数据!AQ18)>1,"×","")) | AF17: =IF(原始数据!AR18="","",IF(COUNTIF(原始数据!18:18,原始数据!AR18)>1,"×","")) | AG17: =IF(原始数据!AS18="","",IF(COUNTIF(原始数据!18:18,原始数据!AS18)>1,"×","")) | AH17: =IF(原始数据!AT18="","",IF(COUNTIF(原始数据!18:18,原始数据!AT18)>1,"×","")) | AI17: =IF(原始数据!AU18="","",IF(COUNTIF(原始数据!18:18,原始数据!AU18)>1,"×","")) | AJ17: =IF(原始数据!AV18="","",IF(COUNTIF(原始数据!18:18,原始数据!AV18)>1,"×","")) | ... AN17: =IF(原始数据!AZ18="","",IF(COUNTIF(原始数据!18:18,原始数据!AZ18)>1,"×",""))
A18: =IF(IFERROR(原始数据!B19,"×")="×","×","") | B18: =IF(IFERROR(原始数据!C19,"×")="×","×","") | C18: =IF(IFERROR(原始数据!D19,"×")="×","×","") | D18: =IF(IFERROR(原始数据!E19,"×")="×","×","") | E18: =IF(IFERROR(原始数据!F19,"×")="×","×","") | F18: =IF(IFERROR(原始数据!G19,"×")="×","×","") | G18: =IF(IFERROR(原始数据!H19,"×")="×","×","") | H18: =IF(IFERROR(原始数据!I19,"×")="×","×","") | ... T18: =IF(IFERROR(原始数据!U19,"×")="×","×","") | U18: {=IF(原始数据!W19="-","",IF(原始数据!W19="","",IF(COUNT(FIND(原始数据!W19,原始数据!19:19))=2,"×","")))} | V18: {=IF(原始数据!Y19="-","",IF(原始数据!Y19="","",IF(COUNT(FIND(原始数据!Y19,原始数据!19:19))=2,"×","")))} | W18: =IF(原始数据!Z19="","",IF(COUNTIF(原始数据!19:19,原始数据!Z19)>1,"×","")) | X18: =IF(原始数据!AA19="","",IF(COUNTIF(原始数据!19:19,原始数据!AA19)>1,"×","")) | Y18: =IF(原始数据!AE19="","",IF(COUNTIF(原始数据!19:19,原始数据!AE19)>1,"×","")) | Z18: =IF(原始数据!AF19="","",IF(COUNTIF(原始数据!19:19,原始数据!AF19)>1,"×","")) | AA18: =IF(原始数据!AI19="","",IF(COUNTIF(原始数据!19:19,原始数据!AI19)>1,"×","")) | AB18: =IF(原始数据!AJ19="","",IF(COUNTIF(原始数据!19:19,原始数据!AJ19)>1,"×","")) | AC18: =IF(原始数据!AO19="","",IF(COUNTIF(原始数据!19:19,原始数据!AO19)>1,"×","")) | AD18: =IF(原始数据!AP19="","",IF(COUNTIF(原始数据!19:19,原始数据!AP19)>1,"×","")) | AE18: =IF(原始数据!AQ19="","",IF(COUNTIF(原始数据!19:19,原始数据!AQ19)>1,"×","")) | AF18: =IF(原始数据!AR19="","",IF(COUNTIF(原始数据!19:19,原始数据!AR19)>1,"×","")) | AG18: =IF(原始数据!AS19="","",IF(COUNTIF(原始数据!19:19,原始数据!AS19)>1,"×","")) | AH18: =IF(原始数据!AT19="","",IF(COUNTIF(原始数据!19:19,原始数据!AT19)>1,"×","")) | AI18: =IF(原始数据!AU19="","",IF(COUNTIF(原始数据!19:19,原始数据!AU19)>1,"×","")) | AJ18: =IF(原始数据!AV19="","",IF(COUNTIF(原始数据!19:19,原始数据!AV19)>1,"×","")) | ... AN18: =IF(原始数据!AZ19="","",IF(COUNTIF(原始数据!19:19,原始数据!AZ19)>1,"×",""))
A19: =IF(IFERROR(原始数据!B20,"×")="×","×","") | B19: =IF(IFERROR(原始数据!C20,"×")="×","×","") | C19: =IF(IFERROR(原始数据!D20,"×")="×","×","") | D19: =IF(IFERROR(原始数据!E20,"×")="×","×","") | E19: =IF(IFERROR(原始数据!F20,"×")="×","×","") | F19: =IF(IFERROR(原始数据!G20,"×")="×","×","") | G19: =IF(IFERROR(原始数据!H20,"×")="×","×","") | H19: =IF(IFERROR(原始数据!I20,"×")="×","×","") | ... T19: =IF(IFERROR(原始数据!U20,"×")="×","×","") | U19: {=IF(原始数据!W20="-","",IF(原始数据!W20="","",IF(COUNT(FIND(原始数据!W20,原始数据!20:20))=2,"×","")))} | V19: {=IF(原始数据!Y20="-","",IF(原始数据!Y20="","",IF(COUNT(FIND(原始数据!Y20,原始数据!20:20))=2,"×","")))} | W19: =IF(原始数据!Z20="","",IF(COUNTIF(原始数据!20:20,原始数据!Z20)>1,"×","")) | X19: =IF(原始数据!AA20="","",IF(COUNTIF(原始数据!20:20,原始数据!AA20)>1,"×","")) | Y19: =IF(原始数据!AE20="","",IF(COUNTIF(原始数据!20:20,原始数据!AE20)>1,"×","")) | Z19: =IF(原始数据!AF20="","",IF(COUNTIF(原始数据!20:20,原始数据!AF20)>1,"×","")) | AA19: =IF(原始数据!AI20="","",IF(COUNTIF(原始数据!20:20,原始数据!AI20)>1,"×","")) | AB19: =IF(原始数据!AJ20="","",IF(COUNTIF(原始数据!20:20,原始数据!AJ20)>1,"×","")) | AC19: =IF(原始数据!AO20="","",IF(COUNTIF(原始数据!20:20,原始数据!AO20)>1,"×","")) | AD19: =IF(原始数据!AP20="","",IF(COUNTIF(原始数据!20:20,原始数据!AP20)>1,"×","")) | AE19: =IF(原始数据!AQ20="","",IF(COUNTIF(原始数据!20:20,原始数据!AQ20)>1,"×","")) | AF19: =IF(原始数据!AR20="","",IF(COUNTIF(原始数据!20:20,原始数据!AR20)>1,"×","")) | AG19: =IF(原始数据!AS20="","",IF(COUNTIF(原始数据!20:20,原始数据!AS20)>1,"×","")) | AH19: =IF(原始数据!AT20="","",IF(COUNTIF(原始数据!20:20,原始数据!AT20)>1,"×","")) | AI19: =IF(原始数据!AU20="","",IF(COUNTIF(原始数据!20:20,原始数据!AU20)>1,"×","")) | AJ19: =IF(原始数据!AV20="","",IF(COUNTIF(原始数据!20:20,原始数据!AV20)>1,"×","")) | ... AN19: =IF(原始数据!AZ20="","",IF(COUNTIF(原始数据!20:20,原始数据!AZ20)>1,"×",""))
A20: =IF(IFERROR(原始数据!B21,"×")="×","×","") | B20: =IF(IFERROR(原始数据!C21,"×")="×","×","") | C20: =IF(IFERROR(原始数据!D21,"×")="×","×","") | D20: =IF(IFERROR(原始数据!E21,"×")="×","×","") | E20: =IF(IFERROR(原始数据!F21,"×")="×","×","") | F20: =IF(IFERROR(原始数据!G21,"×")="×","×","") | G20: =IF(IFERROR(原始数据!H21,"×")="×","×","") | H20: =IF(IFERROR(原始数据!I21,"×")="×","×","") | ... T20: =IF(IFERROR(原始数据!U21,"×")="×","×","") | U20: {=IF(原始数据!W21="-","",IF(原始数据!W21="","",IF(COUNT(FIND(原始数据!W21,原始数据!21:21))=2,"×","")))} | V20: {=IF(原始数据!Y21="-","",IF(原始数据!Y21="","",IF(COUNT(FIND(原始数据!Y21,原始数据!21:21))=2,"×","")))} | W20: =IF(原始数据!Z21="","",IF(COUNTIF(原始数据!21:21,原始数据!Z21)>1,"×","")) | X20: =IF(原始数据!AA21="","",IF(COUNTIF(原始数据!21:21,原始数据!AA21)>1,"×","")) | Y20: =IF(原始数据!AE21="","",IF(COUNTIF(原始数据!21:21,原始数据!AE21)>1,"×","")) | Z20: =IF(原始数据!AF21="","",IF(COUNTIF(原始数据!21:21,原始数据!AF21)>1,"×","")) | AA20: =IF(原始数据!AI21="","",IF(COUNTIF(原始数据!21:21,原始数据!AI21)>1,"×","")) | AB20: =IF(原始数据!AJ21="","",IF(COUNTIF(原始数据!21:21,原始数据!AJ21)>1,"×","")) | AC20: =IF(原始数据!AO21="","",IF(COUNTIF(原始数据!21:21,原始数据!AO21)>1,"×","")) | AD20: =IF(原始数据!AP21="","",IF(COUNTIF(原始数据!21:21,原始数据!AP21)>1,"×","")) | AE20: =IF(原始数据!AQ21="","",IF(COUNTIF(原始数据!21:21,原始数据!AQ21)>1,"×","")) | AF20: =IF(原始数据!AR21="","",IF(COUNTIF(原始数据!21:21,原始数据!AR21)>1,"×","")) | AG20: =IF(原始数据!AS21="","",IF(COUNTIF(原始数据!21:21,原始数据!AS21)>1,"×","")) | AH20: =IF(原始数据!AT21="","",IF(COUNTIF(原始数据!21:21,原始数据!AT21)>1,"×","")) | AI20: =IF(原始数据!AU21="","",IF(COUNTIF(原始数据!21:21,原始数据!AU21)>1,"×","")) | AJ20: =IF(原始数据!AV21="","",IF(COUNTIF(原始数据!21:21,原始数据!AV21)>1,"×","")) | ... AN20: =IF(原始数据!AZ21="","",IF(COUNTIF(原始数据!21:21,原始数据!AZ21)>1,"×",""))
A21: =IF(IFERROR(原始数据!B22,"×")="×","×","") | B21: =IF(IFERROR(原始数据!C22,"×")="×","×","") | C21: =IF(IFERROR(原始数据!D22,"×")="×","×","") | D21: =IF(IFERROR(原始数据!E22,"×")="×","×","") | E21: =IF(IFERROR(原始数据!F22,"×")="×","×","") | F21: =IF(IFERROR(原始数据!G22,"×")="×","×","") | G21: =IF(IFERROR(原始数据!H22,"×")="×","×","") | H21: =IF(IFERROR(原始数据!I22,"×")="×","×","") | ... T21: =IF(IFERROR(原始数据!U22,"×")="×","×","") | U21: {=IF(原始数据!W22="-","",IF(原始数据!W22="","",IF(COUNT(FIND(原始数据!W22,原始数据!22:22))=2,"×","")))} | V21: {=IF(原始数据!Y22="-","",IF(原始数据!Y22="","",IF(COUNT(FIND(原始数据!Y22,原始数据!22:22))=2,"×","")))} | W21: =IF(原始数据!Z22="","",IF(COUNTIF(原始数据!22:22,原始数据!Z22)>1,"×","")) | X21: =IF(原始数据!AA22="","",IF(COUNTIF(原始数据!22:22,原始数据!AA22)>1,"×","")) | Y21: =IF(原始数据!AE22="","",IF(COUNTIF(原始数据!22:22,原始数据!AE22)>1,"×","")) | Z21: =IF(原始数据!AF22="","",IF(COUNTIF(原始数据!22:22,原始数据!AF22)>1,"×","")) | AA21: =IF(原始数据!AI22="","",IF(COUNTIF(原始数据!22:22,原始数据!AI22)>1,"×","")) | AB21: =IF(原始数据!AJ22="","",IF(COUNTIF(原始数据!22:22,原始数据!AJ22)>1,"×","")) | AC21: =IF(原始数据!AO22="","",IF(COUNTIF(原始数据!22:22,原始数据!AO22)>1,"×","")) | AD21: =IF(原始数据!AP22="","",IF(COUNTIF(原始数据!22:22,原始数据!AP22)>1,"×","")) | AE21: =IF(原始数据!AQ22="","",IF(COUNTIF(原始数据!22:22,原始数据!AQ22)>1,"×","")) | AF21: =IF(原始数据!AR22="","",IF(COUNTIF(原始数据!22:22,原始数据!AR22)>1,"×","")) | AG21: =IF(原始数据!AS22="","",IF(COUNTIF(原始数据!22:22,原始数据!AS22)>1,"×","")) | AH21: =IF(原始数据!AT22="","",IF(COUNTIF(原始数据!22:22,原始数据!AT22)>1,"×","")) | AI21: =IF(原始数据!AU22="","",IF(COUNTIF(原始数据!22:22,原始数据!AU22)>1,"×","")) | AJ21: =IF(原始数据!AV22="","",IF(COUNTIF(原始数据!22:22,原始数据!AV22)>1,"×","")) | ... AN21: =IF(原始数据!AZ22="","",IF(COUNTIF(原始数据!22:22,原始数据!AZ22)>1,"×",""))
A22: =IF(IFERROR(原始数据!B23,"×")="×","×","") | B22: =IF(IFERROR(原始数据!C23,"×")="×","×","") | C22: =IF(IFERROR(原始数据!D23,"×")="×","×","") | D22: =IF(IFERROR(原始数据!E23,"×")="×","×","") | E22: =IF(IFERROR(原始数据!F23,"×")="×","×","") | F22: =IF(IFERROR(原始数据!G23,"×")="×","×","") | G22: =IF(IFERROR(原始数据!H23,"×")="×","×","") | H22: =IF(IFERROR(原始数据!I23,"×")="×","×","") | ... T22: =IF(IFERROR(原始数据!U23,"×")="×","×","") | U22: {=IF(原始数据!W23="-","",IF(原始数据!W23="","",IF(COUNT(FIND(原始数据!W23,原始数据!23:23))=2,"×","")))} | V22: {=IF(原始数据!Y23="-","",IF(原始数据!Y23="","",IF(COUNT(FIND(原始数据!Y23,原始数据!23:23))=2,"×","")))} | W22: =IF(原始数据!Z23="","",IF(COUNTIF(原始数据!23:23,原始数据!Z23)>1,"×","")) | X22: =IF(原始数据!AA23="","",IF(COUNTIF(原始数据!23:23,原始数据!AA23)>1,"×","")) | Y22: =IF(原始数据!AE23="","",IF(COUNTIF(原始数据!23:23,原始数据!AE23)>1,"×","")) | Z22: =IF(原始数据!AF23="","",IF(COUNTIF(原始数据!23:23,原始数据!AF23)>1,"×","")) | AA22: =IF(原始数据!AI23="","",IF(COUNTIF(原始数据!23:23,原始数据!AI23)>1,"×","")) | AB22: =IF(原始数据!AJ23="","",IF(COUNTIF(原始数据!23:23,原始数据!AJ23)>1,"×","")) | AC22: =IF(原始数据!AO23="","",IF(COUNTIF(原始数据!23:23,原始数据!AO23)>1,"×","")) | AD22: =IF(原始数据!AP23="","",IF(COUNTIF(原始数据!23:23,原始数据!AP23)>1,"×","")) | AE22: =IF(原始数据!AQ23="","",IF(COUNTIF(原始数据!23:23,原始数据!AQ23)>1,"×","")) | AF22: =IF(原始数据!AR23="","",IF(COUNTIF(原始数据!23:23,原始数据!AR23)>1,"×","")) | AG22: =IF(原始数据!AS23="","",IF(COUNTIF(原始数据!23:23,原始数据!AS23)>1,"×","")) | AH22: =IF(原始数据!AT23="","",IF(COUNTIF(原始数据!23:23,原始数据!AT23)>1,"×","")) | AI22: =IF(原始数据!AU23="","",IF(COUNTIF(原始数据!23:23,原始数据!AU23)>1,"×","")) | AJ22: =IF(原始数据!AV23="","",IF(COUNTIF(原始数据!23:23,原始数据!AV23)>1,"×","")) | ... AN22: =IF(原始数据!AZ23="","",IF(COUNTIF(原始数据!23:23,原始数据!AZ23)>1,"×",""))
A23: =IF(IFERROR(原始数据!B24,"×")="×","×","") | B23: =IF(IFERROR(原始数据!C24,"×")="×","×","") | C23: =IF(IFERROR(原始数据!D24,"×")="×","×","") | D23: =IF(IFERROR(原始数据!E24,"×")="×","×","") | E23: =IF(IFERROR(原始数据!F24,"×")="×","×","") | F23: =IF(IFERROR(原始数据!G24,"×")="×","×","") | G23: =IF(IFERROR(原始数据!H24,"×")="×","×","") | H23: =IF(IFERROR(原始数据!I24,"×")="×","×","") | ... T23: =IF(IFERROR(原始数据!U24,"×")="×","×","") | U23: {=IF(原始数据!W24="-","",IF(原始数据!W24="","",IF(COUNT(FIND(原始数据!W24,原始数据!24:24))=2,"×","")))} | V23: {=IF(原始数据!Y24="-","",IF(原始数据!Y24="","",IF(COUNT(FIND(原始数据!Y24,原始数据!24:24))=2,"×","")))} | W23: =IF(原始数据!Z24="","",IF(COUNTIF(原始数据!24:24,原始数据!Z24)>1,"×","")) | X23: =IF(原始数据!AA24="","",IF(COUNTIF(原始数据!24:24,原始数据!AA24)>1,"×","")) | Y23: =IF(原始数据!AE24="","",IF(COUNTIF(原始数据!24:24,原始数据!AE24)>1,"×","")) | Z23: =IF(原始数据!AF24="","",IF(COUNTIF(原始数据!24:24,原始数据!AF24)>1,"×","")) | AA23: =IF(原始数据!AI24="","",IF(COUNTIF(原始数据!24:24,原始数据!AI24)>1,"×","")) | AB23: =IF(原始数据!AJ24="","",IF(COUNTIF(原始数据!24:24,原始数据!AJ24)>1,"×","")) | AC23: =IF(原始数据!AO24="","",IF(COUNTIF(原始数据!24:24,原始数据!AO24)>1,"×","")) | AD23: =IF(原始数据!AP24="","",IF(COUNTIF(原始数据!24:24,原始数据!AP24)>1,"×","")) | AE23: =IF(原始数据!AQ24="","",IF(COUNTIF(原始数据!24:24,原始数据!AQ24)>1,"×","")) | AF23: =IF(原始数据!AR24="","",IF(COUNTIF(原始数据!24:24,原始数据!AR24)>1,"×","")) | AG23: =IF(原始数据!AS24="","",IF(COUNTIF(原始数据!24:24,原始数据!AS24)>1,"×","")) | AH23: =IF(原始数据!AT24="","",IF(COUNTIF(原始数据!24:24,原始数据!AT24)>1,"×","")) | AI23: =IF(原始数据!AU24="","",IF(COUNTIF(原始数据!24:24,原始数据!AU24)>1,"×","")) | AJ23: =IF(原始数据!AV24="","",IF(COUNTIF(原始数据!24:24,原始数据!AV24)>1,"×","")) | ... AN23: =IF(原始数据!AZ24="","",IF(COUNTIF(原始数据!24:24,原始数据!AZ24)>1,"×",""))
A24: =IF(IFERROR(原始数据!B25,"×")="×","×","") | B24: =IF(IFERROR(原始数据!C25,"×")="×","×","") | C24: =IF(IFERROR(原始数据!D25,"×")="×","×","") | D24: =IF(IFERROR(原始数据!E25,"×")="×","×","") | E24: =IF(IFERROR(原始数据!F25,"×")="×","×","") | F24: =IF(IFERROR(原始数据!G25,"×")="×","×","") | G24: =IF(IFERROR(原始数据!H25,"×")="×","×","") | H24: =IF(IFERROR(原始数据!I25,"×")="×","×","") | ... T24: =IF(IFERROR(原始数据!U25,"×")="×","×","") | U24: {=IF(原始数据!W25="-","",IF(原始数据!W25="","",IF(COUNT(FIND(原始数据!W25,原始数据!25:25))=2,"×","")))} | V24: {=IF(原始数据!Y25="-","",IF(原始数据!Y25="","",IF(COUNT(FIND(原始数据!Y25,原始数据!25:25))=2,"×","")))} | W24: =IF(原始数据!Z25="","",IF(COUNTIF(原始数据!25:25,原始数据!Z25)>1,"×","")) | X24: =IF(原始数据!AA25="","",IF(COUNTIF(原始数据!25:25,原始数据!AA25)>1,"×","")) | Y24: =IF(原始数据!AE25="","",IF(COUNTIF(原始数据!25:25,原始数据!AE25)>1,"×","")) | Z24: =IF(原始数据!AF25="","",IF(COUNTIF(原始数据!25:25,原始数据!AF25)>1,"×","")) | AA24: =IF(原始数据!AI25="","",IF(COUNTIF(原始数据!25:25,原始数据!AI25)>1,"×","")) | AB24: =IF(原始数据!AJ25="","",IF(COUNTIF(原始数据!25:25,原始数据!AJ25)>1,"×","")) | AC24: =IF(原始数据!AO25="","",IF(COUNTIF(原始数据!25:25,原始数据!AO25)>1,"×","")) | AD24: =IF(原始数据!AP25="","",IF(COUNTIF(原始数据!25:25,原始数据!AP25)>1,"×","")) | AE24: =IF(原始数据!AQ25="","",IF(COUNTIF(原始数据!25:25,原始数据!AQ25)>1,"×","")) | AF24: =IF(原始数据!AR25="","",IF(COUNTIF(原始数据!25:25,原始数据!AR25)>1,"×","")) | AG24: =IF(原始数据!AS25="","",IF(COUNTIF(原始数据!25:25,原始数据!AS25)>1,"×","")) | AH24: =IF(原始数据!AT25="","",IF(COUNTIF(原始数据!25:25,原始数据!AT25)>1,"×","")) | AI24: =IF(原始数据!AU25="","",IF(COUNTIF(原始数据!25:25,原始数据!AU25)>1,"×","")) | AJ24: =IF(原始数据!AV25="","",IF(COUNTIF(原始数据!25:25,原始数据!AV25)>1,"×","")) | ... AN24: =IF(原始数据!AZ25="","",IF(COUNTIF(原始数据!25:25,原始数据!AZ25)>1,"×",""))
A25: =IF(IFERROR(原始数据!B26,"×")="×","×","") | B25: =IF(IFERROR(原始数据!C26,"×")="×","×","") | C25: =IF(IFERROR(原始数据!D26,"×")="×","×","") | D25: =IF(IFERROR(原始数据!E26,"×")="×","×","") | E25: =IF(IFERROR(原始数据!F26,"×")="×","×","") | F25: =IF(IFERROR(原始数据!G26,"×")="×","×","") | G25: =IF(IFERROR(原始数据!H26,"×")="×","×","") | H25: =IF(IFERROR(原始数据!I26,"×")="×","×","") | ... T25: =IF(IFERROR(原始数据!U26,"×")="×","×","") | U25: {=IF(原始数据!W26="-","",IF(原始数据!W26="","",IF(COUNT(FIND(原始数据!W26,原始数据!26:26))=2,"×","")))} | V25: {=IF(原始数据!Y26="-","",IF(原始数据!Y26="","",IF(COUNT(FIND(原始数据!Y26,原始数据!26:26))=2,"×","")))} | W25: =IF(原始数据!Z26="","",IF(COUNTIF(原始数据!26:26,原始数据!Z26)>1,"×","")) | X25: =IF(原始数据!AA26="","",IF(COUNTIF(原始数据!26:26,原始数据!AA26)>1,"×","")) | Y25: =IF(原始数据!AE26="","",IF(COUNTIF(原始数据!26:26,原始数据!AE26)>1,"×","")) | Z25: =IF(原始数据!AF26="","",IF(COUNTIF(原始数据!26:26,原始数据!AF26)>1,"×","")) | AA25: =IF(原始数据!AI26="","",IF(COUNTIF(原始数据!26:26,原始数据!AI26)>1,"×","")) | AB25: =IF(原始数据!AJ26="","",IF(COUNTIF(原始数据!26:26,原始数据!AJ26)>1,"×","")) | AC25: =IF(原始数据!AO26="","",IF(COUNTIF(原始数据!26:26,原始数据!AO26)>1,"×","")) | AD25: =IF(原始数据!AP26="","",IF(COUNTIF(原始数据!26:26,原始数据!AP26)>1,"×","")) | AE25: =IF(原始数据!AQ26="","",IF(COUNTIF(原始数据!26:26,原始数据!AQ26)>1,"×","")) | AF25: =IF(原始数据!AR26="","",IF(COUNTIF(原始数据!26:26,原始数据!AR26)>1,"×","")) | AG25: =IF(原始数据!AS26="","",IF(COUNTIF(原始数据!26:26,原始数据!AS26)>1,"×","")) | AH25: =IF(原始数据!AT26="","",IF(COUNTIF(原始数据!26:26,原始数据!AT26)>1,"×","")) | AI25: =IF(原始数据!AU26="","",IF(COUNTIF(原始数据!26:26,原始数据!AU26)>1,"×","")) | AJ25: =IF(原始数据!AV26="","",IF(COUNTIF(原始数据!26:26,原始数据!AV26)>1,"×","")) | ... AN25: =IF(原始数据!AZ26="","",IF(COUNTIF(原始数据!26:26,原始数据!AZ26)>1,"×",""))
A26: =IF(IFERROR(原始数据!B27,"×")="×","×","") | B26: =IF(IFERROR(原始数据!C27,"×")="×","×","") | C26: =IF(IFERROR(原始数据!D27,"×")="×","×","") | D26: =IF(IFERROR(原始数据!E27,"×")="×","×","") | E26: =IF(IFERROR(原始数据!F27,"×")="×","×","") | F26: =IF(IFERROR(原始数据!G27,"×")="×","×","") | G26: =IF(IFERROR(原始数据!H27,"×")="×","×","") | H26: =IF(IFERROR(原始数据!I27,"×")="×","×","") | ... T26: =IF(IFERROR(原始数据!U27,"×")="×","×","") | U26: {=IF(原始数据!W27="-","",IF(原始数据!W27="","",IF(COUNT(FIND(原始数据!W27,原始数据!27:27))=2,"×","")))} | V26: {=IF(原始数据!Y27="-","",IF(原始数据!Y27="","",IF(COUNT(FIND(原始数据!Y27,原始数据!27:27))=2,"×","")))} | W26: =IF(原始数据!Z27="","",IF(COUNTIF(原始数据!27:27,原始数据!Z27)>1,"×","")) | X26: =IF(原始数据!AA27="","",IF(COUNTIF(原始数据!27:27,原始数据!AA27)>1,"×","")) | Y26: =IF(原始数据!AE27="","",IF(COUNTIF(原始数据!27:27,原始数据!AE27)>1,"×","")) | Z26: =IF(原始数据!AF27="","",IF(COUNTIF(原始数据!27:27,原始数据!AF27)>1,"×","")) | AA26: =IF(原始数据!AI27="","",IF(COUNTIF(原始数据!27:27,原始数据!AI27)>1,"×","")) | AB26: =IF(原始数据!AJ27="","",IF(COUNTIF(原始数据!27:27,原始数据!AJ27)>1,"×","")) | AC26: =IF(原始数据!AO27="","",IF(COUNTIF(原始数据!27:27,原始数据!AO27)>1,"×","")) | AD26: =IF(原始数据!AP27="","",IF(COUNTIF(原始数据!27:27,原始数据!AP27)>1,"×","")) | AE26: =IF(原始数据!AQ27="","",IF(COUNTIF(原始数据!27:27,原始数据!AQ27)>1,"×","")) | AF26: =IF(原始数据!AR27="","",IF(COUNTIF(原始数据!27:27,原始数据!AR27)>1,"×","")) | AG26: =IF(原始数据!AS27="","",IF(COUNTIF(原始数据!27:27,原始数据!AS27)>1,"×","")) | AH26: =IF(原始数据!AT27="","",IF(COUNTIF(原始数据!27:27,原始数据!AT27)>1,"×","")) | AI26: =IF(原始数据!AU27="","",IF(COUNTIF(原始数据!27:27,原始数据!AU27)>1,"×","")) | AJ26: =IF(原始数据!AV27="","",IF(COUNTIF(原始数据!27:27,原始数据!AV27)>1,"×","")) | ... AN26: =IF(原始数据!AZ27="","",IF(COUNTIF(原始数据!27:27,原始数据!AZ27)>1,"×",""))
A27: =IF(IFERROR(原始数据!B28,"×")="×","×","") | B27: =IF(IFERROR(原始数据!C28,"×")="×","×","") | C27: =IF(IFERROR(原始数据!D28,"×")="×","×","") | D27: =IF(IFERROR(原始数据!E28,"×")="×","×","") | E27: =IF(IFERROR(原始数据!F28,"×")="×","×","") | F27: =IF(IFERROR(原始数据!G28,"×")="×","×","") | G27: =IF(IFERROR(原始数据!H28,"×")="×","×","") | H27: =IF(IFERROR(原始数据!I28,"×")="×","×","") | ... T27: =IF(IFERROR(原始数据!U28,"×")="×","×","") | U27: {=IF(原始数据!W28="-","",IF(原始数据!W28="","",IF(COUNT(FIND(原始数据!W28,原始数据!28:28))=2,"×","")))} | V27: {=IF(原始数据!Y28="-","",IF(原始数据!Y28="","",IF(COUNT(FIND(原始数据!Y28,原始数据!28:28))=2,"×","")))} | W27: =IF(原始数据!Z28="","",IF(COUNTIF(原始数据!28:28,原始数据!Z28)>1,"×","")) | X27: =IF(原始数据!AA28="","",IF(COUNTIF(原始数据!28:28,原始数据!AA28)>1,"×","")) | Y27: =IF(原始数据!AE28="","",IF(COUNTIF(原始数据!28:28,原始数据!AE28)>1,"×","")) | Z27: =IF(原始数据!AF28="","",IF(COUNTIF(原始数据!28:28,原始数据!AF28)>1,"×","")) | AA27: =IF(原始数据!AI28="","",IF(COUNTIF(原始数据!28:28,原始数据!AI28)>1,"×","")) | AB27: =IF(原始数据!AJ28="","",IF(COUNTIF(原始数据!28:28,原始数据!AJ28)>1,"×","")) | AC27: =IF(原始数据!AO28="","",IF(COUNTIF(原始数据!28:28,原始数据!AO28)>1,"×","")) | AD27: =IF(原始数据!AP28="","",IF(COUNTIF(原始数据!28:28,原始数据!AP28)>1,"×","")) | AE27: =IF(原始数据!AQ28="","",IF(COUNTIF(原始数据!28:28,原始数据!AQ28)>1,"×","")) | AF27: =IF(原始数据!AR28="","",IF(COUNTIF(原始数据!28:28,原始数据!AR28)>1,"×","")) | AG27: =IF(原始数据!AS28="","",IF(COUNTIF(原始数据!28:28,原始数据!AS28)>1,"×","")) | AH27: =IF(原始数据!AT28="","",IF(COUNTIF(原始数据!28:28,原始数据!AT28)>1,"×","")) | AI27: =IF(原始数据!AU28="","",IF(COUNTIF(原始数据!28:28,原始数据!AU28)>1,"×","")) | AJ27: =IF(原始数据!AV28="","",IF(COUNTIF(原始数据!28:28,原始数据!AV28)>1,"×","")) | ... AN27: =IF(原始数据!AZ28="","",IF(COUNTIF(原始数据!28:28,原始数据!AZ28)>1,"×",""))
A28: =IF(IFERROR(原始数据!B29,"×")="×","×","") | B28: =IF(IFERROR(原始数据!C29,"×")="×","×","") | C28: =IF(IFERROR(原始数据!D29,"×")="×","×","") | D28: =IF(IFERROR(原始数据!E29,"×")="×","×","") | E28: =IF(IFERROR(原始数据!F29,"×")="×","×","") | F28: =IF(IFERROR(原始数据!G29,"×")="×","×","") | G28: =IF(IFERROR(原始数据!H29,"×")="×","×","") | H28: =IF(IFERROR(原始数据!I29,"×")="×","×","") | ... T28: =IF(IFERROR(原始数据!U29,"×")="×","×","") | U28: {=IF(原始数据!W29="-","",IF(原始数据!W29="","",IF(COUNT(FIND(原始数据!W29,原始数据!29:29))=2,"×","")))} | V28: {=IF(原始数据!Y29="-","",IF(原始数据!Y29="","",IF(COUNT(FIND(原始数据!Y29,原始数据!29:29))=2,"×","")))} | W28: =IF(原始数据!Z29="","",IF(COUNTIF(原始数据!29:29,原始数据!Z29)>1,"×","")) | X28: =IF(原始数据!AA29="","",IF(COUNTIF(原始数据!29:29,原始数据!AA29)>1,"×","")) | Y28: =IF(原始数据!AE29="","",IF(COUNTIF(原始数据!29:29,原始数据!AE29)>1,"×","")) | Z28: =IF(原始数据!AF29="","",IF(COUNTIF(原始数据!29:29,原始数据!AF29)>1,"×","")) | AA28: =IF(原始数据!AI29="","",IF(COUNTIF(原始数据!29:29,原始数据!AI29)>1,"×","")) | AB28: =IF(原始数据!AJ29="","",IF(COUNTIF(原始数据!29:29,原始数据!AJ29)>1,"×","")) | AC28: =IF(原始数据!AO29="","",IF(COUNTIF(原始数据!29:29,原始数据!AO29)>1,"×","")) | AD28: =IF(原始数据!AP29="","",IF(COUNTIF(原始数据!29:29,原始数据!AP29)>1,"×","")) | AE28: =IF(原始数据!AQ29="","",IF(COUNTIF(原始数据!29:29,原始数据!AQ29)>1,"×","")) | AF28: =IF(原始数据!AR29="","",IF(COUNTIF(原始数据!29:29,原始数据!AR29)>1,"×","")) | AG28: =IF(原始数据!AS29="","",IF(COUNTIF(原始数据!29:29,原始数据!AS29)>1,"×","")) | AH28: =IF(原始数据!AT29="","",IF(COUNTIF(原始数据!29:29,原始数据!AT29)>1,"×","")) | AI28: =IF(原始数据!AU29="","",IF(COUNTIF(原始数据!29:29,原始数据!AU29)>1,"×","")) | AJ28: =IF(原始数据!AV29="","",IF(COUNTIF(原始数据!29:29,原始数据!AV29)>1,"×","")) | ... AN28: =IF(原始数据!AZ29="","",IF(COUNTIF(原始数据!29:29,原始数据!AZ29)>1,"×",""))
A29: =IF(IFERROR(原始数据!B30,"×")="×","×","") | B29: =IF(IFERROR(原始数据!C30,"×")="×","×","") | C29: =IF(IFERROR(原始数据!D30,"×")="×","×","") | D29: =IF(IFERROR(原始数据!E30,"×")="×","×","") | E29: =IF(IFERROR(原始数据!F30,"×")="×","×","") | F29: =IF(IFERROR(原始数据!G30,"×")="×","×","") | G29: =IF(IFERROR(原始数据!H30,"×")="×","×","") | H29: =IF(IFERROR(原始数据!I30,"×")="×","×","") | ... T29: =IF(IFERROR(原始数据!U30,"×")="×","×","") | U29: {=IF(原始数据!W30="-","",IF(原始数据!W30="","",IF(COUNT(FIND(原始数据!W30,原始数据!30:30))=2,"×","")))} | V29: {=IF(原始数据!Y30="-","",IF(原始数据!Y30="","",IF(COUNT(FIND(原始数据!Y30,原始数据!30:30))=2,"×","")))} | W29: =IF(原始数据!Z30="","",IF(COUNTIF(原始数据!30:30,原始数据!Z30)>1,"×","")) | X29: =IF(原始数据!AA30="","",IF(COUNTIF(原始数据!30:30,原始数据!AA30)>1,"×","")) | Y29: =IF(原始数据!AE30="","",IF(COUNTIF(原始数据!30:30,原始数据!AE30)>1,"×","")) | Z29: =IF(原始数据!AF30="","",IF(COUNTIF(原始数据!30:30,原始数据!AF30)>1,"×","")) | AA29: =IF(原始数据!AI30="","",IF(COUNTIF(原始数据!30:30,原始数据!AI30)>1,"×","")) | AB29: =IF(原始数据!AJ30="","",IF(COUNTIF(原始数据!30:30,原始数据!AJ30)>1,"×","")) | AC29: =IF(原始数据!AO30="","",IF(COUNTIF(原始数据!30:30,原始数据!AO30)>1,"×","")) | AD29: =IF(原始数据!AP30="","",IF(COUNTIF(原始数据!30:30,原始数据!AP30)>1,"×","")) | AE29: =IF(原始数据!AQ30="","",IF(COUNTIF(原始数据!30:30,原始数据!AQ30)>1,"×","")) | AF29: =IF(原始数据!AR30="","",IF(COUNTIF(原始数据!30:30,原始数据!AR30)>1,"×","")) | AG29: =IF(原始数据!AS30="","",IF(COUNTIF(原始数据!30:30,原始数据!AS30)>1,"×","")) | AH29: =IF(原始数据!AT30="","",IF(COUNTIF(原始数据!30:30,原始数据!AT30)>1,"×","")) | AI29: =IF(原始数据!AU30="","",IF(COUNTIF(原始数据!30:30,原始数据!AU30)>1,"×","")) | AJ29: =IF(原始数据!AV30="","",IF(COUNTIF(原始数据!30:30,原始数据!AV30)>1,"×","")) | ... AN29: =IF(原始数据!AZ30="","",IF(COUNTIF(原始数据!30:30,原始数据!AZ30)>1,"×",""))
A30: =IF(IFERROR(原始数据!B31,"×")="×","×","") | B30: =IF(IFERROR(原始数据!C31,"×")="×","×","") | C30: =IF(IFERROR(原始数据!D31,"×")="×","×","") | D30: =IF(IFERROR(原始数据!E31,"×")="×","×","") | E30: =IF(IFERROR(原始数据!F31,"×")="×","×","") | F30: =IF(IFERROR(原始数据!G31,"×")="×","×","") | G30: =IF(IFERROR(原始数据!H31,"×")="×","×","") | H30: =IF(IFERROR(原始数据!I31,"×")="×","×","") | ... T30: =IF(IFERROR(原始数据!U31,"×")="×","×","") | U30: {=IF(原始数据!W31="-","",IF(原始数据!W31="","",IF(COUNT(FIND(原始数据!W31,原始数据!31:31))=2,"×","")))} | V30: {=IF(原始数据!Y31="-","",IF(原始数据!Y31="","",IF(COUNT(FIND(原始数据!Y31,原始数据!31:31))=2,"×","")))} | W30: =IF(原始数据!Z31="","",IF(COUNTIF(原始数据!31:31,原始数据!Z31)>1,"×","")) | X30: =IF(原始数据!AA31="","",IF(COUNTIF(原始数据!31:31,原始数据!AA31)>1,"×","")) | Y30: =IF(原始数据!AE31="","",IF(COUNTIF(原始数据!31:31,原始数据!AE31)>1,"×","")) | Z30: =IF(原始数据!AF31="","",IF(COUNTIF(原始数据!31:31,原始数据!AF31)>1,"×","")) | AA30: =IF(原始数据!AI31="","",IF(COUNTIF(原始数据!31:31,原始数据!AI31)>1,"×","")) | AB30: =IF(原始数据!AJ31="","",IF(COUNTIF(原始数据!31:31,原始数据!AJ31)>1,"×","")) | AC30: =IF(原始数据!AO31="","",IF(COUNTIF(原始数据!31:31,原始数据!AO31)>1,"×","")) | AD30: =IF(原始数据!AP31="","",IF(COUNTIF(原始数据!31:31,原始数据!AP31)>1,"×","")) | AE30: =IF(原始数据!AQ31="","",IF(COUNTIF(原始数据!31:31,原始数据!AQ31)>1,"×","")) | AF30: =IF(原始数据!AR31="","",IF(COUNTIF(原始数据!31:31,原始数据!AR31)>1,"×","")) | AG30: =IF(原始数据!AS31="","",IF(COUNTIF(原始数据!31:31,原始数据!AS31)>1,"×","")) | AH30: =IF(原始数据!AT31="","",IF(COUNTIF(原始数据!31:31,原始数据!AT31)>1,"×","")) | AI30: =IF(原始数据!AU31="","",IF(COUNTIF(原始数据!31:31,原始数据!AU31)>1,"×","")) | AJ30: =IF(原始数据!AV31="","",IF(COUNTIF(原始数据!31:31,原始数据!AV31)>1,"×","")) | ... AN30: =IF(原始数据!AZ31="","",IF(COUNTIF(原始数据!31:31,原始数据!AZ31)>1,"×",""))
A31: =IF(IFERROR(原始数据!B32,"×")="×","×","") | B31: =IF(IFERROR(原始数据!C32,"×")="×","×","") | C31: =IF(IFERROR(原始数据!D32,"×")="×","×","") | D31: =IF(IFERROR(原始数据!E32,"×")="×","×","") | E31: =IF(IFERROR(原始数据!F32,"×")="×","×","") | F31: =IF(IFERROR(原始数据!G32,"×")="×","×","") | G31: =IF(IFERROR(原始数据!H32,"×")="×","×","") | H31: =IF(IFERROR(原始数据!I32,"×")="×","×","") | ... T31: =IF(IFERROR(原始数据!U32,"×")="×","×","") | U31: {=IF(原始数据!W32="-","",IF(原始数据!W32="","",IF(COUNT(FIND(原始数据!W32,原始数据!32:32))=2,"×","")))} | V31: {=IF(原始数据!Y32="-","",IF(原始数据!Y32="","",IF(COUNT(FIND(原始数据!Y32,原始数据!32:32))=2,"×","")))} | W31: =IF(原始数据!Z32="","",IF(COUNTIF(原始数据!32:32,原始数据!Z32)>1,"×","")) | X31: =IF(原始数据!AA32="","",IF(COUNTIF(原始数据!32:32,原始数据!AA32)>1,"×","")) | Y31: =IF(原始数据!AE32="","",IF(COUNTIF(原始数据!32:32,原始数据!AE32)>1,"×","")) | Z31: =IF(原始数据!AF32="","",IF(COUNTIF(原始数据!32:32,原始数据!AF32)>1,"×","")) | AA31: =IF(原始数据!AI32="","",IF(COUNTIF(原始数据!32:32,原始数据!AI32)>1,"×","")) | AB31: =IF(原始数据!AJ32="","",IF(COUNTIF(原始数据!32:32,原始数据!AJ32)>1,"×","")) | AC31: =IF(原始数据!AO32="","",IF(COUNTIF(原始数据!32:32,原始数据!AO32)>1,"×","")) | AD31: =IF(原始数据!AP32="","",IF(COUNTIF(原始数据!32:32,原始数据!AP32)>1,"×","")) | AE31: =IF(原始数据!AQ32="","",IF(COUNTIF(原始数据!32:32,原始数据!AQ32)>1,"×","")) | AF31: =IF(原始数据!AR32="","",IF(COUNTIF(原始数据!32:32,原始数据!AR32)>1,"×","")) | AG31: =IF(原始数据!AS32="","",IF(COUNTIF(原始数据!32:32,原始数据!AS32)>1,"×","")) | AH31: =IF(原始数据!AT32="","",IF(COUNTIF(原始数据!32:32,原始数据!AT32)>1,"×","")) | AI31: =IF(原始数据!AU32="","",IF(COUNTIF(原始数据!32:32,原始数据!AU32)>1,"×","")) | AJ31: =IF(原始数据!AV32="","",IF(COUNTIF(原始数据!32:32,原始数据!AV32)>1,"×","")) | ... AN31: =IF(原始数据!AZ32="","",IF(COUNTIF(原始数据!32:32,原始数据!AZ32)>1,"×",""))
A32: =IF(IFERROR(原始数据!B33,"×")="×","×","") | B32: =IF(IFERROR(原始数据!C33,"×")="×","×","") | C32: =IF(IFERROR(原始数据!D33,"×")="×","×","") | D32: =IF(IFERROR(原始数据!E33,"×")="×","×","") | E32: =IF(IFERROR(原始数据!F33,"×")="×","×","") | F32: =IF(IFERROR(原始数据!G33,"×")="×","×","") | G32: =IF(IFERROR(原始数据!H33,"×")="×","×","") | H32: =IF(IFERROR(原始数据!I33,"×")="×","×","") | ... T32: =IF(IFERROR(原始数据!U33,"×")="×","×","") | U32: {=IF(原始数据!W33="-","",IF(原始数据!W33="","",IF(COUNT(FIND(原始数据!W33,原始数据!33:33))=2,"×","")))} | V32: {=IF(原始数据!Y33="-","",IF(原始数据!Y33="","",IF(COUNT(FIND(原始数据!Y33,原始数据!33:33))=2,"×","")))} | W32: =IF(原始数据!Z33="","",IF(COUNTIF(原始数据!33:33,原始数据!Z33)>1,"×","")) | X32: =IF(原始数据!AA33="","",IF(COUNTIF(原始数据!33:33,原始数据!AA33)>1,"×","")) | Y32: =IF(原始数据!AE33="","",IF(COUNTIF(原始数据!33:33,原始数据!AE33)>1,"×","")) | Z32: =IF(原始数据!AF33="","",IF(COUNTIF(原始数据!33:33,原始数据!AF33)>1,"×","")) | AA32: =IF(原始数据!AI33="","",IF(COUNTIF(原始数据!33:33,原始数据!AI33)>1,"×","")) | AB32: =IF(原始数据!AJ33="","",IF(COUNTIF(原始数据!33:33,原始数据!AJ33)>1,"×","")) | AC32: =IF(原始数据!AO33="","",IF(COUNTIF(原始数据!33:33,原始数据!AO33)>1,"×","")) | AD32: =IF(原始数据!AP33="","",IF(COUNTIF(原始数据!33:33,原始数据!AP33)>1,"×","")) | AE32: =IF(原始数据!AQ33="","",IF(COUNTIF(原始数据!33:33,原始数据!AQ33)>1,"×","")) | AF32: =IF(原始数据!AR33="","",IF(COUNTIF(原始数据!33:33,原始数据!AR33)>1,"×","")) | AG32: =IF(原始数据!AS33="","",IF(COUNTIF(原始数据!33:33,原始数据!AS33)>1,"×","")) | AH32: =IF(原始数据!AT33="","",IF(COUNTIF(原始数据!33:33,原始数据!AT33)>1,"×","")) | AI32: =IF(原始数据!AU33="","",IF(COUNTIF(原始数据!33:33,原始数据!AU33)>1,"×","")) | AJ32: =IF(原始数据!AV33="","",IF(COUNTIF(原始数据!33:33,原始数据!AV33)>1,"×","")) | ... AN32: =IF(原始数据!AZ33="","",IF(COUNTIF(原始数据!33:33,原始数据!AZ33)>1,"×",""))
A33: =IF(IFERROR(原始数据!B34,"×")="×","×","") | B33: =IF(IFERROR(原始数据!C34,"×")="×","×","") | C33: =IF(IFERROR(原始数据!D34,"×")="×","×","") | D33: =IF(IFERROR(原始数据!E34,"×")="×","×","") | E33: =IF(IFERROR(原始数据!F34,"×")="×","×","") | F33: =IF(IFERROR(原始数据!G34,"×")="×","×","") | G33: =IF(IFERROR(原始数据!H34,"×")="×","×","") | H33: =IF(IFERROR(原始数据!I34,"×")="×","×","") | ... T33: =IF(IFERROR(原始数据!U34,"×")="×","×","") | U33: {=IF(原始数据!W34="-","",IF(原始数据!W34="","",IF(COUNT(FIND(原始数据!W34,原始数据!34:34))=2,"×","")))} | V33: {=IF(原始数据!Y34="-","",IF(原始数据!Y34="","",IF(COUNT(FIND(原始数据!Y34,原始数据!34:34))=2,"×","")))} | W33: =IF(原始数据!Z34="","",IF(COUNTIF(原始数据!34:34,原始数据!Z34)>1,"×","")) | X33: =IF(原始数据!AA34="","",IF(COUNTIF(原始数据!34:34,原始数据!AA34)>1,"×","")) | Y33: =IF(原始数据!AE34="","",IF(COUNTIF(原始数据!34:34,原始数据!AE34)>1,"×","")) | Z33: =IF(原始数据!AF34="","",IF(COUNTIF(原始数据!34:34,原始数据!AF34)>1,"×","")) | AA33: =IF(原始数据!AI34="","",IF(COUNTIF(原始数据!34:34,原始数据!AI34)>1,"×","")) | AB33: =IF(原始数据!AJ34="","",IF(COUNTIF(原始数据!34:34,原始数据!AJ34)>1,"×","")) | AC33: =IF(原始数据!AO34="","",IF(COUNTIF(原始数据!34:34,原始数据!AO34)>1,"×","")) | AD33: =IF(原始数据!AP34="","",IF(COUNTIF(原始数据!34:34,原始数据!AP34)>1,"×","")) | AE33: =IF(原始数据!AQ34="","",IF(COUNTIF(原始数据!34:34,原始数据!AQ34)>1,"×","")) | AF33: =IF(原始数据!AR34="","",IF(COUNTIF(原始数据!34:34,原始数据!AR34)>1,"×","")) | AG33: =IF(原始数据!AS34="","",IF(COUNTIF(原始数据!34:34,原始数据!AS34)>1,"×","")) | AH33: =IF(原始数据!AT34="","",IF(COUNTIF(原始数据!34:34,原始数据!AT34)>1,"×","")) | AI33: =IF(原始数据!AU34="","",IF(COUNTIF(原始数据!34:34,原始数据!AU34)>1,"×","")) | AJ33: =IF(原始数据!AV34="","",IF(COUNTIF(原始数据!34:34,原始数据!AV34)>1,"×","")) | ... AN33: =IF(原始数据!AZ34="","",IF(COUNTIF(原始数据!34:34,原始数据!AZ34)>1,"×",""))
A34: =IF(IFERROR(原始数据!B35,"×")="×","×","") | B34: =IF(IFERROR(原始数据!C35,"×")="×","×","") | C34: =IF(IFERROR(原始数据!D35,"×")="×","×","") | D34: =IF(IFERROR(原始数据!E35,"×")="×","×","") | E34: =IF(IFERROR(原始数据!F35,"×")="×","×","") | F34: =IF(IFERROR(原始数据!G35,"×")="×","×","") | G34: =IF(IFERROR(原始数据!H35,"×")="×","×","") | H34: =IF(IFERROR(原始数据!I35,"×")="×","×","") | ... T34: =IF(IFERROR(原始数据!U35,"×")="×","×","") | U34: {=IF(原始数据!W35="-","",IF(原始数据!W35="","",IF(COUNT(FIND(原始数据!W35,原始数据!35:35))=2,"×","")))} | V34: {=IF(原始数据!Y35="-","",IF(原始数据!Y35="","",IF(COUNT(FIND(原始数据!Y35,原始数据!35:35))=2,"×","")))} | W34: =IF(原始数据!Z35="","",IF(COUNTIF(原始数据!35:35,原始数据!Z35)>1,"×","")) | X34: =IF(原始数据!AA35="","",IF(COUNTIF(原始数据!35:35,原始数据!AA35)>1,"×","")) | Y34: =IF(原始数据!AE35="","",IF(COUNTIF(原始数据!35:35,原始数据!AE35)>1,"×","")) | Z34: =IF(原始数据!AF35="","",IF(COUNTIF(原始数据!35:35,原始数据!AF35)>1,"×","")) | AA34: =IF(原始数据!AI35="","",IF(COUNTIF(原始数据!35:35,原始数据!AI35)>1,"×","")) | AB34: =IF(原始数据!AJ35="","",IF(COUNTIF(原始数据!35:35,原始数据!AJ35)>1,"×","")) | AC34: =IF(原始数据!AO35="","",IF(COUNTIF(原始数据!35:35,原始数据!AO35)>1,"×","")) | AD34: =IF(原始数据!AP35="","",IF(COUNTIF(原始数据!35:35,原始数据!AP35)>1,"×","")) | AE34: =IF(原始数据!AQ35="","",IF(COUNTIF(原始数据!35:35,原始数据!AQ35)>1,"×","")) | AF34: =IF(原始数据!AR35="","",IF(COUNTIF(原始数据!35:35,原始数据!AR35)>1,"×","")) | AG34: =IF(原始数据!AS35="","",IF(COUNTIF(原始数据!35:35,原始数据!AS35)>1,"×","")) | AH34: =IF(原始数据!AT35="","",IF(COUNTIF(原始数据!35:35,原始数据!AT35)>1,"×","")) | AI34: =IF(原始数据!AU35="","",IF(COUNTIF(原始数据!35:35,原始数据!AU35)>1,"×","")) | AJ34: =IF(原始数据!AV35="","",IF(COUNTIF(原始数据!35:35,原始数据!AV35)>1,"×","")) | ... AN34: =IF(原始数据!AZ35="","",IF(COUNTIF(原始数据!35:35,原始数据!AZ35)>1,"×",""))
A35: =IF(IFERROR(原始数据!B36,"×")="×","×","") | B35: =IF(IFERROR(原始数据!C36,"×")="×","×","") | C35: =IF(IFERROR(原始数据!D36,"×")="×","×","") | D35: =IF(IFERROR(原始数据!E36,"×")="×","×","") | E35: =IF(IFERROR(原始数据!F36,"×")="×","×","") | F35: =IF(IFERROR(原始数据!G36,"×")="×","×","") | G35: =IF(IFERROR(原始数据!H36,"×")="×","×","") | H35: =IF(IFERROR(原始数据!I36,"×")="×","×","") | ... T35: =IF(IFERROR(原始数据!U36,"×")="×","×","") | U35: {=IF(原始数据!W36="-","",IF(原始数据!W36="","",IF(COUNT(FIND(原始数据!W36,原始数据!36:36))=2,"×","")))} | V35: {=IF(原始数据!Y36="-","",IF(原始数据!Y36="","",IF(COUNT(FIND(原始数据!Y36,原始数据!36:36))=2,"×","")))} | W35: =IF(原始数据!Z36="","",IF(COUNTIF(原始数据!36:36,原始数据!Z36)>1,"×","")) | X35: =IF(原始数据!AA36="","",IF(COUNTIF(原始数据!36:36,原始数据!AA36)>1,"×","")) | Y35: =IF(原始数据!AE36="","",IF(COUNTIF(原始数据!36:36,原始数据!AE36)>1,"×","")) | Z35: =IF(原始数据!AF36="","",IF(COUNTIF(原始数据!36:36,原始数据!AF36)>1,"×","")) | AA35: =IF(原始数据!AI36="","",IF(COUNTIF(原始数据!36:36,原始数据!AI36)>1,"×","")) | AB35: =IF(原始数据!AJ36="","",IF(COUNTIF(原始数据!36:36,原始数据!AJ36)>1,"×","")) | AC35: =IF(原始数据!AO36="","",IF(COUNTIF(原始数据!36:36,原始数据!AO36)>1,"×","")) | AD35: =IF(原始数据!AP36="","",IF(COUNTIF(原始数据!36:36,原始数据!AP36)>1,"×","")) | AE35: =IF(原始数据!AQ36="","",IF(COUNTIF(原始数据!36:36,原始数据!AQ36)>1,"×","")) | AF35: =IF(原始数据!AR36="","",IF(COUNTIF(原始数据!36:36,原始数据!AR36)>1,"×","")) | AG35: =IF(原始数据!AS36="","",IF(COUNTIF(原始数据!36:36,原始数据!AS36)>1,"×","")) | AH35: =IF(原始数据!AT36="","",IF(COUNTIF(原始数据!36:36,原始数据!AT36)>1,"×","")) | AI35: =IF(原始数据!AU36="","",IF(COUNTIF(原始数据!36:36,原始数据!AU36)>1,"×","")) | AJ35: =IF(原始数据!AV36="","",IF(COUNTIF(原始数据!36:36,原始数据!AV36)>1,"×","")) | ... AN35: =IF(原始数据!AZ36="","",IF(COUNTIF(原始数据!36:36,原始数据!AZ36)>1,"×",""))
